Workbook

Sheet Claude Log
A1: Turn # | B1: Date | C1: User Request | D1: Action Taken | E1: Details | F1: Outcome
A2: 1 | B2: 46231 | C2: 성장곡선 회귀 구간을 오픈후 6~36개월로 잡은 이유 질문 | D2: 읽기 전용 분석 — 회귀 구간 근거 설명 | E2: 요약_성장곡선 M32:P35(SLOPE/INTERCEPT/RSQ, B8:B38 = m6~36), G28:J40 표본수(n), 세팅!K3:L8(36M/48M 초과 매장수), 요약_연차별성장률 확인 | F2: 설명 완료: 하한 6=램프업·오픈할인 왜곡 제외 및 기준선(100) 도달 시점, 상한 36=표본수 급감·생존편향 회피. 워크북 변경 없음
A3: 2 | B3: 46231 | C3: 그룹0의 m6~36 평균은 124인데 절편(97.2)은 어떻게 산출되는지 질문. 이어서 N32 복구는 불필요하다고 회신 | D3: 읽기 전용 설명 — 회귀 절편 산출 원리 설명 후 회귀 블록 현재 상태 재확인 | E3: 절편 = ȳ − 기울기×x̄ = 124.0 − 1.2756×21 = 97.2 (x̄=21은 m6~36의 중앙). 요약_성장곡선 M32:P35 재확인 결과 N32의 =INTERCEPT(B8:B38,$A8:$A38) 수식이 정상 복원되어 있음(97.226) | F3: 설명 완료. 사용자 요청에 따라 워크북 수정 없음. M32:P35 수식 4행 모두 정상
A4: 3 | B4: 46231 | C4: (1) x̄=(6+36)/2의 의미, (2) 절편 97.2 vs 실제 시작 66~80 차이, (3) 기준창 m4~9와 회귀창 m6~36의 차이 질문 / 신규매장(실적 4개월)용으로 m1-12·m1-24·m1-36 기울기를 그룹별+3+제외 평균으로 산출 요청 | D4: 요약_성장곡선 L45:R53에 m1 시작 기준 구간별 SLOPE·RSQ 표 신설 | E4: SLOPE/RSQ(B$3:B$14 / B$3:B$26 / B$3:B$38 등) 그룹0~3+ 4행, 평균행은 AVERAGE(M47:M49)로 그룹3+ 제외 단순평균. 기존 M32:P35(m6-36 회귀)는 미변경, 사용자 검산블록 M41:P43도 미변경 | F4: 기울기 m1-12/24/36 = 그룹0 3.63/2.25/1.62, 그룹1 3.14/1.64/1.35, 그룹2 3.89/1.74/1.39, 그룹3+ 2.38/1.11/0.30, 3+제외 평균 3.55/1.88/1.45. 장기 외삽 금지 주석 2행 추가

Sheet 세팅
E1: 46174
A2: 지점키 | B2: 경쟁강도 | C2: 오픈일 | D2: 오픈다음달1일 | E2: 운영개월수 | F2: 36m초과 | G2: 48m초과 | K2: 36M초과 | L2: 48M초과 | N2: 월 | O2: 평균 인덱스 (램프업 제외)
A3: (0001) 건대점 | B3: 150-1 | C3: 42292 | D3: =EOMONTH(C3,0)+1 -> 42309 | E3: =DATEDIF(C3,$E$1,"m") -> 127 | F3: 36M초과 | G3: 48M초과 | J3: 150-0 | K3: =COUNTIF($B$3:$B$85,J3) -> 17 | L3: =COUNTIF($B$3:$B$56,J3) -> 9 | N3: 1 | O3: 91.030317
A4: (0002) 인헌점 | B4: 150-1 | C4: 42444 | D4: =EOMONTH(C4,0)+1 -> 42461 | E4: =DATEDIF(C4,$E$1,"m") -> 122 | F4: 36M초과 | G4: 48M초과 | J4: 150-1 | K4: =COUNTIF($B$3:$B$85,J4) -> 31 | L4: =COUNTIF($B$3:$B$56,J4) -> 21 | N4: 2 | O4: 84.287776
A5: (0003) 구디점 | B5: 150-3 | C5: 42503 | D5: =EOMONTH(C5,0)+1 -> 42522 | E5: =DATEDIF(C5,$E$1,"m") -> 120 | F5: 36M초과 | G5: 48M초과 | J5: 150-2 | K5: =COUNTIF($B$3:$B$85,J5) -> 23 | L5: =COUNTIF($B$3:$B$56,J5) -> 14 | N5: 3 | O5: 97.171601
A6: (0004) 신림점 | B6: 150-4 | C6: 42638 | D6: =EOMONTH(C6,0)+1 -> 42644 | E6: =DATEDIF(C6,$E$1,"m") -> 116 | F6: 36M초과 | G6: 48M초과 | J6: 150-3 | K6: =COUNTIF($B$3:$B$85,J6) -> 8 | L6: =COUNTIF($B$3:$B$56,J6) -> 6 | N6: 4 | O6: 96.499915
A7: (0005) 대학점 | B7: 150-2 | C7: 42708 | D7: =EOMONTH(C7,0)+1 -> 42736 | E7: =DATEDIF(C7,$E$1,"m") -> 113 | F7: 36M초과 | G7: 48M초과 | J7: 150-4 | K7: =COUNTIF($B$3:$B$85,J7) -> 3 | L7: =COUNTIF($B$3:$B$56,J7) -> 3 | N7: 5 | O7: 105.36696
A8: (0006) 서림점 | B8: 150-2 | C8: 43039 | D8: =EOMONTH(C8,0)+1 -> 43040 | E8: =DATEDIF(C8,$E$1,"m") -> 103 | F8: 36M초과 | G8: 48M초과 | J8: 150-5 | K8: =COUNTIF($B$3:$B$85,J8) -> 0 | L8: =COUNTIF($B$3:$B$56,J8) -> 0 | N8: 6 | O8: 102.78469
A9: (0007) 낙성대점 | B9: 150-1 | C9: 43146 | D9: =EOMONTH(C9,0)+1 -> 43160 | E9: =DATEDIF(C9,$E$1,"m") -> 99 | F9: 36M초과 | G9: 48M초과 | N9: 7 | O9: 104.67865
A10: (0008) 트리하우스점 | C10: 43252 | D10: =EOMONTH(C10,0)+1 -> 43282 | E10: =DATEDIF(C10,$E$1,"m") -> 96 | F10: 36M초과 | G10: 48M초과 | N10: 8 | O10: 102.04522
A11: (0009) 신원점 | B11: 150-0 | C11: 43779 | D11: =EOMONTH(C11,0)+1 -> 43800 | E11: =DATEDIF(C11,$E$1,"m") -> 78 | F11: 36M초과 | G11: 48M초과 | N11: 9 | O11: 100.12358
A12: (0010) 별빛거리점 | B12: 150-3 | C12: 44583 | D12: =EOMONTH(C12,0)+1 -> 44593 | E12: =DATEDIF(C12,$E$1,"m") -> 52 | F12: 36M초과 | G12: 48M초과 | N12: 10 | O12: 115.59456
A13: (0011) 천안성정공원점 | B13: 150-2 | C13: 44889 | D13: =EOMONTH(C13,0)+1 -> 44896 | E13: =DATEDIF(C13,$E$1,"m") -> 42 | F13: 36M초과 | G13: 48M초과 | N13: 11 | O13: 104.11252
A14: (0012) 우송대북문점 | B14: 150-1 | C14: 45470 | D14: =EOMONTH(C14,0)+1 -> 45474 | E14: =DATEDIF(C14,$E$1,"m") -> 23 | F14: 36M초과 | G14: 48M초과 | N14: 12 | O14: 103.33184
A15: (0013) 구의역파워점 | B15: 150-1 | C15: 45810 | D15: =EOMONTH(C15,0)+1 -> 45839 | E15: =DATEDIF(C15,$E$1,"m") -> 11 | F15: 36M초과 | G15: 48M초과
A16: (0014) 수원서둔골드점 | B16: 150-1 | C16: 45859 | D16: =EOMONTH(C16,0)+1 -> 45870 | E16: =DATEDIF(C16,$E$1,"m") -> 10 | F16: 36M초과 | G16: 48M초과
A17: (1001) #화곡점 | B17: 150-1 | C17: 43629 | D17: =EOMONTH(C17,0)+1 -> 43647 | E17: =DATEDIF(C17,$E$1,"m") -> 83 | F17: 36M초과 | G17: 48M초과 | K17: 정상가 | L17: 오픈할인가 | M17: 할인율
A18: (1002) #신대방점 | B18: 150-4 | C18: 43631 | D18: =EOMONTH(C18,0)+1 -> 43647 | E18: =DATEDIF(C18,$E$1,"m") -> 83 | F18: 36M초과 | G18: 48M초과 | J18: 표준 | K18: 4950 | L18: 1990 | M18: =L18/K18-1 -> -0.5979798
A19: (1003) #샤로수점 | B19: 150-2 | C19: 43743 | D19: =EOMONTH(C19,0)+1 -> 43770 | E19: =DATEDIF(C19,$E$1,"m") -> 79 | F19: 36M초과 | G19: 48M초과 | J19: 살균 | K19: 5950 | L19: 2990 | M19: =L19/K19-1 -> -0.49747899
A20: (1004) #서울대입구점 | B20: 150-1 | C20: 43834 | D20: =EOMONTH(C20,0)+1 -> 43862 | E20: =DATEDIF(C20,$E$1,"m") -> 76 | F20: 36M초과 | G20: 48M초과 | J20: 대용량 | K20: 6950 | L20: 3990 | M20: =L20/K20-1 -> -0.42589928
A21: (1005) #쑥고개점 | B21: 150-1 | C21: 43833 | D21: =EOMONTH(C21,0)+1 -> 43862 | E21: =DATEDIF(C21,$E$1,"m") -> 76 | F21: 36M초과 | G21: 48M초과
A22: (1006) #회기점 | B22: 150-1 | C22: 43853 | D22: =EOMONTH(C22,0)+1 -> 43862 | E22: =DATEDIF(C22,$E$1,"m") -> 76 | F22: 36M초과 | G22: 48M초과
A23: (1007) #구의점 | B23: 150-2 | C23: 43945 | D23: =EOMONTH(C23,0)+1 -> 43952 | E23: =DATEDIF(C23,$E$1,"m") -> 73 | F23: 36M초과 | G23: 48M초과
A24: (1008) #개포드림웍스점 | B24: 150-0 | C24: 44015 | D24: =EOMONTH(C24,0)+1 -> 44044 | E24: =DATEDIF(C24,$E$1,"m") -> 70 | F24: 36M초과 | G24: 48M초과
A25: (1009) #진시스장항점 | B25: 150-3 | C25: 44042 | D25: =EOMONTH(C25,0)+1 -> 44044 | E25: =DATEDIF(C25,$E$1,"m") -> 70 | F25: 36M초과 | G25: 48M초과
A26: (1010) #삼전엠케이점 | B26: 150-0 | C26: 44043 | D26: =EOMONTH(C26,0)+1 -> 44044 | E26: =DATEDIF(C26,$E$1,"m") -> 70 | F26: 36M초과 | G26: 48M초과
A27: (1011) #신길점 | B27: 150-1 | C27: 44072 | D27: =EOMONTH(C27,0)+1 -> 44075 | E27: =DATEDIF(C27,$E$1,"m") -> 69 | F27: 36M초과 | G27: 48M초과
A28: (1012) #석촌점 | B28: 150-0 | C28: 44085 | D28: =EOMONTH(C28,0)+1 -> 44105 | E28: =DATEDIF(C28,$E$1,"m") -> 68 | F28: 36M초과 | G28: 48M초과
A29: (1014) #자곡점 | B29: 150-2 | C29: 44147 | D29: =EOMONTH(C29,0)+1 -> 44166 | E29: =DATEDIF(C29,$E$1,"m") -> 66 | F29: 36M초과 | G29: 48M초과
A30: (1015) #사당점 | B30: 150-1 | C30: 44154 | D30: =EOMONTH(C30,0)+1 -> 44166 | E30: =DATEDIF(C30,$E$1,"m") -> 66 | F30: 36M초과 | G30: 48M초과
A31: (1016) #가산점 | B31: 150-2 | C31: 44169 | D31: =EOMONTH(C31,0)+1 -> 44197 | E31: =DATEDIF(C31,$E$1,"m") -> 65 | F31: 36M초과 | G31: 48M초과
A32: (1019) #청룡점 | B32: 150-3 | C32: 44252 | D32: =EOMONTH(C32,0)+1 -> 44256 | E32: =DATEDIF(C32,$E$1,"m") -> 63 | F32: 36M초과 | G32: 48M초과
... A48: (1036) #낙성대행운점 | B48: 150-1 | C48: 44508 | D48: =EOMONTH(C48,0)+1 -> 44531 | E48: =DATEDIF(C48,$E$1,"m") -> 54 | F48: 36M초과 | G48: 48M초과
A49: (1037) #신림퍼스트점 | B49: 150-2 | C49: #N/A | D49: =EOMONTH(C49,0)+1 -> #N/A | E49: =DATEDIF(C49,$E$1,"m") -> #N/A | F49: 36M초과 | G49: 48M초과
A50: (1038) #한양여대점 | B50: 150-2 | C50: 44616 | D50: =EOMONTH(C50,0)+1 -> 44621 | E50: =DATEDIF(C50,$E$1,"m") -> 51 | F50: 36M초과 | G50: 48M초과
A51: (1039) #이문점 | B51: 150-2 | C51: 44643 | D51: =EOMONTH(C51,0)+1 -> 44652 | E51: =DATEDIF(C51,$E$1,"m") -> 50 | F51: 36M초과 | G51: 48M초과
A52: (1040) #독산역점 | B52: 150-1 | C52: 44651 | D52: =EOMONTH(C52,0)+1 -> 44652 | E52: =DATEDIF(C52,$E$1,"m") -> 50 | F52: 36M초과 | G52: 48M초과
A53: (1041) #인하대점 | B53: 150-3 | C53: 44657 | D53: =EOMONTH(C53,0)+1 -> 44682 | E53: =DATEDIF(C53,$E$1,"m") -> 49 | F53: 36M초과 | G53: 48M초과
A54: (1042) #연희점 | B54: 150-1 | C54: 44659 | D54: =EOMONTH(C54,0)+1 -> 44682 | E54: =DATEDIF(C54,$E$1,"m") -> 49 | F54: 36M초과 | G54: 48M초과
A55: (1043) #고대정문점 | B55: 150-0 | C55: 44694 | D55: =EOMONTH(C55,0)+1 -> 44713 | E55: =DATEDIF(C55,$E$1,"m") -> 48 | F55: 36M초과 | G55: 48M초과
...

Sheet 요약_월별시즈널리티
A1: 월별 시즈널리티 인덱스 (이상치 매장 8개 제외)
A3: 인덱스 = (해당월 매출 / 매장-연도 평균 매출) × 100, 100=평균
A4: 제외 매장: 요약_이상치감지 [B] 8개 매장 (3개월 이동평균 -30% 이상 급락)
A6: 월 | B6: 페어 수 | C6: 평균 인덱스 | D6: 중앙값 인덱스 | E6: 페어 수 (램프업 제외) | F6: 평균 인덱스 (램프업 제외) | G6: 중앙값 인덱스 (램프업 제외) | H6: 평균 차이 (제외 − 포함)
A7: 1 | B7: {=SUMPRODUCT((ISNUMBER([1]Calc_매장월인덱스!P$2:P$242))*([1]Calc_매장월인덱스!AB$2:AB$242=0))} -> 218 | C7: {=IFERROR(SUMPRODUCT(IFERROR([1]Calc_매장월인덱스!P$2:P$242*(ISNUMBER([1]Calc_매장월인덱스!P$2:P$242))*([1]Calc_매장월인덱스!AB$2:AB$242=0),0))/B7,"-")} -> 87.245366 | D7: {=IFERROR(_xlfn.AGGREGATE(17,6,[1]Calc_매장월인덱스!P$2:P$242/(([1]Calc_매장월인덱스!AB$2:AB$242=0)*ISNUMBER([1]Calc_매장월인덱스!P$2:P$242)),2),"-")} -> 88.781982 | E7: {=SUMPRODUCT((ISNUMBER(INDEX([1]Calc_매장월인덱스!$P$2:$AA$242,0,$A7)))*([1]Calc_매장월인덱스!$AB$2:$AB$242=0)*(([1]Calc_매장월인덱스!$B$2:$B$242*12+$A7) - ([1]Calc_매장월인덱스!$AD$2:$AD$242*12+[1]Calc_매장월인덱스!$AE$2:$AE$242)>=6))} -> 165 | F7: {=IFERROR(SUMPRODUCT(IFERROR(INDEX([1]Calc_매장월인덱스!$P$2:$AA$242,0,$A7)*(ISNUMBER(INDEX([1]Calc_매장월인덱스!$P$2:$AA$242,0,$A7)))*([1]Calc_매장월인덱스!$AB$2:$AB$242=0)*(([1]Calc_매장월인덱스!$B$2:$B$242*12+$A7) - ([1]Calc_매장월인덱스!$AD$2:$AD$242*12+[1]Calc_매장월인덱스!$AE$2:$AE$242)>=6),0))/E7,"-")} -> 91.030317 | G7: {=IFERROR(_xlfn.AGGREGATE(17,6,INDEX([1]Calc_매장월인덱스!$P$2:$AA$242,0,$A7)/(([1]Calc_매장월인덱스!$AB$2:$AB$242=0)*ISNUMBER(INDEX([1]Calc_매장월인덱스!$P$2:$AA$242,0,$A7))*(([1]Calc_매장월인덱스!$B$2:$B$242*12+$A7) - ([1]Calc_매장월인덱스!$AD$2:$AD$242*12+[1]Calc_매장월인덱스!$AE$2:$AE$242)>=6)),2),"-")} -> 91.064932 | H7: =IFERROR(F7-C7,"-") -> 3.7849509
A8: 2 | B8: {=SUMPRODUCT((ISNUMBER([1]Calc_매장월인덱스!Q$2:Q$242))*([1]Calc_매장월인덱스!AB$2:AB$242=0))} -> 218 | C8: {=IFERROR(SUMPRODUCT(IFERROR([1]Calc_매장월인덱스!Q$2:Q$242*(ISNUMBER([1]Calc_매장월인덱스!Q$2:Q$242))*([1]Calc_매장월인덱스!AB$2:AB$242=0),0))/B8,"-")} -> 82.522548 | D8: {=IFERROR(_xlfn.AGGREGATE(17,6,[1]Calc_매장월인덱스!Q$2:Q$242/(([1]Calc_매장월인덱스!AB$2:AB$242=0)*ISNUMBER([1]Calc_매장월인덱스!Q$2:Q$242)),2),"-")} -> 82.250637 | E8: {=SUMPRODUCT((ISNUMBER(INDEX([1]Calc_매장월인덱스!$P$2:$AA$242,0,$A8)))*([1]Calc_매장월인덱스!$AB$2:$AB$242=0)*(([1]Calc_매장월인덱스!$B$2:$B$242*12+$A8) - ([1]Calc_매장월인덱스!$AD$2:$AD$242*12+[1]Calc_매장월인덱스!$AE$2:$AE$242)>=6))} -> 176 | F8: {=IFERROR(SUMPRODUCT(IFERROR(INDEX([1]Calc_매장월인덱스!$P$2:$AA$242,0,$A8)*(ISNUMBER(INDEX([1]Calc_매장월인덱스!$P$2:$AA$242,0,$A8)))*([1]Calc_매장월인덱스!$AB$2:$AB$242=0)*(([1]Calc_매장월인덱스!$B$2:$B$242*12+$A8) - ([1]Calc_매장월인덱스!$AD$2:$AD$242*12+[1]Calc_매장월인덱스!$AE$2:$AE$242)>=6),0))/E8,"-")} -> 84.287776 | G8: {=IFERROR(_xlfn.AGGREGATE(17,6,INDEX([1]Calc_매장월인덱스!$P$2:$AA$242,0,$A8)/(([1]Calc_매장월인덱스!$AB$2:$AB$242=0)*ISNUMBER(INDEX([1]Calc_매장월인덱스!$P$2:$AA$242,0,$A8))*(([1]Calc_매장월인덱스!$B$2:$B$242*12+$A8) - ([1]Calc_매장월인덱스!$AD$2:$AD$242*12+[1]Calc_매장월인덱스!$AE$2:$AE$242)>=6)),2),"-")} -> 83.667925 | H8: =IFERROR(F8-C8,"-") -> 1.7652281
A9: 3 | B9: {=SUMPRODUCT((ISNUMBER([1]Calc_매장월인덱스!R$2:R$242))*([1]Calc_매장월인덱스!AB$2:AB$242=0))} -> 218 | C9: {=IFERROR(SUMPRODUCT(IFERROR([1]Calc_매장월인덱스!R$2:R$242*(ISNUMBER([1]Calc_매장월인덱스!R$2:R$242))*([1]Calc_매장월인덱스!AB$2:AB$242=0),0))/B9,"-")} -> 96.187233 | D9: {=IFERROR(_xlfn.AGGREGATE(17,6,[1]Calc_매장월인덱스!R$2:R$242/(([1]Calc_매장월인덱스!AB$2:AB$242=0)*ISNUMBER([1]Calc_매장월인덱스!R$2:R$242)),2),"-")} -> 96.098186 | E9: {=SUMPRODUCT((ISNUMBER(INDEX([1]Calc_매장월인덱스!$P$2:$AA$242,0,$A9)))*([1]Calc_매장월인덱스!$AB$2:$AB$242=0)*(([1]Calc_매장월인덱스!$B$2:$B$242*12+$A9) - ([1]Calc_매장월인덱스!$AD$2:$AD$242*12+[1]Calc_매장월인덱스!$AE$2:$AE$242)>=6))} -> 188 | F9: {=IFERROR(SUMPRODUCT(IFERROR(INDEX([1]Calc_매장월인덱스!$P$2:$AA$242,0,$A9)*(ISNUMBER(INDEX([1]Calc_매장월인덱스!$P$2:$AA$242,0,$A9)))*([1]Calc_매장월인덱스!$AB$2:$AB$242=0)*(([1]Calc_매장월인덱스!$B$2:$B$242*12+$A9) - ([1]Calc_매장월인덱스!$AD$2:$AD$242*12+[1]Calc_매장월인덱스!$AE$2:$AE$242)>=6),0))/E9,"-")} -> 97.171601 | G9: {=IFERROR(_xlfn.AGGREGATE(17,6,INDEX([1]Calc_매장월인덱스!$P$2:$AA$242,0,$A9)/(([1]Calc_매장월인덱스!$AB$2:$AB$242=0)*ISNUMBER(INDEX([1]Calc_매장월인덱스!$P$2:$AA$242,0,$A9))*(([1]Calc_매장월인덱스!$B$2:$B$242*12+$A9) - ([1]Calc_매장월인덱스!$AD$2:$AD$242*12+[1]Calc_매장월인덱스!$AE$2:$AE$242)>=6)),2),"-")} -> 96.898163 | H9: =IFERROR(F9-C9,"-") -> 0.98436727
A10: 4 | B10: {=SUMPRODUCT((ISNUMBER([1]Calc_매장월인덱스!S$2:S$242))*([1]Calc_매장월인덱스!AB$2:AB$242=0))} -> 218 | C10: {=IFERROR(SUMPRODUCT(IFERROR([1]Calc_매장월인덱스!S$2:S$242*(ISNUMBER([1]Calc_매장월인덱스!S$2:S$242))*([1]Calc_매장월인덱스!AB$2:AB$242=0),0))/B10,"-")} -> 95.963431 | D10: {=IFERROR(_xlfn.AGGREGATE(17,6,[1]Calc_매장월인덱스!S$2:S$242/(([1]Calc_매장월인덱스!AB$2:AB$242=0)*ISNUMBER([1]Calc_매장월인덱스!S$2:S$242)),2),"-")} -> 96.328113 | E10: {=SUMPRODUCT((ISNUMBER(INDEX([1]Calc_매장월인덱스!$P$2:$AA$242,0,$A10)))*([1]Calc_매장월인덱스!$AB$2:$AB$242=0)*(([1]Calc_매장월인덱스!$B$2:$B$242*12+$A10) - ([1]Calc_매장월인덱스!$AD$2:$AD$242*12+[1]Calc_매장월인덱스!$AE$2:$AE$242)>=6))} -> 197 | F10: {=IFERROR(SUMPRODUCT(IFERROR(INDEX([1]Calc_매장월인덱스!$P$2:$AA$242,0,$A10)*(ISNUMBER(INDEX([1]Calc_매장월인덱스!$P$2:$AA$242,0,$A10)))*([1]Calc_매장월인덱스!$AB$2:$AB$242=0)*(([1]Calc_매장월인덱스!$B$2:$B$242*12+$A10) - ([1]Calc_매장월인덱스!$AD$2:$AD$242*12+[1]Calc_매장월인덱스!$AE$2:$AE$242)>=6),0))/E10,"-")} -> 96.499915 | G10: {=IFERROR(_xlfn.AGGREGATE(17,6,INDEX([1]Calc_매장월인덱스!$P$2:$AA$242,0,$A10)/(([1]Calc_매장월인덱스!$AB$2:$AB$242=0)*ISNUMBER(INDEX([1]Calc_매장월인덱스!$P$2:$AA$242,0,$A10))*(([1]Calc_매장월인덱스!$B$2:$B$242*12+$A10) - ([1]Calc_매장월인덱스!$AD$2:$AD$242*12+[1]Calc_매장월인덱스!$AE$2:$AE$242)>=6)),2),"-")} -> 96.795853 | H10: =IFERROR(F10-C10,"-") -> 0.53648379
A11: 5 | B11: {=SUMPRODUCT((ISNUMBER([1]Calc_매장월인덱스!T$2:T$242))*([1]Calc_매장월인덱스!AB$2:AB$242=0))} -> 218 | C11: {=IFERROR(SUMPRODUCT(IFERROR([1]Calc_매장월인덱스!T$2:T$242*(ISNUMBER([1]Calc_매장월인덱스!T$2:T$242))*([1]Calc_매장월인덱스!AB$2:AB$242=0),0))/B11,"-")} -> 105.32404 | D11: {=IFERROR(_xlfn.AGGREGATE(17,6,[1]Calc_매장월인덱스!T$2:T$242/(([1]Calc_매장월인덱스!AB$2:AB$242=0)*ISNUMBER([1]Calc_매장월인덱스!T$2:T$242)),2),"-")} -> 105.53665 | E11: {=SUMPRODUCT((ISNUMBER(INDEX([1]Calc_매장월인덱스!$P$2:$AA$242,0,$A11)))*([1]Calc_매장월인덱스!$AB$2:$AB$242=0)*(([1]Calc_매장월인덱스!$B$2:$B$242*12+$A11) - ([1]Calc_매장월인덱스!$AD$2:$AD$242*12+[1]Calc_매장월인덱스!$AE$2:$AE$242)>=6))} -> 207 | F11: {=IFERROR(SUMPRODUCT(IFERROR(INDEX([1]Calc_매장월인덱스!$P$2:$AA$242,0,$A11)*(ISNUMBER(INDEX([1]Calc_매장월인덱스!$P$2:$AA$242,0,$A11)))*([1]Calc_매장월인덱스!$AB$2:$AB$242=0)*(([1]Calc_매장월인덱스!$B$2:$B$242*12+$A11) - ([1]Calc_매장월인덱스!$AD$2:$AD$242*12+[1]Calc_매장월인덱스!$AE$2:$AE$242)>=6),0))/E11,"-")} -> 105.36696 | G11: {=IFERROR(_xlfn.AGGREGATE(17,6,INDEX([1]Calc_매장월인덱스!$P$2:$AA$242,0,$A11)/(([1]Calc_매장월인덱스!$AB$2:$AB$242=0)*ISNUMBER(INDEX([1]Calc_매장월인덱스!$P$2:$AA$242,0,$A11))*(([1]Calc_매장월인덱스!$B$2:$B$242*12+$A11) - ([1]Calc_매장월인덱스!$AD$2:$AD$242*12+[1]Calc_매장월인덱스!$AE$2:$AE$242)>=6)),2),"-")} -> 105.56666 | H11: =IFERROR(F11-C11,"-") -> 0.042921698
A12: 6 | B12: {=SUMPRODUCT((ISNUMBER([1]Calc_매장월인덱스!U$2:U$242))*([1]Calc_매장월인덱스!AB$2:AB$242=0))} -> 218 | C12: {=IFERROR(SUMPRODUCT(IFERROR([1]Calc_매장월인덱스!U$2:U$242*(ISNUMBER([1]Calc_매장월인덱스!U$2:U$242))*([1]Calc_매장월인덱스!AB$2:AB$242=0),0))/B12,"-")} -> 102.87101 | D12: {=IFERROR(_xlfn.AGGREGATE(17,6,[1]Calc_매장월인덱스!U$2:U$242/(([1]Calc_매장월인덱스!AB$2:AB$242=0)*ISNUMBER([1]Calc_매장월인덱스!U$2:U$242)),2),"-")} -> 103.00425 | E12: {=SUMPRODUCT((ISNUMBER(INDEX([1]Calc_매장월인덱스!$P$2:$AA$242,0,$A12)))*([1]Calc_매장월인덱스!$AB$2:$AB$242=0)*(([1]Calc_매장월인덱스!$B$2:$B$242*12+$A12) - ([1]Calc_매장월인덱스!$AD$2:$AD$242*12+[1]Calc_매장월인덱스!$AE$2:$AE$242)>=6))} -> 213 | F12: {=IFERROR(SUMPRODUCT(IFERROR(INDEX([1]Calc_매장월인덱스!$P$2:$AA$242,0,$A12)*(ISNUMBER(INDEX([1]Calc_매장월인덱스!$P$2:$AA$242,0,$A12)))*([1]Calc_매장월인덱스!$AB$2:$AB$242=0)*(([1]Calc_매장월인덱스!$B$2:$B$242*12+$A12) - ([1]Calc_매장월인덱스!$AD$2:$AD$242*12+[1]Calc_매장월인덱스!$AE$2:$AE$242)>=6),0))/E12,"-")} -> 102.78469 | G12: {=IFERROR(_xlfn.AGGREGATE(17,6,INDEX([1]Calc_매장월인덱스!$P$2:$AA$242,0,$A12)/(([1]Calc_매장월인덱스!$AB$2:$AB$242=0)*ISNUMBER(INDEX([1]Calc_매장월인덱스!$P$2:$AA$242,0,$A12))*(([1]Calc_매장월인덱스!$B$2:$B$242*12+$A12) - ([1]Calc_매장월인덱스!$AD$2:$AD$242*12+[1]Calc_매장월인덱스!$AE$2:$AE$242)>=6)),2),"-")} -> 102.82351 | H12: =IFERROR(F12-C12,"-") -> -0.086325039
A13: 7 | B13: {=SUMPRODUCT((ISNUMBER([1]Calc_매장월인덱스!V$2:V$242))*([1]Calc_매장월인덱스!AB$2:AB$242=0))} -> 218 | C13: {=IFERROR(SUMPRODUCT(IFERROR([1]Calc_매장월인덱스!V$2:V$242*(ISNUMBER([1]Calc_매장월인덱스!V$2:V$242))*([1]Calc_매장월인덱스!AB$2:AB$242=0),0))/B13,"-")} -> 104.67865 | D13: {=IFERROR(_xlfn.AGGREGATE(17,6,[1]Calc_매장월인덱스!V$2:V$242/(([1]Calc_매장월인덱스!AB$2:AB$242=0)*ISNUMBER([1]Calc_매장월인덱스!V$2:V$242)),2),"-")} -> 104.40187 | E13: {=SUMPRODUCT((ISNUMBER(INDEX([1]Calc_매장월인덱스!$P$2:$AA$242,0,$A13)))*([1]Calc_매장월인덱스!$AB$2:$AB$242=0)*(([1]Calc_매장월인덱스!$B$2:$B$242*12+$A13) - ([1]Calc_매장월인덱스!$AD$2:$AD$242*12+[1]Calc_매장월인덱스!$AE$2:$AE$242)>=6))} -> 218 | F13: {=IFERROR(SUMPRODUCT(IFERROR(INDEX([1]Calc_매장월인덱스!$P$2:$AA$242,0,$A13)*(ISNUMBER(INDEX([1]Calc_매장월인덱스!$P$2:$AA$242,0,$A13)))*([1]Calc_매장월인덱스!$AB$2:$AB$242=0)*(([1]Calc_매장월인덱스!$B$2:$B$242*12+$A13) - ([1]Calc_매장월인덱스!$AD$2:$AD$242*12+[1]Calc_매장월인덱스!$AE$2:$AE$242)>=6),0))/E13,"-")} -> 104.67865 | G13: {=IFERROR(_xlfn.AGGREGATE(17,6,INDEX([1]Calc_매장월인덱스!$P$2:$AA$242,0,$A13)/(([1]Calc_매장월인덱스!$AB$2:$AB$242=0)*ISNUMBER(INDEX([1]Calc_매장월인덱스!$P$2:$AA$242,0,$A13))*(([1]Calc_매장월인덱스!$B$2:$B$242*12+$A13) - ([1]Calc_매장월인덱스!$AD$2:$AD$242*12+[1]Calc_매장월인덱스!$AE$2:$AE$242)>=6)),2),"-")} -> 104.40187 | H13: =IFERROR(F13-C13,"-") -> 0
A14: 8 | B14: {=SUMPRODUCT((ISNUMBER([1]Calc_매장월인덱스!W$2:W$242))*([1]Calc_매장월인덱스!AB$2:AB$242=0))} -> 218 | C14: {=IFERROR(SUMPRODUCT(IFERROR([1]Calc_매장월인덱스!W$2:W$242*(ISNUMBER([1]Calc_매장월인덱스!W$2:W$242))*([1]Calc_매장월인덱스!AB$2:AB$242=0),0))/B14,"-")} -> 102.04522 | D14: {=IFERROR(_xlfn.AGGREGATE(17,6,[1]Calc_매장월인덱스!W$2:W$242/(([1]Calc_매장월인덱스!AB$2:AB$242=0)*ISNUMBER([1]Calc_매장월인덱스!W$2:W$242)),2),"-")} -> 100.96882 | E14: {=SUMPRODUCT((ISNUMBER(INDEX([1]Calc_매장월인덱스!$P$2:$AA$242,0,$A14)))*([1]Calc_매장월인덱스!$AB$2:$AB$242=0)*(([1]Calc_매장월인덱스!$B$2:$B$242*12+$A14) - ([1]Calc_매장월인덱스!$AD$2:$AD$242*12+[1]Calc_매장월인덱스!$AE$2:$AE$242)>=6))} -> 218 | F14: {=IFERROR(SUMPRODUCT(IFERROR(INDEX([1]Calc_매장월인덱스!$P$2:$AA$242,0,$A14)*(ISNUMBER(INDEX([1]Calc_매장월인덱스!$P$2:$AA$242,0,$A14)))*([1]Calc_매장월인덱스!$AB$2:$AB$242=0)*(([1]Calc_매장월인덱스!$B$2:$B$242*12+$A14) - ([1]Calc_매장월인덱스!$AD$2:$AD$242*12+[1]Calc_매장월인덱스!$AE$2:$AE$242)>=6),0))/E14,"-")} -> 102.04522 | G14: {=IFERROR(_xlfn.AGGREGATE(17,6,INDEX([1]Calc_매장월인덱스!$P$2:$AA$242,0,$A14)/(([1]Calc_매장월인덱스!$AB$2:$AB$242=0)*ISNUMBER(INDEX([1]Calc_매장월인덱스!$P$2:$AA$242,0,$A14))*(([1]Calc_매장월인덱스!$B$2:$B$242*12+$A14) - ([1]Calc_매장월인덱스!$AD$2:$AD$242*12+[1]Calc_매장월인덱스!$AE$2:$AE$242)>=6)),2),"-")} -> 100.96882 | H14: =IFERROR(F14-C14,"-") -> 0
A15: 9 | B15: {=SUMPRODUCT((ISNUMBER([1]Calc_매장월인덱스!X$2:X$242))*([1]Calc_매장월인덱스!AB$2:AB$242=0))} -> 218 | C15: {=IFERROR(SUMPRODUCT(IFERROR([1]Calc_매장월인덱스!X$2:X$242*(ISNUMBER([1]Calc_매장월인덱스!X$2:X$242))*([1]Calc_매장월인덱스!AB$2:AB$242=0),0))/B15,"-")} -> 100.12358 | D15: {=IFERROR(_xlfn.AGGREGATE(17,6,[1]Calc_매장월인덱스!X$2:X$242/(([1]Calc_매장월인덱스!AB$2:AB$242=0)*ISNUMBER([1]Calc_매장월인덱스!X$2:X$242)),2),"-")} -> 99.05002 | E15: {=SUMPRODUCT((ISNUMBER(INDEX([1]Calc_매장월인덱스!$P$2:$AA$242,0,$A15)))*([1]Calc_매장월인덱스!$AB$2:$AB$242=0)*(([1]Calc_매장월인덱스!$B$2:$B$242*12+$A15) - ([1]Calc_매장월인덱스!$AD$2:$AD$242*12+[1]Calc_매장월인덱스!$AE$2:$AE$242)>=6))} -> 218 | F15: {=IFERROR(SUMPRODUCT(IFERROR(INDEX([1]Calc_매장월인덱스!$P$2:$AA$242,0,$A15)*(ISNUMBER(INDEX([1]Calc_매장월인덱스!$P$2:$AA$242,0,$A15)))*([1]Calc_매장월인덱스!$AB$2:$AB$242=0)*(([1]Calc_매장월인덱스!$B$2:$B$242*12+$A15) - ([1]Calc_매장월인덱스!$AD$2:$AD$242*12+[1]Calc_매장월인덱스!$AE$2:$AE$242)>=6),0))/E15,"-")} -> 100.12358 | G15: {=IFERROR(_xlfn.AGGREGATE(17,6,INDEX([1]Calc_매장월인덱스!$P$2:$AA$242,0,$A15)/(([1]Calc_매장월인덱스!$AB$2:$AB$242=0)*ISNUMBER(INDEX([1]Calc_매장월인덱스!$P$2:$AA$242,0,$A15))*(([1]Calc_매장월인덱스!$B$2:$B$242*12+$A15) - ([1]Calc_매장월인덱스!$AD$2:$AD$242*12+[1]Calc_매장월인덱스!$AE$2:$AE$242)>=6)),2),"-")} -> 99.05002 | H15: =IFERROR(F15-C15,"-") -> 0
A16: 10 | B16: {=SUMPRODUCT((ISNUMBER([1]Calc_매장월인덱스!Y$2:Y$242))*([1]Calc_매장월인덱스!AB$2:AB$242=0))} -> 218 | C16: {=IFERROR(SUMPRODUCT(IFERROR([1]Calc_매장월인덱스!Y$2:Y$242*(ISNUMBER([1]Calc_매장월인덱스!Y$2:Y$242))*([1]Calc_매장월인덱스!AB$2:AB$242=0),0))/B16,"-")} -> 115.59456 | D16: {=IFERROR(_xlfn.AGGREGATE(17,6,[1]Calc_매장월인덱스!Y$2:Y$242/(([1]Calc_매장월인덱스!AB$2:AB$242=0)*ISNUMBER([1]Calc_매장월인덱스!Y$2:Y$242)),2),"-")} -> 115.39964 | E16: {=SUMPRODUCT((ISNUMBER(INDEX([1]Calc_매장월인덱스!$P$2:$AA$242,0,$A16)))*([1]Calc_매장월인덱스!$AB$2:$AB$242=0)*(([1]Calc_매장월인덱스!$B$2:$B$242*12+$A16) - ([1]Calc_매장월인덱스!$AD$2:$AD$242*12+[1]Calc_매장월인덱스!$AE$2:$AE$242)>=6))} -> 218 | F16: {=IFERROR(SUMPRODUCT(IFERROR(INDEX([1]Calc_매장월인덱스!$P$2:$AA$242,0,$A16)*(ISNUMBER(INDEX([1]Calc_매장월인덱스!$P$2:$AA$242,0,$A16)))*([1]Calc_매장월인덱스!$AB$2:$AB$242=0)*(([1]Calc_매장월인덱스!$B$2:$B$242*12+$A16) - ([1]Calc_매장월인덱스!$AD$2:$AD$242*12+[1]Calc_매장월인덱스!$AE$2:$AE$242)>=6),0))/E16,"-")} -> 115.59456 | G16: {=IFERROR(_xlfn.AGGREGATE(17,6,INDEX([1]Calc_매장월인덱스!$P$2:$AA$242,0,$A16)/(([1]Calc_매장월인덱스!$AB$2:$AB$242=0)*ISNUMBER(INDEX([1]Calc_매장월인덱스!$P$2:$AA$242,0,$A16))*(([1]Calc_매장월인덱스!$B$2:$B$242*12+$A16) - ([1]Calc_매장월인덱스!$AD$2:$AD$242*12+[1]Calc_매장월인덱스!$AE$2:$AE$242)>=6)),2),"-")} -> 115.39964 | H16: =IFERROR(F16-C16,"-") -> 0
A17: 11 | B17: {=SUMPRODUCT((ISNUMBER([1]Calc_매장월인덱스!Z$2:Z$242))*([1]Calc_매장월인덱스!AB$2:AB$242=0))} -> 218 | C17: {=IFERROR(SUMPRODUCT(IFERROR([1]Calc_매장월인덱스!Z$2:Z$242*(ISNUMBER([1]Calc_매장월인덱스!Z$2:Z$242))*([1]Calc_매장월인덱스!AB$2:AB$242=0),0))/B17,"-")} -> 104.11252 | D17: {=IFERROR(_xlfn.AGGREGATE(17,6,[1]Calc_매장월인덱스!Z$2:Z$242/(([1]Calc_매장월인덱스!AB$2:AB$242=0)*ISNUMBER([1]Calc_매장월인덱스!Z$2:Z$242)),2),"-")} -> 104.08415 | E17: {=SUMPRODUCT((ISNUMBER(INDEX([1]Calc_매장월인덱스!$P$2:$AA$242,0,$A17)))*([1]Calc_매장월인덱스!$AB$2:$AB$242=0)*(([1]Calc_매장월인덱스!$B$2:$B$242*12+$A17) - ([1]Calc_매장월인덱스!$AD$2:$AD$242*12+[1]Calc_매장월인덱스!$AE$2:$AE$242)>=6))} -> 218 | F17: {=IFERROR(SUMPRODUCT(IFERROR(INDEX([1]Calc_매장월인덱스!$P$2:$AA$242,0,$A17)*(ISNUMBER(INDEX([1]Calc_매장월인덱스!$P$2:$AA$242,0,$A17)))*([1]Calc_매장월인덱스!$AB$2:$AB$242=0)*(([1]Calc_매장월인덱스!$B$2:$B$242*12+$A17) - ([1]Calc_매장월인덱스!$AD$2:$AD$242*12+[1]Calc_매장월인덱스!$AE$2:$AE$242)>=6),0))/E17,"-")} -> 104.11252 | G17: {=IFERROR(_xlfn.AGGREGATE(17,6,INDEX([1]Calc_매장월인덱스!$P$2:$AA$242,0,$A17)/(([1]Calc_매장월인덱스!$AB$2:$AB$242=0)*ISNUMBER(INDEX([1]Calc_매장월인덱스!$P$2:$AA$242,0,$A17))*(([1]Calc_매장월인덱스!$B$2:$B$242*12+$A17) - ([1]Calc_매장월인덱스!$AD$2:$AD$242*12+[1]Calc_매장월인덱스!$AE$2:$AE$242)>=6)),2),"-")} -> 104.08415 | H17: =IFERROR(F17-C17,"-") -> 0
A18: 12 | B18: {=SUMPRODUCT((ISNUMBER([1]Calc_매장월인덱스!AA$2:AA$242))*([1]Calc_매장월인덱스!AB$2:AB$242=0))} -> 218 | C18: {=IFERROR(SUMPRODUCT(IFERROR([1]Calc_매장월인덱스!AA$2:AA$242*(ISNUMBER([1]Calc_매장월인덱스!AA$2:AA$242))*([1]Calc_매장월인덱스!AB$2:AB$242=0),0))/B18,"-")} -> 103.33184 | D18: {=IFERROR(_xlfn.AGGREGATE(17,6,[1]Calc_매장월인덱스!AA$2:AA$242/(([1]Calc_매장월인덱스!AB$2:AB$242=0)*ISNUMBER([1]Calc_매장월인덱스!AA$2:AA$242)),2),"-")} -> 102.19251 | E18: {=SUMPRODUCT((ISNUMBER(INDEX([1]Calc_매장월인덱스!$P$2:$AA$242,0,$A18)))*([1]Calc_매장월인덱스!$AB$2:$AB$242=0)*(([1]Calc_매장월인덱스!$B$2:$B$242*12+$A18) - ([1]Calc_매장월인덱스!$AD$2:$AD$242*12+[1]Calc_매장월인덱스!$AE$2:$AE$242)>=6))} -> 218 | F18: {=IFERROR(SUMPRODUCT(IFERROR(INDEX([1]Calc_매장월인덱스!$P$2:$AA$242,0,$A18)*(ISNUMBER(INDEX([1]Calc_매장월인덱스!$P$2:$AA$242,0,$A18)))*([1]Calc_매장월인덱스!$AB$2:$AB$242=0)*(([1]Calc_매장월인덱스!$B$2:$B$242*12+$A18) - ([1]Calc_매장월인덱스!$AD$2:$AD$242*12+[1]Calc_매장월인덱스!$AE$2:$AE$242)>=6),0))/E18,"-")} -> 103.33184 | G18: {=IFERROR(_xlfn.AGGREGATE(17,6,INDEX([1]Calc_매장월인덱스!$P$2:$AA$242,0,$A18)/(([1]Calc_매장월인덱스!$AB$2:$AB$242=0)*ISNUMBER(INDEX([1]Calc_매장월인덱스!$P$2:$AA$242,0,$A18))*(([1]Calc_매장월인덱스!$B$2:$B$242*12+$A18) - ([1]Calc_매장월인덱스!$AD$2:$AD$242*12+[1]Calc_매장월인덱스!$AE$2:$AE$242)>=6)),2),"-")} -> 102.19251 | H18: =IFERROR(F18-C18,"-") -> 0
A20: * 이 시트는 Calc_매장월인덱스의 AB열(급락매장여부) 플래그를 SUMPRODUCT/AGGREGATE로 참조 — 원본/이상치 리스트가 바뀌면 자동 갱신

Sheet Raw_매출
A1: 세탁건조매출 | B1: 44348 | C1: 44378 | D1: 44409 | E1: 44440 | F1: 44470 | G1: 44501 | H1: 44531 | I1: 44562 | J1: 44593 | K1: 44621 | L1: 44652 | M1: 44682 | N1: 44713 | O1: 44743 | P1: 44774 | Q1: 44805 | R1: 44835 | S1: 44866 | T1: 44896 | U1: 44927 | V1: 44958 | W1: 44986 | X1: 45017 | Y1: 45047 | Z1: 45078 | AA1: 45108 | AB1: 45139 | AC1: 45170 | AD1: 45200 | AE1: 45231 | AF1: 45261 | AG1: 45292 | AH1: 45323 | AI1: 45352 | AJ1: 45383 | AK1: 45413 | AL1: 45444 | AM1: 45474 | AN1: 45505 | AO1: 45536 | AP1: 45566 | AQ1: 45597 | AR1: 45627 | AS1: 45658 | AT1: 45689 | AU1: 45717 | AV1: 45748 | AW1: 45778 | AX1: 45809 | AY1: 45839 | AZ1: 45870 | BA1: 45901 | BB1: 45931 | BC1: 45962 | BD1: 45992 | BE1: 46023 | BF1: 46054 | BG1: 46082 | BH1: 46113 | BI1: 46143
A2: (0001) 건대점 | B2: 193400 | C2: 7561200 | D2: 6431400 | E2: 8401000 | F2: 9178900 | G2: 7918000 | H2: 7795000 | I2: 6824100 | J2: 6134200 | K2: 7716900 | L2: 6987700 | M2: 7937400 | N2: 8624200 | O2: 9084500 | P2: 8553400 | Q2: 9049300 | R2: 9025800 | S2: 8478200 | T2: 7662100 | U2: 7313400 | V2: 6392700 | W2: 7458100 | X2: 7823300 | Y2: 9523600 | Z2: 8120450 | AA2: 8896850 | AB2: 7930450 | AC2: 7730050 | AD2: 8308350 | AE2: 8039450 | AF2: 6658900 | AG2: 8042150 | AH2: 7343550 | AI2: 8013100 | AJ2: 8572300 | AK2: 7700150 | AL2: 7368700 | AM2: 7751950 | AN2: 7486400 | AO2: 5874700 | AP2: 7656950 | AQ2: 7655950 | AR2: 7403150 | AS2: 6888050 | AT2: 6023950 | AU2: 7039850 | AV2: 7178950 | AW2: 7692850 | AX2: 7548250 | AY2: 6828650 | AZ2: 7331450 | BA2: 6538350 | BB2: 7767300 | BC2: 6271650 | BD2: 6644800 | BE2: 6189650 | BF2: 5298600 | BG2: 6216400 | BH2: 6160000 | BI2: 7042650
A3: (0002) 인헌점 | B3: 113000 | C3: 5491900 | D3: 4113500 | E3: 4667000 | F3: 5822000 | G3: 4470000 | H3: 4047000 | I3: 4335500 | J3: 3899500 | K3: 4436500 | L3: 4610000 | M3: 5362500 | N3: 5093500 | O3: 6120000 | P3: 5770500 | Q3: 4870500 | R3: 5568500 | S3: 4891500 | T3: 4932500 | U3: 4945000 | V3: 4775000 | W3: 5387500 | X3: 5181000 | Y3: 6133500 | Z3: 6177940 | AA3: 6730430 | AB3: 6296470 | AC3: 5602680 | AD3: 6418450 | AE3: 6200880 | AF3: 5144830 | AG3: 5403310 | AH3: 5798720 | AI3: 6636980 | AJ3: 6814250 | AK3: 6928350 | AL3: 6564910 | AM3: 6889200 | AN3: 7081180 | AO3: 6578010 | AP3: 7097730 | AQ3: 6262690 | AR3: 5861120 | AS3: 6091150 | AT3: 5360980 | AU3: 6384280 | AV3: 6532930 | AW3: 7210560 | AX3: 5709830 | AY3: 2724440 | AZ3: 2161790 | BA3: 2528070 | BB3: 3050900 | BC3: 2858500 | BD3: 2609500 | BE3: 2651600 | BF3: 2816850 | BG3: 2941800 | BH3: 3025050 | BI3: 3320250
A4: (0003) 구디점 | B4: 305600 | C4: 14270700 | D4: 13036800 | E4: 12786500 | F4: 14478400 | G4: 13358100 | H4: 12859700 | I4: 13752200 | J4: 11892500 | K4: 13332300 | L4: 13992600 | M4: 14353400 | N4: 15844200 | O4: 16917500 | P4: 14601200 | Q4: 13746000 | R4: 14436200 | S4: 12438800 | T4: 11463000 | U4: 8277300 | V4: 8065000 | W4: 8258100 | X4: 8535500 | Y4: 9539200 | Z4: 8136900 | AA4: 9184400 | AB4: 8502700 | AC4: 8079900 | AD4: 8428400 | AE4: 7169900 | AF4: 7121350 | AG4: 6754950 | AH4: 5790600 | AI4: 7513100 | AJ4: 7705650 | AK4: 4774400 | AL4: 10181900 | AM4: 10065050 | AN4: 9834250 | AO4: 9351100 | AP4: 9130600 | AQ4: 9090000 | AR4: 9096200 | AS4: 9008450 | AT4: 7824700 | AU4: 9602000 | AV4: 9729600 | AW4: 10671600 | AX4: 10915300 | AY4: 10145600 | AZ4: 11044350 | BA4: 10258350 | BB4: 11712250 | BC4: 10532000 | BD4: 9301150 | BE4: 9505900 | BF4: 8455650 | BG4: 9206350 | BH4: 9705850 | BI4: 10438350
A5: (0004) 신림점 | B5: 225000 | C5: 5867000 | D5: 5567000 | E5: 6162000 | F5: 7681000 | G5: 6670500 | H5: 5813500 | I5: 5581500 | J5: 5312000 | K5: 5392000 | L5: 4931000 | M5: 5678500 | N5: 6105000 | O5: 6447000 | P5: 5832500 | Q5: 5707000 | R5: 6481000 | S5: 5419000 | T5: 5264000 | U5: 5257500 | V5: 4730500 | W5: 5123500 | X5: 5227500 | Y5: 5865500 | Z5: 5057450 | AA5: 5614050 | AB5: 5238610 | AC5: 5974410 | AD5: 6724500 | AE5: 6098790 | AF5: 5098390 | AG5: 5628600 | AH5: 5016810 | AI5: 5616080 | AJ5: 6219450 | AK5: 5831070 | AL5: 5898290 | AM5: 6246000 | AN5: 6401340 | AO5: 5763860 | AP5: 6276860 | AQ5: 5620420 | AR5: 5156120 | AS5: 4802940 | AT5: 4354520 | AU5: 5698950 | AV5: 5225270 | AW5: 6762780 | AX5: 6475860 | AY5: 6354480 | AZ5: 6235990 | BA5: 5561620 | BB5: 7159160 | BC5: 5962910 | BD5: 5575050 | BE5: 5582450 | BF5: 4919230 | BG5: 5623570 | BH5: 5664970 | BI5: 6726340
A6: (0005) 대학점 | B6: 101600 | C6: 5185300 | D6: 4164300 | E6: 4560600 | F6: 4321600 | G6: 3515800 | H6: 3466000 | I6: 3489500 | J6: 3586000 | K6: 3789500 | L6: 3863500 | M6: 3971500 | N6: 4249000 | O6: 4566500 | P6: 3899000 | Q6: 3981500 | R6: 4572000 | S6: 3944500 | T6: 4158500 | U6: 4148500 | V6: 3937500 | W6: 4201500 | X6: 4697000 | Y6: 5190500 | Z6: 5006420 | AA6: 6001260 | AB6: 5706060 | AC6: 5288220 | AD6: 5271510 | AE6: 5290660 | AF6: 5309700 | AG6: 4944390 | AH6: 4308510 | AI6: 4813890 | AJ6: 5253860 | AK6: 5049090 | AL6: 5400140 | AM6: 6134350 | AN6: 5507800 | AO6: 5957000 | AP6: 6200290 | AQ6: 5956510 | AR6: 6442380 | AS6: 5531420 | AT6: 4860050 | AU6: 5984860 | AV6: 5844820 | AW6: 6767650 | AX6: 6254650 | AY6: 6135770 | AZ6: 6022900 | BA6: 5959750 | BB6: 6625130 | BC6: 6223620 | BD6: 5774800 | BE6: 5348430 | BF6: 5077690 | BG6: 5407950 | BH6: 5626210 | BI6: 6951900
A7: (0006) 서림점 | B7: 135400 | C7: 5622700 | D7: 5475200 | E7: 5693800 | F7: 6121600 | G7: 5632500 | H7: 5784200 | I7: 5609700 | J7: 4845400 | K7: 5985000 | L7: 5982400 | M7: 6652800 | N7: 7034000 | O7: 7942000 | P7: 7378900 | Q7: 6800800 | R7: 7920400 | S7: 6790000 | T7: 7096900 | U7: 6667800 | V7: 6378300 | W7: 6225700 | X7: 6767500 | Y7: 7858400 | Z7: 7598700 | AA7: 8510500 | AB7: 7465500 | AC7: 7789400 | AD7: 8231900 | AE7: 7505500 | AF7: 8696130 | AG7: 7062100 | AH7: 6631730 | AI7: 7402700 | AJ7: 8324160 | AK7: 6090380 | AL7: 3905140 | AM7: 4191900 | AN7: 4038270 | AO7: 3808730 | AP7: 4437330 | AQ7: 3889830 | AR7: 3729130 | AS7: 3034620 | AT7: 2887050 | AU7: 3192250 | AV7: 2118610 | AW7: 3251750 | AX7: 3385920 | AY7: 3426980 | AZ7: 3532330 | BA7: 3760850 | BB7: 4398100 | BC7: 3980300 | BD7: 4512950 | BE7: 4047600 | BF7: 3713800 | BG7: 4334550 | BH7: 4528600 | BI7: 5410950
A8: (0007) 낙성대점 | B8: 232000 | C8: 8519000 | D8: 7571000 | E8: 8082500 | F8: 8238000 | G8: 6528500 | H8: 6507500 | I8: 6164000 | J8: 6100000 | K8: 6835000 | L8: 6756000 | M8: 7323000 | N8: 7691500 | O8: 9214500 | P8: 8276000 | Q8: 8342500 | R8: 8444000 | S8: 7228500 | T8: 7708500 | U8: 7278000 | V8: 7083500 | W8: 8135500 | X8: 8787000 | Y8: 9587000 | Z8: 9329400 | AA8: 10312650 | AB8: 9135950 | AC8: 9564100 | AD8: 10192650 | AE8: 9283250 | AF8: 9728620 | AG8: 8951310 | AH8: 7716310 | AI8: 9159570 | AJ8: 7272460 | AK8: 6975130 | AL8: 7322570 | AM8: 7876880 | AN8: 7449240 | AO8: 7060980 | AP8: 7673890 | AQ8: 6579640 | AR8: 6457640 | AS8: 6277840 | AT8: 5647560 | AU8: 6659820 | AV8: 6305990 | AW8: 7502260 | AX8: 7933620 | AY8: 7291430 | AZ8: 6983520 | BA8: 6561910 | BB8: 7633680 | BC8: 7027210 | BD8: 6319060 | BE8: 6484900 | BF8: 5688630 | BG8: 6502630 | BH8: 6115690 | BI8: 7152950
A9: (0008) 트리하우스점 | C9: 493500 | D9: 364500 | E9: 360500 | F9: 517000 | G9: 416000 | H9: 484500 | I9: 396000 | J9: 449000 | K9: 603000 | L9: 647500 | M9: 843500 | N9: 866500 | O9: 1007000 | P9: 858000 | Q9: 889000 | R9: 789000 | S9: 631500 | T9: 537000 | U9: 492500 | V9: 433500 | W9: 463500 | X9: 580000 | Y9: 608500 | Z9: 680500 | AA9: 1179500 | AB9: 1033000 | AC9: 1140500 | AD9: 960000 | AE9: 1120000 | AF9: 1031500 | AG9: 957500 | AH9: 865000 | AI9: 1174000 | AJ9: 929500 | AK9: 803500 | AL9: 652000 | AM9: 971000 | AN9: 952000 | AO9: 1035000 | AP9: 950500 | AQ9: 969000 | AR9: 907000 | AS9: 971500 | AT9: 613500 | AU9: 814500 | AV9: 806000 | AW9: 1045500 | AX9: 1048000 | AY9: 970000 | AZ9: 1004000 | BA9: 756000 | BB9: 921500 | BC9: 1027000 | BD9: 981000 | BE9: 819000 | BF9: 934500 | BG9: 775000 | BH9: 759500 | BI9: 894500
A10: (0009) 신원점 | B10: 89000 | C10: 5686000 | D10: 5002500 | E10: 5012500 | F10: 5860000 | G10: 5140000 | H10: 5181500 | I10: 5370500 | J10: 4572000 | K10: 5852500 | L10: 5475000 | M10: 5232500 | N10: 6455000 | O10: 6301500 | P10: 6689500 | Q10: 5766500 | R10: 6628000 | S10: 6465000 | T10: 6007000 | U10: 5497500 | V10: 5549000 | W10: 6489500 | X10: 5716500 | Y10: 6931500 | Z10: 6094500 | AA10: 6557500 | AB10: 4508500 | AC10: 6401500 | AD10: 7132000 | AE10: 6379500 | AF10: 6707790 | AG10: 7199400 | AH10: 6548140 | AI10: 7695220 | AJ10: 7865860 | AK10: 7285940 | AL10: 6999740 | AM10: 7246850 | AN10: 6994320 | AO10: 6715340 | AP10: 6370430 | AQ10: 6443870 | AR10: 6394440 | AS10: 6957680 | AT10: 5623120 | AU10: 7082690 | AV10: 7182230 | AW10: 7384690 | AX10: 7499740 | AY10: 7155340 | AZ10: 7272910 | BA10: 6600190 | BB10: 7701240 | BC10: 7456340 | BD10: 7102410 | BE10: 6589380 | BF10: 6649300 | BG10: 7280680 | BH10: 6787020 | BI10: 8222690
A11: (0010) 별빛거리점 | I11: 1024500 | J11: 3038000 | K11: 3760500 | L11: 4223000 | M11: 5134000 | N11: 6009000 | O11: 6428000 | P11: 7036500 | Q11: 6246000 | R11: 6306500 | S11: 5716000 | T11: 5781000 | U11: 6321500 | V11: 5659500 | W11: 6860500 | X11: 5979500 | Y11: 6769500 | Z11: 6398200 | AA11: 7743300 | AB11: 6719000 | AC11: 6854300 | AD11: 6809350 | AE11: 6178650 | AF11: 5129650 | AG11: 5698700 | AH11: 4507150 | AI11: 4849300 | AJ11: 5109550 | AK11: 4821150 | AL11: 5158500 | AM11: 5891250 | AN11: 5184100 | AO11: 5209750 | AP11: 5461700 | AQ11: 5078200 | AR11: 5342150 | AS11: 5050200 | AT11: 4298150 | AU11: 4202600 | AV11: 5546900 | AW11: 6358450 | AX11: 5739450 | AY11: 6103800 | AZ11: 6312250 | BA11: 6232300 | BB11: 6727300 | BC11: 5403550 | BD11: 5090950 | BE11: 4663800 | BF11: 4691150 | BG11: 4864450 | BH11: 5300200 | BI11: 5874950
A12: (0011) 천안성정공원점 | S12: 724690 | T12: 3796220 | U12: 4466630 | V12: 4432000 | W12: 5810000 | X12: 6103500 | Y12: 6196000 | Z12: 6172500 | AA12: 7859000 | AB12: 7071000 | AC12: 6970000 | AD12: 7158000 | AE12: 6975780 | AF12: 6626070 | AG12: 6271020 | AH12: 5743010 | AI12: 6650250 | AJ12: 6668680 | AK12: 6766920 | AL12: 6305960 | AM12: 8553280 | AN12: 7604290 | AO12: 7373650 | AP12: 7781070 | AQ12: 7065200 | AR12: 7229070 | AS12: 7472630 | AT12: 5801400 | AU12: 6112000 | AV12: 7391060 | AW12: 7463680 | AX12: 7316800 | AY12: 7441710 | AZ12: 7568330 | BA12: 6919420 | BB12: 8074430 | BC12: 7907860 | BD12: 7176720 | BE12: 7894170 | BF12: 7549070 | BG12: 7424070 | BH12: 7803150 | BI12: 7426530
A13: (0012) 우송대북문점 | AL13: 252630 | AM13: 2815040 | AN13: 2979770 | AO13: 4058690 | AP13: 4244670 | AQ13: 3901170 | AR13: 4137000 | AS13: 4029740 | AT13: 3456300 | AU13: 4217440 | AV13: 3606060 | AW13: 4572480 | AX13: 3881900 | AY13: 3201480 | AZ13: 3308240 | BA13: 4875210 | BB13: 5071500 | BC13: 4550800 | BD13: 4996700 | BE13: 4120100 | BF13: 4858400 | BG13: 5393000 | BH13: 4732000 | BI13: 4822200
A14: (0013) 구의역파워점 | AX14: 2901360 | AY14: 3114520 | AZ14: 3147610 | BA14: 3018930 | BB14: 3959300 | BC14: 3766160 | BD14: 3730110 | BE14: 3741410 | BF14: 3501570 | BG14: 3800870 | BH14: 4108020 | BI14: 4763630
A15: (0014) 수원서둔골드점 | AY15: 579050 | AZ15: 2577160 | BA15: 2606630 | BB15: 3332850 | BC15: 3206000 | BD15: 3063000 | BE15: 2495250 | BF15: 2861750 | BG15: 3129350 | BH15: 3389500 | BI15: 3566500
A16: (0015) 부평더갤러리점 | BG16: 573310 | BH16: 1605700 | BI16: 1493700
A17: (1001) #화곡점 | B17: 300000 | C17: 9797000 | D17: 8330000 | E17: 9148500 | F17: 10910500 | G17: 8399500 | H17: 9460500 | I17: 9689000 | J17: 7282000 | K17: 8815000 | L17: 9437500 | M17: 8720000 | N17: 8539000 | O17: 10246500 | P17: 9609500 | Q17: 8886000 | R17: 10681500 | S17: 9362000 | T17: 8747000 | U17: 8643000 | V17: 8872500 | W17: 9355500 | X17: 9435500 | Y17: 11152000 | Z17: 9888000 | AA17: 11507500 | AB17: 8975500 | AC17: 8647000 | AD17: 11127500 | AE17: 9377500 | AF17: 10459490 | AG17: 9315320 | AH17: 8691490 | AI17: 10230920 | AJ17: 10261510 | AK17: 10113700 | AL17: 10434330 | AM17: 10583310 | AN17: 11343820 | AO17: 10589780 | AP17: 11826280 | AQ17: 10354780 | AR17: 9945240 | AS17: 8726090 | AT17: 8684580 | AU17: 9709700 | AV17: 9125750 | AW17: 10492210 | AX17: 8948970 | AY17: 8820390 | AZ17: 8821320 | BA17: 8807750 | BB17: 10100080 | BC17: 8827710 | BD17: 7824260 | BE17: 8028880 | BF17: 6741410 | BG17: 8058110 | BH17: 8524730 | BI17: 9508830
A18: (1002) #신대방점 | B18: 162900 | C18: 5005700 | D18: 4116700 | E18: 3893100 | F18: 4867000 | G18: 4218500 | H18: 4663500 | I18: 4739000 | J18: 4105000 | K18: 4863500 | L18: 4976000 | M18: 4372500 | N18: 5344000 | O18: 5607000 | P18: 5939000 | Q18: 5307500 | R18: 5715500 | S18: 5141000 | T18: 5203000 | U18: 5281500 | V18: 4747000 | W18: 5107000 | X18: 5698000 | Y18: 6194500 | Z18: 5462500 | AA18: 6462500 | AB18: 5792500 | AC18: 6263300 | AD18: 7224800 | AE18: 5879400 | AF18: 6220400 | AG18: 5557400 | AH18: 4875600 | AI18: 6427400 | AJ18: 5744600 | AK18: 5728400 | AL18: 5759200 | AM18: 6529400 | AN18: 5522000 | AO18: 5510600 | AP18: 6626200 | AQ18: 5434600 | AR18: 4094600 | AS18: 3372000 | AT18: 2861400 | AU18: 3072500 | AV18: 3469500 | AW18: 3731000 | AX18: 3758500 | AY18: 3525000 | AZ18: 3398000 | BA18: 3718500 | BB18: 4242000 | BC18: 3727000 | BD18: 3853500 | BE18: 3732000 | BF18: 3645500 | BG18: 4002500 | BH18: 3900000 | BI18: 4283000
A19: (1003) #샤로수점 | B19: 160900 | C19: 6167000 | D19: 5894600 | E19: 5324000 | F19: 5867200 | G19: 5212300 | H19: 5785900 | I19: 5731000 | J19: 3497500 | K19: 5809000 | L19: 6256500 | M19: 6495000 | N19: 7392500 | O19: 7416000 | P19: 4969500 | Q19: 5310000 | R19: 7872000 | S19: 6198000 | T19: 6651000 | U19: 6735500 | V19: 6870500 | W19: 7128500 | X19: 7751000 | Y19: 8398500 | Z19: 8118000 | AA19: 8510500 | AB19: 7868000 | AC19: 9438200 | AD19: 9372400 | AE19: 9261600 | AF19: 8768000 | AG19: 8624400 | AH19: 7891800 | AI19: 9424200 | AJ19: 10016600 | AK19: 9180400 | AL19: 8423200 | AM19: 9026800 | AN19: 8070800 | AO19: 7208000 | AP19: 9132400 | AQ19: 8345400 | AR19: 8050000 | AS19: 7368200 | AT19: 6682600 | AU19: 7983600 | AV19: 7363600 | AW19: 9060600 | AX19: 7828400 | AY19: 7020200 | AZ19: 7140800 | BA19: 6098600 | BB19: 8072400 | BC19: 6767200 | BD19: 6612800 | BE19: 6812400 | BF19: 5891000 | BG19: 6861800 | BH19: 6759400 | BI19: 7667200
A20: (1004) #서울대입구점 | B20: 358000 | C20: 10842000 | D20: 10412500 | E20: 9646500 | F20: 11898000 | G20: 9691000 | H20: 9495500 | I20: 8529500 | J20: 8592500 | K20: 9463000 | L20: 10011000 | M20: 11021000 | N20: 12488000 | O20: 13288000 | P20: 12073000 | Q20: 11503500 | R20: 12617500 | S20: 11042000 | T20: 10232000 | U20: 9421500 | V20: 9262500 | W20: 10885500 | X20: 11310500 | Y20: 12703500 | Z20: 11778500 | AA20: 13434000 | AB20: 12039500 | AC20: 13014500 | AD20: 13519500 | AE20: 12081500 | AF20: 13822000 | AG20: 12847720 | AH20: 11537500 | AI20: 13583360 | AJ20: 13754390 | AK20: 14685930 | AL20: 14786330 | AM20: 15602870 | AN20: 15676800 | AO20: 14265520 | AP20: 15605550 | AQ20: 13923970 | AR20: 13777470 | AS20: 12265540 | AT20: 11858590 | AU20: 13491510 | AV20: 12438310 | AW20: 10975260 | AX20: 10542270 | AY20: 10124560 | AZ20: 10602220 | BA20: 9904860 | BB20: 10266440 | BC20: 9596170 | BD20: 9040750 | BE20: 8867830 | BF20: 7979050 | BG20: 9394080 | BH20: 9811540 | BI20: 10528110
A21: (1005) #쑥고개점 | B21: 160200 | C21: 6669800 | D21: 6049500 | E21: 6038000 | F21: 7350500 | G21: 4811500 | H21: 4456500 | I21: 4368500 | J21: 3727000 | K21: 4845500 | L21: 5291500 | M21: 5237500 | N21: 4841500 | O21: 5230000 | P21: 5388500 | Q21: 4948000 | R21: 5459500 | S21: 4943000 | T21: 4689500 | U21: 4993500 | V21: 4275000 | W21: 4849500 | X21: 4887500 | Y21: 5134000 | Z21: 4778000 | AA21: 5688500 | AB21: 4904500 | AC21: 5171500 | AD21: 5728500 | AE21: 5328500 | AF21: 5206580 | AG21: 5253200 | AH21: 4652840 | AI21: 5612320 | AJ21: 5331450 | AK21: 4914550 | AL21: 5110670 | AM21: 5469140 | AN21: 5280500 | AO21: 4875680 | AP21: 5009020 | AQ21: 4768920 | AR21: 5259500 | AS21: 4714700 | AT21: 4053750 | AU21: 4784710 | AV21: 4925930 | AW21: 5087070 | AX21: 4734180 | AY21: 4904200 | AZ21: 4869260 | BA21: 4245400 | BB21: 5282480 | BC21: 4561100 | BD21: 4677040 | BE21: 4462660 | BF21: 3974920 | BG21: 4735240 | BH21: 4512120 | BI21: 5174420
A22: (1006) #회기점 | B22: 250000 | C22: 8516500 | D22: 8091000 | E22: 8510500 | F22: 10252000 | G22: 8035500 | H22: 9166500 | I22: 8580500 | J22: 7955000 | K22: 9305000 | L22: 9615000 | M22: 9571000 | N22: 7891500 | O22: 7640000 | P22: 7311000 | Q22: 7329000 | R22: 8223500 | S22: 6691000 | T22: 6318500 | U22: 5128000 | V22: 5895500 | W22: 6005500 | X22: 6475500 | Y22: 7017500 | Z22: 6493500 | AA22: 6497000 | AB22: 6514000 | AC22: 7155500 | AD22: 7779000 | AE22: 6906500 | AF22: 6580280 | AG22: 5887920 | AH22: 5758180 | AI22: 7449380 | AJ22: 7247230 | AK22: 7077020 | AL22: 7406340 | AM22: 7222730 | AN22: 7663610 | AO22: 7445380 | AP22: 8189720 | AQ22: 6669310 | AR22: 6821720 | AS22: 5543720 | AT22: 5922960 | AU22: 8025080 | AV22: 7719310 | AW22: 8348740 | AX22: 8779580 | AY22: 7409400 | AZ22: 8273220 | BA22: 8184130 | BB22: 8893430 | BC22: 8251020 | BD22: 7471450 | BE22: 6534530 | BF22: 6427450 | BG22: 7929520 | BH22: 7055400 | BI22: 8842070
A23: (1007) #구의점 | B23: 290500 | C23: 8485000 | D23: 7869000 | E23: 7305500 | F23: 9158000 | G23: 6790000 | H23: 7335500 | I23: 7721000 | J23: 6881000 | K23: 8523500 | L23: 8923500 | M23: 8629000 | N23: 8660000 | O23: 9931000 | P23: 9330500 | Q23: 9306000 | R23: 9921000 | S23: 8436500 | T23: 8868500 | U23: 9811500 | V23: 8291000 | W23: 9793500 | X23: 10481000 | Y23: 11578500 | Z23: 10528200 | AA23: 11507000 | AB23: 9777000 | AC23: 9560500 | AD23: 10501000 | AE23: 10341500 | AF23: 10944840 | AG23: 9475600 | AH23: 9121730 | AI23: 10189400 | AJ23: 10809500 | AK23: 10355440 | AL23: 10771330 | AM23: 10468340 | AN23: 10016670 | AO23: 9479670 | AP23: 11208450 | AQ23: 9399790 | AR23: 9413620 | AS23: 10400210 | AT23: 8258200 | AU23: 10555710 | AV23: 10349470 | AW23: 11023910 | AX23: 11082780 | AY23: 9979110 | AZ23: 7704840 | BA23: 6931420 | BB23: 9913760 | BC23: 9338320 | BD23: 8605630 | BE23: 8751460 | BF23: 8546190 | BG23: 9363840 | BH23: 9607310 | BI23: 11178750
A24: (1008) #개포드림웍스점 | B24: 107910 | C24: 2792940 | D24: 2680380 | E24: 2911140 | F24: 3372820 | G24: 2684450 | H24: 2327630 | I24: 2432140 | J24: 2305650 | K24: 2364750 | L24: 2576620 | M24: 2567920 | N24: 2915820 | O24: 3096650 | P24: 2857630 | Q24: 3039250 | R24: 2940890 | S24: 2876900 | T24: 3242970 | U24: 3118120 | V24: 3092070 | W24: 3259420 | X24: 3113560 | Y24: 3618570 | Z24: 2956830 | AA24: 3683210 | AB24: 2796130 | AC24: 3071310 | AD24: 3006370 | AE24: 3204320 | AF24: 3818410 | AG24: 3789040 | AH24: 2782300 | AI24: 3345970 | AJ24: 4178840 | AK24: 3723580 | AL24: 3541120 | AM24: 3753340 | AN24: 3394030 | AO24: 3590350 | AP24: 3780670 | AQ24: 3373020 | AR24: 3527940 | AS24: 3853930 | AT24: 3233040 | AU24: 4092070 | AV24: 4190610 | AW24: 4416860 | AX24: 3935110 | AY24: 4219400 | AZ24: 3707810 | BA24: 3154800 | BB24: 4254140 | BC24: 3613510 | BD24: 2904400 | BE24: 3662330 | BF24: 2981240 | BG24: 3528600 | BH24: 3522180 | BI24: 4000060
A25: (1009) #진시스장항점 | B25: 49100 | C25: 2515500 | D25: 2167800 | E25: 2133500 | F25: 2667300 | G25: 2493700 | H25: 2872800 | I25: 2458500 | J25: 2126700 | K25: 2748700 | L25: 3015700 | M25: 2733100 | N25: 2804800 | O25: 2803200 | P25: 2500700 | Q25: 1058400 | R25: 1975180 | S25: 3265460 | T25: 3786060 | U25: 4151500 | V25: 3014000 | W25: 3982000 | X25: 3778500 | Y25: 4229000 | Z25: 3715500 | AA25: 5300000 | AB25: 4318000 | AC25: 4482500 | AD25: 4670000 | AE25: 4192500 | AF25: 4553400 | AG25: 4749700 | AH25: 4063450 | AI25: 4746000 | AJ25: 4838100 | AK25: 5028000 | AL25: 5009200 | AM25: 5167550 | AN25: 5111250 | AO25: 5034800 | AP25: 5446050 | AQ25: 5023800 | AR25: 4888800 | AS25: 4624850 | AT25: 4227700 | AU25: 5397850 | AV25: 5102650 | AW25: 6103400 | AX25: 6288300 | AY25: 6135800 | AZ25: 6365000 | BA25: 5700000 | BB25: 7808750 | BC25: 6055350 | BD25: 5684100 | BE25: 5675300 | BF25: 4651600 | BG25: 5511850 | BH25: =232850+6122200 -> 6355050 | BI25: 7472050
A26: (1010) #삼전엠케이점 | B26: 43400 | C26: 2481900 | D26: 2663300 | E26: 2688800 | F26: 3430000 | G26: 2657300 | H26: 3444000 | I26: 3614500 | J26: 3231000 | K26: 3394500 | L26: 3634000 | M26: 3589000 | N26: 3739000 | O26: 3712000 | P26: 3857500 | Q26: 4159500 | R26: 3971000 | S26: 3627500 | T26: 4036500 | U26: 4383500 | V26: 3303500 | W26: 4023000 | X26: 4344000 | Y26: 4117500 | Z26: 4147500 | AA26: 4936000 | AB26: 4202500 | AC26: 4462500 | AD26: 5055500 | AE26: 4676500 | AF26: 5332570 | AG26: 4967430 | AH26: 4421540 | AI26: 5214210 | AJ26: 4671920 | AK26: 5158770 | AL26: 5111760 | AM26: 4592850 | AN26: 3920990 | AO26: 4229260 | AP26: 4753230 | AQ26: 4000920 | AR26: 3880610 | AS26: 4316420 | AT26: 3466120 | AU26: 4518390 | AV26: 4194890 | AW26: 4870350 | AX26: 4629080 | AY26: 4027720 | AZ26: 3953940 | BA26: 4259370 | BB26: 4577500 | BC26: 4141100 | BD26: 3728700 | BE26: 4248000 | BF26: 4106300 | BG26: 4483100 | BH26: 4410900 | BI26: 5325500
A27: (1011) #신길점 | B27: 134100 | C27: 3575600 | D27: 3502100 | E27: 2994000 | F27: 3578800 | G27: 3325700 | H27: 3298000 | I27: 3260500 | J27: 2783500 | K27: 3737000 | L27: 3961500 | M27: 4587000 | N27: 5125500 | O27: 6490500 | P27: 6642000 | Q27: 6090500 | R27: 6797000 | S27: 5830000 | T27: 5463000 | U27: 4484500 | V27: 4034500 | W27: 5008500 | X27: 6490000 | Y27: 6792000 | Z27: 6466000 | AA27: 7506500 | AB27: 6586500 | AC27: 6711500 | AD27: 7452000 | AE27: 5567000 | AF27: 5509230 | AG27: 5636810 | AH27: 4247130 | AI27: 5759570 | AJ27: 6327940 | AK27: 6600900 | AL27: 7417440 | AM27: 7874510 | AN27: 8147000 | AO27: 7879680 | AP27: 7766690 | AQ27: 6376050 | AR27: 6797580 | AS27: 6231420 | AT27: 5395260 | AU27: 6669100 | AV27: 7720050 | AW27: 8341750 | AX27: 9001540 | AY27: 8769120 | AZ27: 8194190 | BA27: 7707120 | BB27: 9092230 | BC27: 9739660 | BD27: 8190680 | BE27: 6678590 | BF27: 7222350 | BG27: 9008250 | BH27: 10035590 | BI27: 10970960
A28: (1012) #석촌점 | B28: 64000 | C28: 4078500 | D28: 3493500 | E28: 3612000 | F28: 5201000 | G28: 3896300 | H28: 4702000 | I28: 5186500 | J28: 4436600 | K28: 5572400 | L28: 5367700 | M28: 5216000 | N28: 5125500 | O28: 5716700 | P28: 5388100 | Q28: 4735400 | R28: 5957100 | S28: 5041400 | T28: 5375000 | U28: 5511700 | V28: 4496900 | W28: 5187700 | X28: 4935200 | Y28: 5469900 | Z28: 3331900 | AA28: 6243200 | AB28: 4438400 | AC28: 4622700 | AD28: 5872500 | AE28: 4876600 | AF28: 5555490 | AG28: 5383790 | AH28: 5203290 | AI28: 5888760 | AJ28: 6195780 | AK28: 5787130 | AL28: 5389270 | AM28: 5954180 | AN28: 4720540 | AO28: 5244680 | AP28: 5952470 | AQ28: 5255030 | AR28: 5899320 | AS28: 5835590 | AT28: 5062470 | AU28: 6000380 | AV28: 5647630 | AW28: 7145610 | AX28: 6690290 | AY28: 5614530 | AZ28: 4895660 | BA28: 4854620 | BB28: 6867160 | BC28: 4788360 | BD28: 4963150 | BE28: 5412120 | BF28: 5318320 | BG28: 5218990 | BH28: 5339260 | BI28: 6210960
A29: (1013) #방이점 | B29: 193000 | C29: 6766500 | D29: 6400000 | E29: 6530500 | F29: 7145000 | G29: 5332000 | H29: 5178500 | I29: 4343000 | J29: 4393000 | K29: 5435500 | L29: 5538000 | M29: 6039000 | N29: 6545000 | O29: 7161500 | P29: 7213500 | Q29: 6700000 | R29: 6726000 | S29: 6103500 | T29: 5761500 | U29: 5524500 | V29: 5292000 | W29: 6307500 | X29: 6084000 | Y29: 7411000 | Z29: 5995500 | AA29: 6601500 | AB29: 4246500 | AC29: 3935500 | AD29: 4140500 | AE29: 3367500 | AF29: 3146000 | AG29: 2662000 | AH29: 2732000 | AI29: 3372500 | AJ29: 3613500 | AK29: 3608500 | AL29: 3809500 | AM29: 3298000 | AN29: 3403500 | AO29: 1099500
A30: (1014) #자곡점 | B30: 205500 | C30: 7196500 | D30: 6652000 | E30: 6313000 | F30: 8014500 | G30: 6486500 | H30: 6464000 | I30: 6994000 | J30: 6004000 | K30: 7379000 | L30: 6228900 | M30: 6867000 | N30: 6478000 | O30: 7080000 | P30: 5789000 | Q30: 5341500 | R30: 6305000 | S30: 5697000 | T30: 5990000 | U30: 5863000 | V30: 5259500 | W30: 6671500 | X30: 6479000 | Y30: 6415500 | Z30: 6328500 | AA30: 7164500 | AB30: 6106500 | AC30: 6438500 | AD30: 7572000 | AE30: 6782000 | AF30: 6934500 | AG30: 6780400 | AH30: 5970600 | AI30: 7655900 | AJ30: 7666950 | AK30: 7182300 | AL30: 6988950 | AM30: 7102750 | AN30: 6502950 | AO30: 5938250 | AP30: 6866800 | AQ30: 6242600 | AR30: 5865950 | AS30: 5387250 | AT30: 4890950 | AU30: 5990000 | AV30: 5930350 | AW30: 6212500 | AX30: 7344000 | AY30: 7234450 | AZ30: 7934800 | BA30: 6979650 | BB30: 9038850 | BC30: 7457450 | BD30: 6752600 | BE30: 6777100 | BF30: 7126800 | BG30: 7512800 | BH30: 7185100 | BI30: 9330100
A31: (1015) #사당점 | B31: 144000 | C31: 6831000 | D31: 6159000 | E31: 5934500 | F31: 7562500 | G31: 6655000 | H31: 5978000 | I31: 6216000 | J31: 5828000 | K31: 7082000 | L31: 7406000 | M31: 8058000 | N31: 8268000 | O31: 8857000 | P31: 9470000 | Q31: 8510500 | R31: 9286000 | S31: 7863500 | T31: 8120000 | U31: 7867000 | V31: 7418000 | W31: 8630000 | X31: 8640500 | Y31: 9895000 | Z31: 8844000 | AA31: 9774000 | AB31: 8625500 | AC31: 6593500 | AD31: 10137000 | AE31: 8912500 | AF31: 10304160 | AG31: 9959250 | AH31: 8365920 | AI31: 10340560 | AJ31: 10158810 | AK31: 10222190 | AL31: 10398840 | AM31: 9200510 | AN31: 9427790 | AO31: 9524120 | AP31: 9992710 | AQ31: 9086770 | AR31: 9713790 | AS31: 8808800 | AT31: 8056240 | AU31: 9428550 | AV31: 9091630 | AW31: 10477590 | AX31: 10186590 | AY31: 9130830 | AZ31: 9169920 | BA31: 8984620 | BB31: 10207850 | BC31: 8681140 | BD31: 8705650 | BE31: 7988460 | BF31: 7943530 | BG31: 9158030 | BH31: 9059550 | BI31: 10175060
A32: (1016) #가산점 | B32: 57500 | C32: 4348500 | D32: 4315500 | E32: 5101500 | F32: 5549500 | G32: 4949500 | H32: 5817000 | I32: 5412500 | J32: 5008500 | K32: 5805500 | L32: 5518500 | M32: 5676000 | N32: 6097000 | O32: 6223000 | P32: 6785000 | Q32: 6392500 | R32: 6694000 | S32: 5975500 | T32: 6672000 | U32: 6612000 | V32: 6523500 | W32: 7278000 | X32: 7228500 | Y32: 7412500 | Z32: 6903500 | AA32: 7517000 | AB32: 6519000 | AC32: 7099500 | AD32: 7770500 | AE32: 7152000 | AF32: 8600370 | AG32: 7240180 | AH32: 6589950 | AI32: 8158470 | AJ32: 8039210 | AK32: 8155310 | AL32: 4349930 | AM32: 4847960 | AN32: 4442210 | AO32: 3966950 | AP32: 3820070 | AQ32: 4038380 | AR32: 3968690 | AS32: 3736980 | AT32: 3670180 | AU32: 4407920 | AV32: 3984710 | AW32: 4381780 | AX32: 4284260 | AY32: 4021480 | AZ32: 4116370 | BA32: 3985290 | BB32: 5673450 | BC32: 4627720 | BD32: 4432120 | BE32: 4432560 | BF32: 4494040 | BG32: 4305240 | BH32: 4430440 | BI32: 4799860
A33: (1017) #마곡점 | B33: 90500 | C33: 3334700 | D33: 2816400 | E33: 3062700 | F33: 4020000 | G33: 2774900 | H33: 3299400 | I33: 3546100 | J33: 2762000 | K33: 3428900 | L33: 3839800 | M33: 3875100 | N33: 3689700 | Q33: 622900 | R33: 2605600 | S33: 2628900 | T33: 3425650 | U33: 3031420 | V33: 2728000 | W33: 2979100 | X33: 3564900 | Y33: 4222900 | Z33: 3829500 | AA33: 4046700 | AB33: 3656900 | AC33: 4016500 | AD33: 4121300 | AE33: 3545900 | AF33: 4453100 | AG33: 3630700 | AH33: 3352600 | AI33: 3991900 | AJ33: 4224400 | AK33: 3970800 | AL33: 4164200 | AM33: 3726900 | AN33: 3913700 | AO33: 3583100 | AP33: 3996300 | AQ33: 3336200
A34: (1018) #논현점 | B34: 239400 | C34: 6905600 | D34: 6378700 | E34: 6224500 | F34: 7510900 | G34: 6465700 | H34: 6587300 | I34: 6129100 | J34: 5368300 | K34: 6973200 | L34: 7346900 | M34: 9148400 | N34: 8081400 | O34: 9807800 | P34: 8905600 | Q34: 8269400 | R34: 9136700 | S34: 8250300 | T34: 7905100 | U34: 7259400 | V34: 6502500 | W34: 7969900 | X34: 7060900 | Y34: 5173300 | Z34: 4532100 | AA34: 5875700 | AB34: 4747700 | AC34: 4526400 | AD34: 4985700 | AE34: 4090500 | AF34: 4023040 | AG34: 4172390 | AH34: 3762640 | AI34: 4205350 | AJ34: 3666470 | AK34: 4222730 | AL34: 3695520 | AM34: 4522550 | AN34: 3685860 | AO34: 3820460 | AP34: 4110080 | AQ34: 3836690 | AR34: 4385550 | AS34: 3810630 | AT34: 3528430 | AU34: 4233650 | AV34: 3985300 | AW34: 4156940 | AX34: 4091750 | AY34: 172290
A35: (1019) #청룡점 | B35: 136500 | C35: 3523000 | D35: 3599000 | E35: 3430500 | F35: 4718000 | G35: 4005500 | H35: 4507500 | I35: 4153000 | J35: 3738000 | K35: 4629500 | L35: 4502500 | M35: 5310500 | N35: 5380500 | O35: 5842000 | P35: 5876000 | Q35: 5467000 | R35: 6178500 | S35: 4951500 | T35: 5222000 | U35: 4723000 | V35: 4998000 | W35: 5545500 | X35: 5388000 | Y35: 6160000 | Z35: 5806000 | AA35: 6546000 | AB35: 4618500 | AC35: 4493000 | AD35: 5190000 | AE35: 4649000 | AF35: 4501500 | AG35: 4393700 | AH35: 3417950 | AI35: 4395900 | AJ35: 4733750 | AK35: 4240850 | AL35: 4766250 | AM35: 4913550 | AN35: 4297850 | AO35: 3721000 | AP35: 3964200 | AQ35: 3871100 | AR35: 4075650 | AS35: 3486550 | AT35: 3385350 | AU35: 4213150 | AV35: 3762200 | AW35: 4398710 | AX35: 4626040 | AY35: 5097490 | AZ35: 4871310 | BA35: 5063830 | BB35: 6045340 | BC35: 4818550 | BD35: 4600150 | BE35: 4119540 | BF35: 4270330 | BG35: 4789250 | BH35: 4757300 | BI35: 5403610
A36: (1020) #신길삼거리점 | B36: 44000 | C36: 3382000 | D36: 2840000 | E36: 3155000 | F36: 4446000 | G36: 3687500 | H36: 3863000 | I36: 4102500 | J36: 3513500 | K36: 4040500 | L36: 4175000 | M36: 3637000 | N36: 3887000 | O36: 4849500 | P36: 4727500 | Q36: 3935000 | R36: 4866000 | S36: 4560000 | T36: 5093500 | U36: 5897500 | V36: 4887000 | W36: 5437500 | X36: 5194500 | Y36: 5701500 | Z36: 5058680 | AA36: 6213750 | AB36: 5166770 | AC36: 5551660 | AD36: 5641400 | AE36: 6405160 | AF36: 5595300 | AG36: 6130550 | AH36: 5898050 | AI36: 6421200 | AJ36: 5881500 | AK36: 5735050 | AL36: 5822650 | AM36: 6249400 | AN36: 5303450 | AO36: 5839850 | AP36: 6539550 | AQ36: 6325350 | AR36: 6008700 | AS36: 6261450 | AT36: 5487800 | AU36: 6840150 | AV36: 5798950 | AW36: 6543150 | AX36: 6225650 | AY36: 5765000 | AZ36: 5607200 | BA36: 5695500 | BB36: 7198350 | BC36: 6109700 | BD36: 6027150 | BE36: 5981600 | BF36: 5618600 | BG36: 5493850 | BH36: 5848050 | BI36: 6295450
A37: (1021) #광주전남대점 | B37: 39000 | C37: 2775000 | D37: 3072500 | E37: 3196500 | F37: 3637500 | G37: 3383000 | H37: 3501000 | I37: 3574500 | J37: 3500000 | K37: 3440500 | L37: 2538000 | M37: 2498000 | N37: 2493500 | O37: 2600500 | P37: 3094000 | Q37: 2442500 | R37: 2364500 | S37: 2384500 | T37: 2424000 | U37: 2680000 | V37: 2526500 | W37: 2624000 | X37: 2745500 | Y37: 2892000 | Z37: 2676000 | AA37: 3282000 | AB37: 2582000 | AC37: 3027000 | AD37: 2887500 | AE37: 2593000 | AF37: 2633000 | AG37: 2632000 | AH37: 2539000 | AI37: 2811500 | AJ37: 2873000 | AK37: 2705000 | AL37: 2625500 | AM37: 2910500 | AN37: 2498000 | AO37: 2520000 | AP37: 2565500 | AQ37: 2375000 | AR37: 2636500 | AS37: 2869000 | AT37: 2224000 | AU37: 2613500 | AV37: 2050000 | AW37: 2087000 | AX37: 2147000 | AY37: 1807000 | AZ37: 2435500 | BA37: 2300450 | BB37: 2230300 | BC37: 2264310 | BD37: 2289640 | BE37: 1692500 | BF37: 1678500 | BG37: 1907000 | BH37: 1801500 | BI37: 2014500
A38: (1022) #서울시립대점 | B38: 67500 | C38: 4295900 | D38: 4795700 | E38: 5295000 | F38: 5872100 | G38: 5011300 | H38: 4442500 | I38: 5111200 | J38: 5327000 | K38: 5967700 | L38: 6499500 | M38: 7031700 | N38: 7347500 | O38: 8451000 | P38: 8659500 | Q38: 8720000 | R38: 8181500 | S38: 7156500 | T38: 7193500 | U38: 6945500 | V38: 7067500 | W38: 9056000 | X38: 8582500 | Y38: 9666000 | Z38: 8909370 | AA38: 9851230 | AB38: 9063890 | AC38: 8842310 | AD38: 8798800 | AE38: 8265090 | AF38: 7012000 | AG38: 6992300 | AH38: 7084800 | AI38: 8727050 | AJ38: 6940900 | AK38: 6626600 | AL38: 6642050 | AM38: 7487500 | AN38: 8021000 | AO38: 7478150 | AP38: 7348800 | AQ38: 7505500 | AR38: 7187950 | AS38: 6239300 | AT38: 6536650 | AU38: 6964750 | AV38: 7007700 | AW38: 8140100 | AX38: 7768850 | AY38: 7097300 | AZ38: 7523750 | BA38: 7520450 | BB38: 8731950 | BC38: 7972700 | BD38: 7717000 | BE38: 6783600 | BF38: 6183400 | BG38: 6019550 | BH38: 5983250 | BI38: 6380200
A39: (1023) #동탄석우동점 | B39: 89400 | C39: 3413700 | D39: 2981400 | E39: 2960500 | F39: 3840500 | G39: 2901500 | H39: 3291700 | I39: 3579200 | J39: 3537700 | K39: 3980400 | L39: 4165700 | M39: 4105200 | N39: 4532400 | O39: 4927100 | P39: 5012400 | Q39: 4472900 | R39: 5367100 | S39: 4912000 | T39: 4531800 | U39: 4314800 | V39: 3914200 | W39: 4417000 | X39: 4726300 | Y39: 4946500 | Z39: 4144600 | AA39: 4947200 | AB39: 4325800 | AC39: 4159300 | AD39: 4656500 | AE39: 3805900 | AF39: 3773330 | AG39: 3837040 | AH39: 3562310 | AI39: 4502550 | AJ39: 4596930 | AK39: 4246310 | AL39: 4389690 | AM39: 4113520 | AN39: 4094980 | AO39: 3907140 | AP39: 4554520 | AQ39: 4486390 | AR39: 3620670 | AS39: 3827510 | AT39: 3578310 | AU39: 4034280 | AV39: 3609630 | AW39: 4169110 | AX39: 3942120 | AY39: 3983110 | AZ39: 4925070 | BA39: 4079270 | BB39: 5311570 | BC39: 4556520 | BD39: 4167600 | BE39: 4815420 | BF39: 3909970 | BG39: 4415060 | BH39: 4781420 | BI39: 3878790
A40: (1024) #인헌그린점 | B40: 56500 | C40: 2157000 | D40: 1802500 | E40: 2085800 | F40: 1754900 | G40: 1829400 | H40: 2173700 | I40: 2247700 | J40: 1815700 | K40: 2280700 | L40: 2402400 | M40: 2021800 | N40: 2348200 | O40: 2297800 | P40: 2373900 | Q40: 2455700 | R40: 2593600 | S40: 2362200 | T40: 3549900 | U40: 3446900 | V40: 2333400 | W40: 2565000 | X40: 2633500 | Y40: 2887200 | Z40: 2367300 | AA40: 3063900 | AB40: 2412400 | AC40: 2433100 | AD40: 2688300 | AE40: 2453300 | AF40: 4158320 | AG40: 2739080 | AH40: 2698170 | AI40: 2642500 | AJ40: 2787600 | AK40: 2757390 | AL40: 3114190 | AM40: 3444110 | AN40: 3157970 | AO40: 3265070 | AP40: 3163600 | AQ40: 3183660 | AR40: 3240240 | AS40: 3495420 | AT40: 3756470 | AU40: 3430820 | AV40: 2802190 | AW40: 3761640 | AX40: 3099590 | AY40: 3173740 | AZ40: 2960550 | BA40: 3057040 | BB40: 4217940 | BC40: 3172270 | BD40: 3414410 | BE40: 5545890 | BF40: 3528640 | BG40: 2999520 | BH40: 2843980 | BI40: 3719600
...

Sheet Calc_오픈정렬
A1: 지점키 | B1: 경쟁강도 | C1: 경쟁사수 | D1: 그룹 | E1: 오픈다음달1일 | F1: 기준매출(m4-9) | G1: 1 | H1: 2 | I1: 3 | J1: 4 | K1: 5 | L1: 6 | M1: 7 | N1: 8 | O1: 9 | P1: 10 | Q1: 11 | R1: 12 | S1: 13 | T1: 14 | U1: 15 | V1: 16 | W1: 17 | X1: 18 | Y1: 19 | Z1: 20 | AA1: 21 | AB1: 22 | AC1: 23 | AD1: 24 | AE1: 25 | AF1: 26 | AG1: 27 | AH1: 28 | AI1: 29 | AJ1: 30 | AK1: 31 | AL1: 32 | AM1: 33 | AN1: 34 | AO1: 35 | AP1: 36 | AQ1: 37 | AR1: 38 | AS1: 39 | AT1: 40 | AU1: 41 | AV1: 42 | AW1: 43 | AX1: 44 | AY1: 45 | AZ1: 46 | BA1: 47 | BB1: 48 | BC1: 49 | BD1: 50 | BE1: 51 | BF1: 52 | BG1: 53 | BH1: 54 | BI1: 55 | BJ1: 56 | BK1: 57 | BL1: 58 | BM1: 59 | BN1: 60
