Workbook

Sheet 세팅
E1: 46174
A2: 지점키 | B2: 경쟁강도 | C2: 오픈일 | D2: 오픈다음달1일 | E2: 운영개월수 | F2: 36m초과 | G2: 48m초과 | K2: 36M초과 | L2: 48M초과 | N2: 월 | O2: 평균 인덱스 (램프업 제외)
A3: (0001) 건대점 | B3: 150-1 | C3: 42292 | D3: =EOMONTH(C3,0)+1 -> 42309 | E3: =DATEDIF(C3,$E$1,"m") -> 127 | F3: 36M초과 | G3: 48M초과 | J3: 150-0 | K3: =COUNTIF($B$3:$B$85,J3) -> 17 | L3: =COUNTIF($B$3:$B$56,J3) -> 9 | N3: 1 | O3: 91.030317
A4: (0002) 인헌점 | B4: 150-1 | C4: 42444 | D4: =EOMONTH(C4,0)+1 -> 42461 | E4: =DATEDIF(C4,$E$1,"m") -> 122 | F4: 36M초과 | G4: 48M초과 | J4: 150-1 | K4: =COUNTIF($B$3:$B$85,J4) -> 31 | L4: =COUNTIF($B$3:$B$56,J4) -> 21 | N4: 2 | O4: 84.287776
A5: (0003) 구디점 | B5: 150-3 | C5: 42503 | D5: =EOMONTH(C5,0)+1 -> 42522 | E5: =DATEDIF(C5,$E$1,"m") -> 120 | F5: 36M초과 | G5: 48M초과 | J5: 150-2 | K5: =COUNTIF($B$3:$B$85,J5) -> 23 | L5: =COUNTIF($B$3:$B$56,J5) -> 14 | N5: 3 | O5: 97.171601
A6: (0004) 신림점 | B6: 150-4 | C6: 42638 | D6: =EOMONTH(C6,0)+1 -> 42644 | E6: =DATEDIF(C6,$E$1,"m") -> 116 | F6: 36M초과 | G6: 48M초과 | J6: 150-3 | K6: =COUNTIF($B$3:$B$85,J6) -> 8 | L6: =COUNTIF($B$3:$B$56,J6) -> 6 | N6: 4 | O6: 96.499915
A7: (0005) 대학점 | B7: 150-2 | C7: 42708 | D7: =EOMONTH(C7,0)+1 -> 42736 | E7: =DATEDIF(C7,$E$1,"m") -> 113 | F7: 36M초과 | G7: 48M초과 | J7: 150-4 | K7: =COUNTIF($B$3:$B$85,J7) -> 3 | L7: =COUNTIF($B$3:$B$56,J7) -> 3 | N7: 5 | O7: 105.36696
A8: (0006) 서림점 | B8: 150-2 | C8: 43039 | D8: =EOMONTH(C8,0)+1 -> 43040 | E8: =DATEDIF(C8,$E$1,"m") -> 103 | F8: 36M초과 | G8: 48M초과 | J8: 150-5 | K8: =COUNTIF($B$3:$B$85,J8) -> 0 | L8: =COUNTIF($B$3:$B$56,J8) -> 0 | N8: 6 | O8: 102.78469
A9: (0007) 낙성대점 | B9: 150-1 | C9: 43146 | D9: =EOMONTH(C9,0)+1 -> 43160 | E9: =DATEDIF(C9,$E$1,"m") -> 99 | F9: 36M초과 | G9: 48M초과 | N9: 7 | O9: 104.67865
A10: (0008) 트리하우스점 | C10: 43252 | D10: =EOMONTH(C10,0)+1 -> 43282 | E10: =DATEDIF(C10,$E$1,"m") -> 96 | F10: 36M초과 | G10: 48M초과 | N10: 8 | O10: 102.04522
A11: (0009) 신원점 | B11: 150-0 | C11: 43779 | D11: =EOMONTH(C11,0)+1 -> 43800 | E11: =DATEDIF(C11,$E$1,"m") -> 78 | F11: 36M초과 | G11: 48M초과 | N11: 9 | O11: 100.12358
A12: (0010) 별빛거리점 | B12: 150-3 | C12: 44583 | D12: =EOMONTH(C12,0)+1 -> 44593 | E12: =DATEDIF(C12,$E$1,"m") -> 52 | F12: 36M초과 | G12: 48M초과 | N12: 10 | O12: 115.59456
A13: (0011) 천안성정공원점 | B13: 150-2 | C13: 44889 | D13: =EOMONTH(C13,0)+1 -> 44896 | E13: =DATEDIF(C13,$E$1,"m") -> 42 | F13: 36M초과 | G13: 48M초과 | N13: 11 | O13: 104.11252
A14: (0012) 우송대북문점 | B14: 150-1 | C14: 45470 | D14: =EOMONTH(C14,0)+1 -> 45474 | E14: =DATEDIF(C14,$E$1,"m") -> 23 | F14: 36M초과 | G14: 48M초과 | N14: 12 | O14: 103.33184
A15: (0013) 구의역파워점 | B15: 150-1 | C15: 45810 | D15: =EOMONTH(C15,0)+1 -> 45839 | E15: =DATEDIF(C15,$E$1,"m") -> 11 | F15: 36M초과 | G15: 48M초과
A16: (0014) 수원서둔골드점 | B16: 150-1 | C16: 45859 | D16: =EOMONTH(C16,0)+1 -> 45870 | E16: =DATEDIF(C16,$E$1,"m") -> 10 | F16: 36M초과 | G16: 48M초과
A17: (1001) #화곡점 | B17: 150-1 | C17: 43629 | D17: =EOMONTH(C17,0)+1 -> 43647 | E17: =DATEDIF(C17,$E$1,"m") -> 83 | F17: 36M초과 | G17: 48M초과 | K17: 정상가 | L17: 오픈할인가 | M17: 할인율
A18: (1002) #신대방점 | B18: 150-4 | C18: 43631 | D18: =EOMONTH(C18,0)+1 -> 43647 | E18: =DATEDIF(C18,$E$1,"m") -> 83 | F18: 36M초과 | G18: 48M초과 | J18: 표준 | K18: 4950 | L18: 1990 | M18: =L18/K18-1 -> -0.5979798
A19: (1003) #샤로수점 | B19: 150-2 | C19: 43743 | D19: =EOMONTH(C19,0)+1 -> 43770 | E19: =DATEDIF(C19,$E$1,"m") -> 79 | F19: 36M초과 | G19: 48M초과 | J19: 살균 | K19: 5950 | L19: 2990 | M19: =L19/K19-1 -> -0.49747899
A20: (1004) #서울대입구점 | B20: 150-1 | C20: 43834 | D20: =EOMONTH(C20,0)+1 -> 43862 | E20: =DATEDIF(C20,$E$1,"m") -> 76 | F20: 36M초과 | G20: 48M초과 | J20: 대용량 | K20: 6950 | L20: 3990 | M20: =L20/K20-1 -> -0.42589928
A21: (1005) #쑥고개점 | B21: 150-1 | C21: 43833 | D21: =EOMONTH(C21,0)+1 -> 43862 | E21: =DATEDIF(C21,$E$1,"m") -> 76 | F21: 36M초과 | G21: 48M초과
A22: (1006) #회기점 | B22: 150-1 | C22: 43853 | D22: =EOMONTH(C22,0)+1 -> 43862 | E22: =DATEDIF(C22,$E$1,"m") -> 76 | F22: 36M초과 | G22: 48M초과
A23: (1007) #구의점 | B23: 150-2 | C23: 43945 | D23: =EOMONTH(C23,0)+1 -> 43952 | E23: =DATEDIF(C23,$E$1,"m") -> 73 | F23: 36M초과 | G23: 48M초과
A24: (1008) #개포드림웍스점 | B24: 150-0 | C24: 44015 | D24: =EOMONTH(C24,0)+1 -> 44044 | E24: =DATEDIF(C24,$E$1,"m") -> 70 | F24: 36M초과 | G24: 48M초과
A25: (1009) #진시스장항점 | B25: 150-3 | C25: 44042 | D25: =EOMONTH(C25,0)+1 -> 44044 | E25: =DATEDIF(C25,$E$1,"m") -> 70 | F25: 36M초과 | G25: 48M초과
A26: (1010) #삼전엠케이점 | B26: 150-0 | C26: 44043 | D26: =EOMONTH(C26,0)+1 -> 44044 | E26: =DATEDIF(C26,$E$1,"m") -> 70 | F26: 36M초과 | G26: 48M초과
A27: (1011) #신길점 | B27: 150-1 | C27: 44072 | D27: =EOMONTH(C27,0)+1 -> 44075 | E27: =DATEDIF(C27,$E$1,"m") -> 69 | F27: 36M초과 | G27: 48M초과
A28: (1012) #석촌점 | B28: 150-0 | C28: 44085 | D28: =EOMONTH(C28,0)+1 -> 44105 | E28: =DATEDIF(C28,$E$1,"m") -> 68 | F28: 36M초과 | G28: 48M초과
A29: (1014) #자곡점 | B29: 150-2 | C29: 44147 | D29: =EOMONTH(C29,0)+1 -> 44166 | E29: =DATEDIF(C29,$E$1,"m") -> 66 | F29: 36M초과 | G29: 48M초과
A30: (1015) #사당점 | B30: 150-1 | C30: 44154 | D30: =EOMONTH(C30,0)+1 -> 44166 | E30: =DATEDIF(C30,$E$1,"m") -> 66 | F30: 36M초과 | G30: 48M초과
A31: (1016) #가산점 | B31: 150-2 | C31: 44169 | D31: =EOMONTH(C31,0)+1 -> 44197 | E31: =DATEDIF(C31,$E$1,"m") -> 65 | F31: 36M초과 | G31: 48M초과
A32: (1019) #청룡점 | B32: 150-3 | C32: 44252 | D32: =EOMONTH(C32,0)+1 -> 44256 | E32: =DATEDIF(C32,$E$1,"m") -> 63 | F32: 36M초과 | G32: 48M초과
... A48: (1036) #낙성대행운점 | B48: 150-1 | C48: 44508 | D48: =EOMONTH(C48,0)+1 -> 44531 | E48: =DATEDIF(C48,$E$1,"m") -> 54 | F48: 36M초과 | G48: 48M초과
A49: (1037) #신림퍼스트점 | B49: 150-2 | C49: =IFERROR(INDEX(RAW_매출A!$D$2:$D$7000,MATCH($A49,RAW_매출A!$B$2:$B$7000,0)),NA()) -> 44536 | D49: =EOMONTH(C49,0)+1 -> 44562 | E49: =DATEDIF(C49,$E$1,"m") -> 53 | F49: 36M초과 | G49: 48M초과
A50: (1038) #한양여대점 | B50: 150-2 | C50: 44616 | D50: =EOMONTH(C50,0)+1 -> 44621 | E50: =DATEDIF(C50,$E$1,"m") -> 51 | F50: 36M초과 | G50: 48M초과
A51: (1039) #이문점 | B51: 150-2 | C51: 44643 | D51: =EOMONTH(C51,0)+1 -> 44652 | E51: =DATEDIF(C51,$E$1,"m") -> 50 | F51: 36M초과 | G51: 48M초과
A52: (1040) #독산역점 | B52: 150-1 | C52: 44651 | D52: =EOMONTH(C52,0)+1 -> 44652 | E52: =DATEDIF(C52,$E$1,"m") -> 50 | F52: 36M초과 | G52: 48M초과
A53: (1041) #인하대점 | B53: 150-3 | C53: 44657 | D53: =EOMONTH(C53,0)+1 -> 44682 | E53: =DATEDIF(C53,$E$1,"m") -> 49 | F53: 36M초과 | G53: 48M초과
A54: (1042) #연희점 | B54: 150-1 | C54: 44659 | D54: =EOMONTH(C54,0)+1 -> 44682 | E54: =DATEDIF(C54,$E$1,"m") -> 49 | F54: 36M초과 | G54: 48M초과
A55: (1043) #고대정문점 | B55: 150-0 | C55: 44694 | D55: =EOMONTH(C55,0)+1 -> 44713 | E55: =DATEDIF(C55,$E$1,"m") -> 48 | F55: 36M초과 | G55: 48M초과
...

Sheet 요약_월별시즈널리티
A1: 월별 시즈널리티 인덱스 (이상치 매장 8개 제외)
A3: 인덱스 = (해당월 매출 / 매장-연도 평균 매출) × 100, 100=평균
A4: 제외 매장: 요약_이상치감지 [B] 8개 매장 (3개월 이동평균 -30% 이상 급락)
A6: 월 | B6: 페어 수 | C6: 평균 인덱스 | D6: 중앙값 인덱스 | E6: 페어 수 (램프업 제외) | F6: 평균 인덱스 (램프업 제외) | G6: 중앙값 인덱스 (램프업 제외) | H6: 평균 차이 (제외 − 포함)
A7: 1 | B7: {=SUMPRODUCT((ISNUMBER([1]Calc_매장월인덱스!P$2:P$242))*([1]Calc_매장월인덱스!AB$2:AB$242=0))} -> 218 | C7: {=IFERROR(SUMPRODUCT(IFERROR([1]Calc_매장월인덱스!P$2:P$242*(ISNUMBER([1]Calc_매장월인덱스!P$2:P$242))*([1]Calc_매장월인덱스!AB$2:AB$242=0),0))/B7,"-")} -> 87.245366 | D7: {=IFERROR(_xlfn.AGGREGATE(17,6,[1]Calc_매장월인덱스!P$2:P$242/(([1]Calc_매장월인덱스!AB$2:AB$242=0)*ISNUMBER([1]Calc_매장월인덱스!P$2:P$242)),2),"-")} -> 88.781982 | E7: {=SUMPRODUCT((ISNUMBER(INDEX([1]Calc_매장월인덱스!$P$2:$AA$242,0,$A7)))*([1]Calc_매장월인덱스!$AB$2:$AB$242=0)*(([1]Calc_매장월인덱스!$B$2:$B$242*12+$A7) - ([1]Calc_매장월인덱스!$AD$2:$AD$242*12+[1]Calc_매장월인덱스!$AE$2:$AE$242)>=6))} -> 165 | F7: {=IFERROR(SUMPRODUCT(IFERROR(INDEX([1]Calc_매장월인덱스!$P$2:$AA$242,0,$A7)*(ISNUMBER(INDEX([1]Calc_매장월인덱스!$P$2:$AA$242,0,$A7)))*([1]Calc_매장월인덱스!$AB$2:$AB$242=0)*(([1]Calc_매장월인덱스!$B$2:$B$242*12+$A7) - ([1]Calc_매장월인덱스!$AD$2:$AD$242*12+[1]Calc_매장월인덱스!$AE$2:$AE$242)>=6),0))/E7,"-")} -> 91.030317 | G7: {=IFERROR(_xlfn.AGGREGATE(17,6,INDEX([1]Calc_매장월인덱스!$P$2:$AA$242,0,$A7)/(([1]Calc_매장월인덱스!$AB$2:$AB$242=0)*ISNUMBER(INDEX([1]Calc_매장월인덱스!$P$2:$AA$242,0,$A7))*(([1]Calc_매장월인덱스!$B$2:$B$242*12+$A7) - ([1]Calc_매장월인덱스!$AD$2:$AD$242*12+[1]Calc_매장월인덱스!$AE$2:$AE$242)>=6)),2),"-")} -> 91.064932 | H7: =IFERROR(F7-C7,"-") -> 3.7849509
A8: 2 | B8: {=SUMPRODUCT((ISNUMBER([1]Calc_매장월인덱스!Q$2:Q$242))*([1]Calc_매장월인덱스!AB$2:AB$242=0))} -> 218 | C8: {=IFERROR(SUMPRODUCT(IFERROR([1]Calc_매장월인덱스!Q$2:Q$242*(ISNUMBER([1]Calc_매장월인덱스!Q$2:Q$242))*([1]Calc_매장월인덱스!AB$2:AB$242=0),0))/B8,"-")} -> 82.522548 | D8: {=IFERROR(_xlfn.AGGREGATE(17,6,[1]Calc_매장월인덱스!Q$2:Q$242/(([1]Calc_매장월인덱스!AB$2:AB$242=0)*ISNUMBER([1]Calc_매장월인덱스!Q$2:Q$242)),2),"-")} -> 82.250637 | E8: {=SUMPRODUCT((ISNUMBER(INDEX([1]Calc_매장월인덱스!$P$2:$AA$242,0,$A8)))*([1]Calc_매장월인덱스!$AB$2:$AB$242=0)*(([1]Calc_매장월인덱스!$B$2:$B$242*12+$A8) - ([1]Calc_매장월인덱스!$AD$2:$AD$242*12+[1]Calc_매장월인덱스!$AE$2:$AE$242)>=6))} -> 176 | F8: {=IFERROR(SUMPRODUCT(IFERROR(INDEX([1]Calc_매장월인덱스!$P$2:$AA$242,0,$A8)*(ISNUMBER(INDEX([1]Calc_매장월인덱스!$P$2:$AA$242,0,$A8)))*([1]Calc_매장월인덱스!$AB$2:$AB$242=0)*(([1]Calc_매장월인덱스!$B$2:$B$242*12+$A8) - ([1]Calc_매장월인덱스!$AD$2:$AD$242*12+[1]Calc_매장월인덱스!$AE$2:$AE$242)>=6),0))/E8,"-")} -> 84.287776 | G8: {=IFERROR(_xlfn.AGGREGATE(17,6,INDEX([1]Calc_매장월인덱스!$P$2:$AA$242,0,$A8)/(([1]Calc_매장월인덱스!$AB$2:$AB$242=0)*ISNUMBER(INDEX([1]Calc_매장월인덱스!$P$2:$AA$242,0,$A8))*(([1]Calc_매장월인덱스!$B$2:$B$242*12+$A8) - ([1]Calc_매장월인덱스!$AD$2:$AD$242*12+[1]Calc_매장월인덱스!$AE$2:$AE$242)>=6)),2),"-")} -> 83.667925 | H8: =IFERROR(F8-C8,"-") -> 1.7652281
A9: 3 | B9: {=SUMPRODUCT((ISNUMBER([1]Calc_매장월인덱스!R$2:R$242))*([1]Calc_매장월인덱스!AB$2:AB$242=0))} -> 218 | C9: {=IFERROR(SUMPRODUCT(IFERROR([1]Calc_매장월인덱스!R$2:R$242*(ISNUMBER([1]Calc_매장월인덱스!R$2:R$242))*([1]Calc_매장월인덱스!AB$2:AB$242=0),0))/B9,"-")} -> 96.187233 | D9: {=IFERROR(_xlfn.AGGREGATE(17,6,[1]Calc_매장월인덱스!R$2:R$242/(([1]Calc_매장월인덱스!AB$2:AB$242=0)*ISNUMBER([1]Calc_매장월인덱스!R$2:R$242)),2),"-")} -> 96.098186 | E9: {=SUMPRODUCT((ISNUMBER(INDEX([1]Calc_매장월인덱스!$P$2:$AA$242,0,$A9)))*([1]Calc_매장월인덱스!$AB$2:$AB$242=0)*(([1]Calc_매장월인덱스!$B$2:$B$242*12+$A9) - ([1]Calc_매장월인덱스!$AD$2:$AD$242*12+[1]Calc_매장월인덱스!$AE$2:$AE$242)>=6))} -> 188 | F9: {=IFERROR(SUMPRODUCT(IFERROR(INDEX([1]Calc_매장월인덱스!$P$2:$AA$242,0,$A9)*(ISNUMBER(INDEX([1]Calc_매장월인덱스!$P$2:$AA$242,0,$A9)))*([1]Calc_매장월인덱스!$AB$2:$AB$242=0)*(([1]Calc_매장월인덱스!$B$2:$B$242*12+$A9) - ([1]Calc_매장월인덱스!$AD$2:$AD$242*12+[1]Calc_매장월인덱스!$AE$2:$AE$242)>=6),0))/E9,"-")} -> 97.171601 | G9: {=IFERROR(_xlfn.AGGREGATE(17,6,INDEX([1]Calc_매장월인덱스!$P$2:$AA$242,0,$A9)/(([1]Calc_매장월인덱스!$AB$2:$AB$242=0)*ISNUMBER(INDEX([1]Calc_매장월인덱스!$P$2:$AA$242,0,$A9))*(([1]Calc_매장월인덱스!$B$2:$B$242*12+$A9) - ([1]Calc_매장월인덱스!$AD$2:$AD$242*12+[1]Calc_매장월인덱스!$AE$2:$AE$242)>=6)),2),"-")} -> 96.898163 | H9: =IFERROR(F9-C9,"-") -> 0.98436727
A10: 4 | B10: {=SUMPRODUCT((ISNUMBER([1]Calc_매장월인덱스!S$2:S$242))*([1]Calc_매장월인덱스!AB$2:AB$242=0))} -> 218 | C10: {=IFERROR(SUMPRODUCT(IFERROR([1]Calc_매장월인덱스!S$2:S$242*(ISNUMBER([1]Calc_매장월인덱스!S$2:S$242))*([1]Calc_매장월인덱스!AB$2:AB$242=0),0))/B10,"-")} -> 95.963431 | D10: {=IFERROR(_xlfn.AGGREGATE(17,6,[1]Calc_매장월인덱스!S$2:S$242/(([1]Calc_매장월인덱스!AB$2:AB$242=0)*ISNUMBER([1]Calc_매장월인덱스!S$2:S$242)),2),"-")} -> 96.328113 | E10: {=SUMPRODUCT((ISNUMBER(INDEX([1]Calc_매장월인덱스!$P$2:$AA$242,0,$A10)))*([1]Calc_매장월인덱스!$AB$2:$AB$242=0)*(([1]Calc_매장월인덱스!$B$2:$B$242*12+$A10) - ([1]Calc_매장월인덱스!$AD$2:$AD$242*12+[1]Calc_매장월인덱스!$AE$2:$AE$242)>=6))} -> 197 | F10: {=IFERROR(SUMPRODUCT(IFERROR(INDEX([1]Calc_매장월인덱스!$P$2:$AA$242,0,$A10)*(ISNUMBER(INDEX([1]Calc_매장월인덱스!$P$2:$AA$242,0,$A10)))*([1]Calc_매장월인덱스!$AB$2:$AB$242=0)*(([1]Calc_매장월인덱스!$B$2:$B$242*12+$A10) - ([1]Calc_매장월인덱스!$AD$2:$AD$242*12+[1]Calc_매장월인덱스!$AE$2:$AE$242)>=6),0))/E10,"-")} -> 96.499915 | G10: {=IFERROR(_xlfn.AGGREGATE(17,6,INDEX([1]Calc_매장월인덱스!$P$2:$AA$242,0,$A10)/(([1]Calc_매장월인덱스!$AB$2:$AB$242=0)*ISNUMBER(INDEX([1]Calc_매장월인덱스!$P$2:$AA$242,0,$A10))*(([1]Calc_매장월인덱스!$B$2:$B$242*12+$A10) - ([1]Calc_매장월인덱스!$AD$2:$AD$242*12+[1]Calc_매장월인덱스!$AE$2:$AE$242)>=6)),2),"-")} -> 96.795853 | H10: =IFERROR(F10-C10,"-") -> 0.53648379
A11: 5 | B11: {=SUMPRODUCT((ISNUMBER([1]Calc_매장월인덱스!T$2:T$242))*([1]Calc_매장월인덱스!AB$2:AB$242=0))} -> 218 | C11: {=IFERROR(SUMPRODUCT(IFERROR([1]Calc_매장월인덱스!T$2:T$242*(ISNUMBER([1]Calc_매장월인덱스!T$2:T$242))*([1]Calc_매장월인덱스!AB$2:AB$242=0),0))/B11,"-")} -> 105.32404 | D11: {=IFERROR(_xlfn.AGGREGATE(17,6,[1]Calc_매장월인덱스!T$2:T$242/(([1]Calc_매장월인덱스!AB$2:AB$242=0)*ISNUMBER([1]Calc_매장월인덱스!T$2:T$242)),2),"-")} -> 105.53665 | E11: {=SUMPRODUCT((ISNUMBER(INDEX([1]Calc_매장월인덱스!$P$2:$AA$242,0,$A11)))*([1]Calc_매장월인덱스!$AB$2:$AB$242=0)*(([1]Calc_매장월인덱스!$B$2:$B$242*12+$A11) - ([1]Calc_매장월인덱스!$AD$2:$AD$242*12+[1]Calc_매장월인덱스!$AE$2:$AE$242)>=6))} -> 207 | F11: {=IFERROR(SUMPRODUCT(IFERROR(INDEX([1]Calc_매장월인덱스!$P$2:$AA$242,0,$A11)*(ISNUMBER(INDEX([1]Calc_매장월인덱스!$P$2:$AA$242,0,$A11)))*([1]Calc_매장월인덱스!$AB$2:$AB$242=0)*(([1]Calc_매장월인덱스!$B$2:$B$242*12+$A11) - ([1]Calc_매장월인덱스!$AD$2:$AD$242*12+[1]Calc_매장월인덱스!$AE$2:$AE$242)>=6),0))/E11,"-")} -> 105.36696 | G11: {=IFERROR(_xlfn.AGGREGATE(17,6,INDEX([1]Calc_매장월인덱스!$P$2:$AA$242,0,$A11)/(([1]Calc_매장월인덱스!$AB$2:$AB$242=0)*ISNUMBER(INDEX([1]Calc_매장월인덱스!$P$2:$AA$242,0,$A11))*(([1]Calc_매장월인덱스!$B$2:$B$242*12+$A11) - ([1]Calc_매장월인덱스!$AD$2:$AD$242*12+[1]Calc_매장월인덱스!$AE$2:$AE$242)>=6)),2),"-")} -> 105.56666 | H11: =IFERROR(F11-C11,"-") -> 0.042921698
A12: 6 | B12: {=SUMPRODUCT((ISNUMBER([1]Calc_매장월인덱스!U$2:U$242))*([1]Calc_매장월인덱스!AB$2:AB$242=0))} -> 218 | C12: {=IFERROR(SUMPRODUCT(IFERROR([1]Calc_매장월인덱스!U$2:U$242*(ISNUMBER([1]Calc_매장월인덱스!U$2:U$242))*([1]Calc_매장월인덱스!AB$2:AB$242=0),0))/B12,"-")} -> 102.87101 | D12: {=IFERROR(_xlfn.AGGREGATE(17,6,[1]Calc_매장월인덱스!U$2:U$242/(([1]Calc_매장월인덱스!AB$2:AB$242=0)*ISNUMBER([1]Calc_매장월인덱스!U$2:U$242)),2),"-")} -> 103.00425 | E12: {=SUMPRODUCT((ISNUMBER(INDEX([1]Calc_매장월인덱스!$P$2:$AA$242,0,$A12)))*([1]Calc_매장월인덱스!$AB$2:$AB$242=0)*(([1]Calc_매장월인덱스!$B$2:$B$242*12+$A12) - ([1]Calc_매장월인덱스!$AD$2:$AD$242*12+[1]Calc_매장월인덱스!$AE$2:$AE$242)>=6))} -> 213 | F12: {=IFERROR(SUMPRODUCT(IFERROR(INDEX([1]Calc_매장월인덱스!$P$2:$AA$242,0,$A12)*(ISNUMBER(INDEX([1]Calc_매장월인덱스!$P$2:$AA$242,0,$A12)))*([1]Calc_매장월인덱스!$AB$2:$AB$242=0)*(([1]Calc_매장월인덱스!$B$2:$B$242*12+$A12) - ([1]Calc_매장월인덱스!$AD$2:$AD$242*12+[1]Calc_매장월인덱스!$AE$2:$AE$242)>=6),0))/E12,"-")} -> 102.78469 | G12: {=IFERROR(_xlfn.AGGREGATE(17,6,INDEX([1]Calc_매장월인덱스!$P$2:$AA$242,0,$A12)/(([1]Calc_매장월인덱스!$AB$2:$AB$242=0)*ISNUMBER(INDEX([1]Calc_매장월인덱스!$P$2:$AA$242,0,$A12))*(([1]Calc_매장월인덱스!$B$2:$B$242*12+$A12) - ([1]Calc_매장월인덱스!$AD$2:$AD$242*12+[1]Calc_매장월인덱스!$AE$2:$AE$242)>=6)),2),"-")} -> 102.82351 | H12: =IFERROR(F12-C12,"-") -> -0.086325039
A13: 7 | B13: {=SUMPRODUCT((ISNUMBER([1]Calc_매장월인덱스!V$2:V$242))*([1]Calc_매장월인덱스!AB$2:AB$242=0))} -> 218 | C13: {=IFERROR(SUMPRODUCT(IFERROR([1]Calc_매장월인덱스!V$2:V$242*(ISNUMBER([1]Calc_매장월인덱스!V$2:V$242))*([1]Calc_매장월인덱스!AB$2:AB$242=0),0))/B13,"-")} -> 104.67865 | D13: {=IFERROR(_xlfn.AGGREGATE(17,6,[1]Calc_매장월인덱스!V$2:V$242/(([1]Calc_매장월인덱스!AB$2:AB$242=0)*ISNUMBER([1]Calc_매장월인덱스!V$2:V$242)),2),"-")} -> 104.40187 | E13: {=SUMPRODUCT((ISNUMBER(INDEX([1]Calc_매장월인덱스!$P$2:$AA$242,0,$A13)))*([1]Calc_매장월인덱스!$AB$2:$AB$242=0)*(([1]Calc_매장월인덱스!$B$2:$B$242*12+$A13) - ([1]Calc_매장월인덱스!$AD$2:$AD$242*12+[1]Calc_매장월인덱스!$AE$2:$AE$242)>=6))} -> 218 | F13: {=IFERROR(SUMPRODUCT(IFERROR(INDEX([1]Calc_매장월인덱스!$P$2:$AA$242,0,$A13)*(ISNUMBER(INDEX([1]Calc_매장월인덱스!$P$2:$AA$242,0,$A13)))*([1]Calc_매장월인덱스!$AB$2:$AB$242=0)*(([1]Calc_매장월인덱스!$B$2:$B$242*12+$A13) - ([1]Calc_매장월인덱스!$AD$2:$AD$242*12+[1]Calc_매장월인덱스!$AE$2:$AE$242)>=6),0))/E13,"-")} -> 104.67865 | G13: {=IFERROR(_xlfn.AGGREGATE(17,6,INDEX([1]Calc_매장월인덱스!$P$2:$AA$242,0,$A13)/(([1]Calc_매장월인덱스!$AB$2:$AB$242=0)*ISNUMBER(INDEX([1]Calc_매장월인덱스!$P$2:$AA$242,0,$A13))*(([1]Calc_매장월인덱스!$B$2:$B$242*12+$A13) - ([1]Calc_매장월인덱스!$AD$2:$AD$242*12+[1]Calc_매장월인덱스!$AE$2:$AE$242)>=6)),2),"-")} -> 104.40187 | H13: =IFERROR(F13-C13,"-") -> 0
A14: 8 | B14: {=SUMPRODUCT((ISNUMBER([1]Calc_매장월인덱스!W$2:W$242))*([1]Calc_매장월인덱스!AB$2:AB$242=0))} -> 218 | C14: {=IFERROR(SUMPRODUCT(IFERROR([1]Calc_매장월인덱스!W$2:W$242*(ISNUMBER([1]Calc_매장월인덱스!W$2:W$242))*([1]Calc_매장월인덱스!AB$2:AB$242=0),0))/B14,"-")} -> 102.04522 | D14: {=IFERROR(_xlfn.AGGREGATE(17,6,[1]Calc_매장월인덱스!W$2:W$242/(([1]Calc_매장월인덱스!AB$2:AB$242=0)*ISNUMBER([1]Calc_매장월인덱스!W$2:W$242)),2),"-")} -> 100.96882 | E14: {=SUMPRODUCT((ISNUMBER(INDEX([1]Calc_매장월인덱스!$P$2:$AA$242,0,$A14)))*([1]Calc_매장월인덱스!$AB$2:$AB$242=0)*(([1]Calc_매장월인덱스!$B$2:$B$242*12+$A14) - ([1]Calc_매장월인덱스!$AD$2:$AD$242*12+[1]Calc_매장월인덱스!$AE$2:$AE$242)>=6))} -> 218 | F14: {=IFERROR(SUMPRODUCT(IFERROR(INDEX([1]Calc_매장월인덱스!$P$2:$AA$242,0,$A14)*(ISNUMBER(INDEX([1]Calc_매장월인덱스!$P$2:$AA$242,0,$A14)))*([1]Calc_매장월인덱스!$AB$2:$AB$242=0)*(([1]Calc_매장월인덱스!$B$2:$B$242*12+$A14) - ([1]Calc_매장월인덱스!$AD$2:$AD$242*12+[1]Calc_매장월인덱스!$AE$2:$AE$242)>=6),0))/E14,"-")} -> 102.04522 | G14: {=IFERROR(_xlfn.AGGREGATE(17,6,INDEX([1]Calc_매장월인덱스!$P$2:$AA$242,0,$A14)/(([1]Calc_매장월인덱스!$AB$2:$AB$242=0)*ISNUMBER(INDEX([1]Calc_매장월인덱스!$P$2:$AA$242,0,$A14))*(([1]Calc_매장월인덱스!$B$2:$B$242*12+$A14) - ([1]Calc_매장월인덱스!$AD$2:$AD$242*12+[1]Calc_매장월인덱스!$AE$2:$AE$242)>=6)),2),"-")} -> 100.96882 | H14: =IFERROR(F14-C14,"-") -> 0
A15: 9 | B15: {=SUMPRODUCT((ISNUMBER([1]Calc_매장월인덱스!X$2:X$242))*([1]Calc_매장월인덱스!AB$2:AB$242=0))} -> 218 | C15: {=IFERROR(SUMPRODUCT(IFERROR([1]Calc_매장월인덱스!X$2:X$242*(ISNUMBER([1]Calc_매장월인덱스!X$2:X$242))*([1]Calc_매장월인덱스!AB$2:AB$242=0),0))/B15,"-")} -> 100.12358 | D15: {=IFERROR(_xlfn.AGGREGATE(17,6,[1]Calc_매장월인덱스!X$2:X$242/(([1]Calc_매장월인덱스!AB$2:AB$242=0)*ISNUMBER([1]Calc_매장월인덱스!X$2:X$242)),2),"-")} -> 99.05002 | E15: {=SUMPRODUCT((ISNUMBER(INDEX([1]Calc_매장월인덱스!$P$2:$AA$242,0,$A15)))*([1]Calc_매장월인덱스!$AB$2:$AB$242=0)*(([1]Calc_매장월인덱스!$B$2:$B$242*12+$A15) - ([1]Calc_매장월인덱스!$AD$2:$AD$242*12+[1]Calc_매장월인덱스!$AE$2:$AE$242)>=6))} -> 218 | F15: {=IFERROR(SUMPRODUCT(IFERROR(INDEX([1]Calc_매장월인덱스!$P$2:$AA$242,0,$A15)*(ISNUMBER(INDEX([1]Calc_매장월인덱스!$P$2:$AA$242,0,$A15)))*([1]Calc_매장월인덱스!$AB$2:$AB$242=0)*(([1]Calc_매장월인덱스!$B$2:$B$242*12+$A15) - ([1]Calc_매장월인덱스!$AD$2:$AD$242*12+[1]Calc_매장월인덱스!$AE$2:$AE$242)>=6),0))/E15,"-")} -> 100.12358 | G15: {=IFERROR(_xlfn.AGGREGATE(17,6,INDEX([1]Calc_매장월인덱스!$P$2:$AA$242,0,$A15)/(([1]Calc_매장월인덱스!$AB$2:$AB$242=0)*ISNUMBER(INDEX([1]Calc_매장월인덱스!$P$2:$AA$242,0,$A15))*(([1]Calc_매장월인덱스!$B$2:$B$242*12+$A15) - ([1]Calc_매장월인덱스!$AD$2:$AD$242*12+[1]Calc_매장월인덱스!$AE$2:$AE$242)>=6)),2),"-")} -> 99.05002 | H15: =IFERROR(F15-C15,"-") -> 0
A16: 10 | B16: {=SUMPRODUCT((ISNUMBER([1]Calc_매장월인덱스!Y$2:Y$242))*([1]Calc_매장월인덱스!AB$2:AB$242=0))} -> 218 | C16: {=IFERROR(SUMPRODUCT(IFERROR([1]Calc_매장월인덱스!Y$2:Y$242*(ISNUMBER([1]Calc_매장월인덱스!Y$2:Y$242))*([1]Calc_매장월인덱스!AB$2:AB$242=0),0))/B16,"-")} -> 115.59456 | D16: {=IFERROR(_xlfn.AGGREGATE(17,6,[1]Calc_매장월인덱스!Y$2:Y$242/(([1]Calc_매장월인덱스!AB$2:AB$242=0)*ISNUMBER([1]Calc_매장월인덱스!Y$2:Y$242)),2),"-")} -> 115.39964 | E16: {=SUMPRODUCT((ISNUMBER(INDEX([1]Calc_매장월인덱스!$P$2:$AA$242,0,$A16)))*([1]Calc_매장월인덱스!$AB$2:$AB$242=0)*(([1]Calc_매장월인덱스!$B$2:$B$242*12+$A16) - ([1]Calc_매장월인덱스!$AD$2:$AD$242*12+[1]Calc_매장월인덱스!$AE$2:$AE$242)>=6))} -> 218 | F16: {=IFERROR(SUMPRODUCT(IFERROR(INDEX([1]Calc_매장월인덱스!$P$2:$AA$242,0,$A16)*(ISNUMBER(INDEX([1]Calc_매장월인덱스!$P$2:$AA$242,0,$A16)))*([1]Calc_매장월인덱스!$AB$2:$AB$242=0)*(([1]Calc_매장월인덱스!$B$2:$B$242*12+$A16) - ([1]Calc_매장월인덱스!$AD$2:$AD$242*12+[1]Calc_매장월인덱스!$AE$2:$AE$242)>=6),0))/E16,"-")} -> 115.59456 | G16: {=IFERROR(_xlfn.AGGREGATE(17,6,INDEX([1]Calc_매장월인덱스!$P$2:$AA$242,0,$A16)/(([1]Calc_매장월인덱스!$AB$2:$AB$242=0)*ISNUMBER(INDEX([1]Calc_매장월인덱스!$P$2:$AA$242,0,$A16))*(([1]Calc_매장월인덱스!$B$2:$B$242*12+$A16) - ([1]Calc_매장월인덱스!$AD$2:$AD$242*12+[1]Calc_매장월인덱스!$AE$2:$AE$242)>=6)),2),"-")} -> 115.39964 | H16: =IFERROR(F16-C16,"-") -> 0
A17: 11 | B17: {=SUMPRODUCT((ISNUMBER([1]Calc_매장월인덱스!Z$2:Z$242))*([1]Calc_매장월인덱스!AB$2:AB$242=0))} -> 218 | C17: {=IFERROR(SUMPRODUCT(IFERROR([1]Calc_매장월인덱스!Z$2:Z$242*(ISNUMBER([1]Calc_매장월인덱스!Z$2:Z$242))*([1]Calc_매장월인덱스!AB$2:AB$242=0),0))/B17,"-")} -> 104.11252 | D17: {=IFERROR(_xlfn.AGGREGATE(17,6,[1]Calc_매장월인덱스!Z$2:Z$242/(([1]Calc_매장월인덱스!AB$2:AB$242=0)*ISNUMBER([1]Calc_매장월인덱스!Z$2:Z$242)),2),"-")} -> 104.08415 | E17: {=SUMPRODUCT((ISNUMBER(INDEX([1]Calc_매장월인덱스!$P$2:$AA$242,0,$A17)))*([1]Calc_매장월인덱스!$AB$2:$AB$242=0)*(([1]Calc_매장월인덱스!$B$2:$B$242*12+$A17) - ([1]Calc_매장월인덱스!$AD$2:$AD$242*12+[1]Calc_매장월인덱스!$AE$2:$AE$242)>=6))} -> 218 | F17: {=IFERROR(SUMPRODUCT(IFERROR(INDEX([1]Calc_매장월인덱스!$P$2:$AA$242,0,$A17)*(ISNUMBER(INDEX([1]Calc_매장월인덱스!$P$2:$AA$242,0,$A17)))*([1]Calc_매장월인덱스!$AB$2:$AB$242=0)*(([1]Calc_매장월인덱스!$B$2:$B$242*12+$A17) - ([1]Calc_매장월인덱스!$AD$2:$AD$242*12+[1]Calc_매장월인덱스!$AE$2:$AE$242)>=6),0))/E17,"-")} -> 104.11252 | G17: {=IFERROR(_xlfn.AGGREGATE(17,6,INDEX([1]Calc_매장월인덱스!$P$2:$AA$242,0,$A17)/(([1]Calc_매장월인덱스!$AB$2:$AB$242=0)*ISNUMBER(INDEX([1]Calc_매장월인덱스!$P$2:$AA$242,0,$A17))*(([1]Calc_매장월인덱스!$B$2:$B$242*12+$A17) - ([1]Calc_매장월인덱스!$AD$2:$AD$242*12+[1]Calc_매장월인덱스!$AE$2:$AE$242)>=6)),2),"-")} -> 104.08415 | H17: =IFERROR(F17-C17,"-") -> 0
A18: 12 | B18: {=SUMPRODUCT((ISNUMBER([1]Calc_매장월인덱스!AA$2:AA$242))*([1]Calc_매장월인덱스!AB$2:AB$242=0))} -> 218 | C18: {=IFERROR(SUMPRODUCT(IFERROR([1]Calc_매장월인덱스!AA$2:AA$242*(ISNUMBER([1]Calc_매장월인덱스!AA$2:AA$242))*([1]Calc_매장월인덱스!AB$2:AB$242=0),0))/B18,"-")} -> 103.33184 | D18: {=IFERROR(_xlfn.AGGREGATE(17,6,[1]Calc_매장월인덱스!AA$2:AA$242/(([1]Calc_매장월인덱스!AB$2:AB$242=0)*ISNUMBER([1]Calc_매장월인덱스!AA$2:AA$242)),2),"-")} -> 102.19251 | E18: {=SUMPRODUCT((ISNUMBER(INDEX([1]Calc_매장월인덱스!$P$2:$AA$242,0,$A18)))*([1]Calc_매장월인덱스!$AB$2:$AB$242=0)*(([1]Calc_매장월인덱스!$B$2:$B$242*12+$A18) - ([1]Calc_매장월인덱스!$AD$2:$AD$242*12+[1]Calc_매장월인덱스!$AE$2:$AE$242)>=6))} -> 218 | F18: {=IFERROR(SUMPRODUCT(IFERROR(INDEX([1]Calc_매장월인덱스!$P$2:$AA$242,0,$A18)*(ISNUMBER(INDEX([1]Calc_매장월인덱스!$P$2:$AA$242,0,$A18)))*([1]Calc_매장월인덱스!$AB$2:$AB$242=0)*(([1]Calc_매장월인덱스!$B$2:$B$242*12+$A18) - ([1]Calc_매장월인덱스!$AD$2:$AD$242*12+[1]Calc_매장월인덱스!$AE$2:$AE$242)>=6),0))/E18,"-")} -> 103.33184 | G18: {=IFERROR(_xlfn.AGGREGATE(17,6,INDEX([1]Calc_매장월인덱스!$P$2:$AA$242,0,$A18)/(([1]Calc_매장월인덱스!$AB$2:$AB$242=0)*ISNUMBER(INDEX([1]Calc_매장월인덱스!$P$2:$AA$242,0,$A18))*(([1]Calc_매장월인덱스!$B$2:$B$242*12+$A18) - ([1]Calc_매장월인덱스!$AD$2:$AD$242*12+[1]Calc_매장월인덱스!$AE$2:$AE$242)>=6)),2),"-")} -> 102.19251 | H18: =IFERROR(F18-C18,"-") -> 0
A20: * 이 시트는 Calc_매장월인덱스의 AB열(급락매장여부) 플래그를 SUMPRODUCT/AGGREGATE로 참조 — 원본/이상치 리스트가 바뀌면 자동 갱신

Sheet RAW_매출A
A1: 해당월 | B1: 지점키 | C1: 사업자키 | D1: 개점일 | E1: 폐점일 | F1: 개점1년초과여부 | G1: 세탁건조매출 | H1: 멀티자판기매출 | I1: 기타매출 | J1: 최종월매출
A2: 42278 | B2: (0001) 건대점 | C2: (D001) 런드리익스프레스 화양점 | D2: 42292 | G2: 1765000 | I2: 0 | J2: 1765000
A3: 42309 | B3: (0001) 건대점 | C3: (D001) 런드리익스프레스 화양점 | D3: 42292 | G3: 3960000 | I3: 0 | J3: 3960000
A4: 42339 | B4: (0001) 건대점 | C4: (D001) 런드리익스프레스 화양점 | D4: 42292 | G4: 4443000 | I4: 0 | J4: 4443000
A5: 42370 | B5: (0001) 건대점 | C5: (D001) 런드리익스프레스 화양점 | D5: 42292 | G5: 4431000 | I5: 0 | J5: 4431000
A6: 42401 | B6: (0001) 건대점 | C6: (D001) 런드리익스프레스 화양점 | D6: 42292 | G6: 4510000 | I6: 0 | J6: 4510000
A7: 42430 | B7: (0001) 건대점 | C7: (D001) 런드리익스프레스 화양점 | D7: 42292 | G7: 5041000 | I7: 0 | J7: 5041000
A8: 42430 | B8: (0002) 인헌점 | C8: (D002) 런드리익스프레스 인헌점 | D8: 42444 | G8: 455000 | I8: 0 | J8: 455000
A9: 42461 | B9: (0001) 건대점 | C9: (D001) 런드리익스프레스 화양점 | D9: 42292 | G9: 4814000 | I9: 0 | J9: 4814000
A10: 42461 | B10: (0002) 인헌점 | C10: (D002) 런드리익스프레스 인헌점 | D10: 42444 | G10: 1567000 | I10: 0 | J10: 1567000
A11: 42491 | B11: (0001) 건대점 | C11: (D001) 런드리익스프레스 화양점 | D11: 42292 | G11: 4832000 | I11: 0 | J11: 4832000
A12: 42491 | B12: (0002) 인헌점 | C12: (D002) 런드리익스프레스 인헌점 | D12: 42444 | G12: 1446000 | I12: 0 | J12: 1446000
A13: 42491 | B13: (0003) 구디점 | C13: (D003) 런드리익스프레스 구로점 | D13: 42503 | G13: 4177000 | I13: 0 | J13: 4177000
... A450: 44105 | B450: (1012) #석촌점 | C450: (F012) 석촌점 런드리익스프레스샵 | D450: 44085 | G450: 3123000 | I450: 0 | J450: 3123000
A451: 44105 | B451: (1013) #방이점 | C451: (F013) 방이점 런드리익스프레스샵 | D451: 44130 | E451: 45543 | G451: 487000 | I451: 0 | J451: 487000
A452: 44136 | B452: (0001) 건대점 | C452: (D001) 런드리익스프레스 화양점 | D452: 42292 | G452: 6261000 | I452: 0 | J452: 6261000
A453: 44136 | B453: (0002) 인헌점 | C453: (D002) 런드리익스프레스 인헌점 | D453: 42444 | G453: 4102000 | I453: 0 | J453: 4102000
A454: 44136 | B454: (0003) 구디점 | C454: (D003) 런드리익스프레스 구로점 | D454: 42503 | G454: 12008000 | I454: 0 | J454: 12008000
A455: 44136 | B455: (0004) 신림점 | C455: (D004) 런드리익스프레스 신림점 | D455: 42638 | G455: 5580000 | I455: 0 | J455: 5580000
A456: 44136 | B456: (0005) 대학점 | C456: (D005) 런드리익스프레스 대학점 | D456: 42708 | G456: 4453000 | I456: 0 | J456: 4453000
A457: 44136 | B457: (0006) 서림점 | C457: (D006) 런드리익스프레스 서림점 | D457: 43039 | G457: 5906000 | I457: 0 | J457: 5906000
A458: 44136 | B458: (0007) 낙성대점 | C458: (D007) 런드리익스프레스 낙성대점 | D458: 43146 | G458: 7508000 | I458: 0 | J458: 7508000
A459: 44136 | B459: (0008) 트리하우스점 | C459: (D008) 트리하우스 | D459: 43252 | G459: 156000 | I459: 0 | J459: 156000
A460: 44136 | B460: (0009) 신원점 | C460: (D009) 신원점 런드리익스프레스 | D460: 43779 | G460: 4836000 | I460: 0 | J460: 4836000
A461: 44136 | B461: (1001) #화곡점 | C461: (F001) 런드리익스프레스샵 화곡점 | D461: 43629 | G461: 7555000 | I461: 0 | J461: 7555000
A462: 44136 | B462: (1002) #신대방점 | C462: (F002) 런드리익스프레스샵 신대방점 | D462: 43631 | G462: 5761000 | I462: 0 | J462: 5761000
A463: 44136 | B463: (1003) #샤로수점 | C463: (F003) 샤로수점 샵런드리익스프레스 | D463: 43743 | G463: 5315000 | I463: 0 | J463: 5315000
... A472: 44136 | B472: (1012) #석촌점 | C472: (F012) 석촌점 런드리익스프레스샵 | D472: 44085 | G472: 3299000 | I472: 0 | J472: 3299000
A473: 44136 | B473: (1013) #방이점 | C473: (F013) 방이점 런드리익스프레스샵 | D473: 44130 | E473: 45543 | G473: 3056000 | I473: 0 | J473: 3056000
A474: 44136 | B474: (1014) #자곡점 | C474: (F014) 자곡점 런드리익스프레스샵 | D474: 44147 | G474: 1452000 | I474: 0 | J474: 1452000
A475: 44136 | B475: (1015) #사당점 | C475: (F015) 사당점 런드리익스프레스샵 | D475: 44154 | G475: 1284000 | I475: 0 | J475: 1284000
A476: 44166 | B476: (0001) 건대점 | C476: (D001) 런드리익스프레스 화양점 | D476: 42292 | G476: 6223000 | I476: 0 | J476: 6223000
A477: 44166 | B477: (0002) 인헌점 | C477: (D002) 런드리익스프레스 인헌점 | D477: 42444 | G477: 4041000 | I477: 0 | J477: 4041000
A478: 44166 | B478: (0003) 구디점 | C478: (D003) 런드리익스프레스 구로점 | D478: 42503 | G478: 11264000 | I478: 0 | J478: 11264000
A479: 44166 | B479: (0004) 신림점 | C479: (D004) 런드리익스프레스 신림점 | D479: 42638 | G479: 5379000 | I479: 0 | J479: 5379000
A480: 44166 | B480: (0005) 대학점 | C480: (D005) 런드리익스프레스 대학점 | D480: 42708 | G480: 3624000 | I480: 0 | J480: 3624000
A481: 44166 | B481: (0006) 서림점 | C481: (D006) 런드리익스프레스 서림점 | D481: 43039 | G481: 5350000 | I481: 0 | J481: 5350000
A482: 44166 | B482: (0007) 낙성대점 | C482: (D007) 런드리익스프레스 낙성대점 | D482: 43146 | G482: 6711000 | I482: 0 | J482: 6711000
A483: 44166 | B483: (0008) 트리하우스점 | C483: (D008) 트리하우스 | D483: 43252 | G483: 227000 | I483: 0 | J483: 227000
A484: 44166 | B484: (0009) 신원점 | C484: (D009) 신원점 런드리익스프레스 | D484: 43779 | G484: 4756000 | I484: 0 | J484: 4756000
...

Sheet Calc_오픈정렬
A1: 지점키 | B1: 경쟁강도 | C1: 경쟁사수 | D1: 그룹 | E1: 오픈다음달1일 | F1: 기준매출(m4-9) | G1: 1 | H1: 2 | I1: 3 | J1: 4 | K1: 5 | L1: 6 | M1: 7 | N1: 8 | O1: 9 | P1: 10 | Q1: 11 | R1: 12 | S1: 13 | T1: 14 | U1: 15 | V1: 16 | W1: 17 | X1: 18 | Y1: 19 | Z1: 20 | AA1: 21 | AB1: 22 | AC1: 23 | AD1: 24 | AE1: 25 | AF1: 26 | AG1: 27 | AH1: 28 | AI1: 29 | AJ1: 30 | AK1: 31 | AL1: 32 | AM1: 33 | AN1: 34 | AO1: 35 | AP1: 36 | AQ1: 37 | AR1: 38 | AS1: 39 | AT1: 40 | AU1: 41 | AV1: 42 | AW1: 43 | AX1: 44 | AY1: 45 | AZ1: 46 | BA1: 47 | BB1: 48 | BC1: 49 | BD1: 50 | BE1: 51 | BF1: 52 | BG1: 53 | BH1: 54 | BI1: 55 | BJ1: 56 | BK1: 57 | BL1: 58 | BM1: 59 | BN1: 60
A2: =세팅!A3 -> (0001) 건대점 | B2: =세팅!B3 -> 150-1 | C2: =IFERROR(VALUE(MID(B2,5,10)),"") -> 1 | D2: =IF(C2="","",IF(C2>=3,"3+",TEXT(C2,"0"))) -> 1 | E2: =세팅!D3 -> 42309 | F2: =IF(COUNT(J2:O2)>=4,AVERAGE(J2:O2),"") -> 4717239.8 | G2: {=IFERROR(IF($A2="","",IF(SUMIFS(RAW_매출A!$J$2:$J$7000,RAW_매출A!$B$2:$B$7000,$A2,RAW_매출A!$A$2:$A$7000,EDATE($E2,G$1-1))=0,"",SUMIFS(RAW_매출A!$J$2:$J$7000,RAW_매출A!$B$2:$B$7000,$A2,RAW_매출A!$A$2:$A$7000,EDATE($E2,G$1-1))/(INDEX(요약_월별시즈널리티!$F$7:$F$18,MONTH(EDATE($E2,G$1-1)))/100))),"")} -> 3803577.3 | H2: {=IFERROR(IF($A2="","",IF(SUMIFS(RAW_매출A!$J$2:$J$7000,RAW_매출A!$B$2:$B$7000,$A2,RAW_매출A!$A$2:$A$7000,EDATE($E2,H$1-1))=0,"",SUMIFS(RAW_매출A!$J$2:$J$7000,RAW_매출A!$B$2:$B$7000,$A2,RAW_매출A!$A$2:$A$7000,EDATE($E2,H$1-1))/(INDEX(요약_월별시즈널리티!$F$7:$F$18,MONTH(EDATE($E2,H$1-1)))/100))),"")} -> 4299739.5 | I2: {=IFERROR(IF($A2="","",IF(SUMIFS(RAW_매출A!$J$2:$J$7000,RAW_매출A!$B$2:$B$7000,$A2,RAW_매출A!$A$2:$A$7000,EDATE($E2,I$1-1))=0,"",SUMIFS(RAW_매출A!$J$2:$J$7000,RAW_매출A!$B$2:$B$7000,$A2,RAW_매출A!$A$2:$A$7000,EDATE($E2,I$1-1))/(INDEX(요약_월별시즈널리티!$F$7:$F$18,MONTH(EDATE($E2,I$1-1)))/100))),"")} -> 4867609.1 | J2: {=IFERROR(IF($A2="","",IF(SUMIFS(RAW_매출A!$J$2:$J$7000,RAW_매출A!$B$2:$B$7000,$A2,RAW_매출A!$A$2:$A$7000,EDATE($E2,J$1-1))=0,"",SUMIFS(RAW_매출A!$J$2:$J$7000,RAW_매출A!$B$2:$B$7000,$A2,RAW_매출A!$A$2:$A$7000,EDATE($E2,J$1-1))/(INDEX(요약_월별시즈널리티!$F$7:$F$18,MONTH(EDATE($E2,J$1-1)))/100))),"")} -> 5350716.5 | K2: {=IFERROR(IF($A2="","",IF(SUMIFS(RAW_매출A!$J$2:$J$7000,RAW_매출A!$B$2:$B$7000,$A2,RAW_매출A!$A$2:$A$7000,EDATE($E2,K$1-1))=0,"",SUMIFS(RAW_매출A!$J$2:$J$7000,RAW_매출A!$B$2:$B$7000,$A2,RAW_매출A!$A$2:$A$7000,EDATE($E2,K$1-1))/(INDEX(요약_월별시즈널리티!$F$7:$F$18,MONTH(EDATE($E2,K$1-1)))/100))),"")} -> 5187729.7 | L2: {=IFERROR(IF($A2="","",IF(SUMIFS(RAW_매출A!$J$2:$J$7000,RAW_매출A!$B$2:$B$7000,$A2,RAW_매출A!$A$2:$A$7000,EDATE($E2,L$1-1))=0,"",SUMIFS(RAW_매출A!$J$2:$J$7000,RAW_매출A!$B$2:$B$7000,$A2,RAW_매출A!$A$2:$A$7000,EDATE($E2,L$1-1))/(INDEX(요약_월별시즈널리티!$F$7:$F$18,MONTH(EDATE($E2,L$1-1)))/100))),"")} -> 4988605.4 | M2: {=IFERROR(IF($A2="","",IF(SUMIFS(RAW_매출A!$J$2:$J$7000,RAW_매출A!$B$2:$B$7000,$A2,RAW_매출A!$A$2:$A$7000,EDATE($E2,M$1-1))=0,"",SUMIFS(RAW_매출A!$J$2:$J$7000,RAW_매출A!$B$2:$B$7000,$A2,RAW_매출A!$A$2:$A$7000,EDATE($E2,M$1-1))/(INDEX(요약_월별시즈널리티!$F$7:$F$18,MONTH(EDATE($E2,M$1-1)))/100))),"")} -> 4585877.7 | N2: {=IFERROR(IF($A2="","",IF(SUMIFS(RAW_매출A!$J$2:$J$7000,RAW_매출A!$B$2:$B$7000,$A2,RAW_매출A!$A$2:$A$7000,EDATE($E2,N$1-1))=0,"",SUMIFS(RAW_매출A!$J$2:$J$7000,RAW_매출A!$B$2:$B$7000,$A2,RAW_매출A!$A$2:$A$7000,EDATE($E2,N$1-1))/(INDEX(요약_월별시즈널리티!$F$7:$F$18,MONTH(EDATE($E2,N$1-1)))/100))),"")} -> 3997677.2 | ... BN2: {=IFERROR(IF($A2="","",IF(SUMIFS(RAW_매출A!$J$2:$J$7000,RAW_매출A!$B$2:$B$7000,$A2,RAW_매출A!$A$2:$A$7000,EDATE($E2,BN$1-1))=0,"",SUMIFS(RAW_매출A!$J$2:$J$7000,RAW_매출A!$B$2:$B$7000,$A2,RAW_매출A!$A$2:$A$7000,EDATE($E2,BN$1-1))/(INDEX(요약_월별시즈널리티!$F$7:$F$18,MONTH(EDATE($E2,BN$1-1)))/100))),"")} -> 6477813.3
A3: =세팅!A4 -> (0002) 인헌점 | B3: =세팅!B4 -> 150-1 | C3: =IFERROR(VALUE(MID(B3,5,10)),"") -> 1 | D3: =IF(C3="","",IF(C3>=3,"3+",TEXT(C3,"0"))) -> 1 | E3: =세팅!D4 -> 42461 | F3: =IF(COUNT(J3:O3)>=4,AVERAGE(J3:O3),"") -> 1702866.4 | G3: {=IFERROR(IF($A3="","",IF(SUMIFS(RAW_매출A!$J$2:$J$7000,RAW_매출A!$B$2:$B$7000,$A3,RAW_매출A!$A$2:$A$7000,EDATE($E3,G$1-1))=0,"",SUMIFS(RAW_매출A!$J$2:$J$7000,RAW_매출A!$B$2:$B$7000,$A3,RAW_매출A!$A$2:$A$7000,EDATE($E3,G$1-1))/(INDEX(요약_월별시즈널리티!$F$7:$F$18,MONTH(EDATE($E3,G$1-1)))/100))),"")} -> 1623835.6 | H3: {=IFERROR(IF($A3="","",IF(SUMIFS(RAW_매출A!$J$2:$J$7000,RAW_매출A!$B$2:$B$7000,$A3,RAW_매출A!$A$2:$A$7000,EDATE($E3,H$1-1))=0,"",SUMIFS(RAW_매출A!$J$2:$J$7000,RAW_매출A!$B$2:$B$7000,$A3,RAW_매출A!$A$2:$A$7000,EDATE($E3,H$1-1))/(INDEX(요약_월별시즈널리티!$F$7:$F$18,MONTH(EDATE($E3,H$1-1)))/100))),"")} -> 1372346.7 | I3: {=IFERROR(IF($A3="","",IF(SUMIFS(RAW_매출A!$J$2:$J$7000,RAW_매출A!$B$2:$B$7000,$A3,RAW_매출A!$A$2:$A$7000,EDATE($E3,I$1-1))=0,"",SUMIFS(RAW_매출A!$J$2:$J$7000,RAW_매출A!$B$2:$B$7000,$A3,RAW_매출A!$A$2:$A$7000,EDATE($E3,I$1-1))/(INDEX(요약_월별시즈널리티!$F$7:$F$18,MONTH(EDATE($E3,I$1-1)))/100))),"")} -> 1213215.7 | J3: {=IFERROR(IF($A3="","",IF(SUMIFS(RAW_매출A!$J$2:$J$7000,RAW_매출A!$B$2:$B$7000,$A3,RAW_매출A!$A$2:$A$7000,EDATE($E3,J$1-1))=0,"",SUMIFS(RAW_매출A!$J$2:$J$7000,RAW_매출A!$B$2:$B$7000,$A3,RAW_매출A!$A$2:$A$7000,EDATE($E3,J$1-1))/(INDEX(요약_월별시즈널리티!$F$7:$F$18,MONTH(EDATE($E3,J$1-1)))/100))),"")} -> 1467347.9 | K3: {=IFERROR(IF($A3="","",IF(SUMIFS(RAW_매출A!$J$2:$J$7000,RAW_매출A!$B$2:$B$7000,$A3,RAW_매출A!$A$2:$A$7000,EDATE($E3,K$1-1))=0,"",SUMIFS(RAW_매출A!$J$2:$J$7000,RAW_매출A!$B$2:$B$7000,$A3,RAW_매출A!$A$2:$A$7000,EDATE($E3,K$1-1))/(INDEX(요약_월별시즈널리티!$F$7:$F$18,MONTH(EDATE($E3,K$1-1)))/100))),"")} -> 1382720.4 | L3: {=IFERROR(IF($A3="","",IF(SUMIFS(RAW_매출A!$J$2:$J$7000,RAW_매출A!$B$2:$B$7000,$A3,RAW_매출A!$A$2:$A$7000,EDATE($E3,L$1-1))=0,"",SUMIFS(RAW_매출A!$J$2:$J$7000,RAW_매출A!$B$2:$B$7000,$A3,RAW_매출A!$A$2:$A$7000,EDATE($E3,L$1-1))/(INDEX(요약_월별시즈널리티!$F$7:$F$18,MONTH(EDATE($E3,L$1-1)))/100))),"")} -> 1577051.1 | M3: {=IFERROR(IF($A3="","",IF(SUMIFS(RAW_매출A!$J$2:$J$7000,RAW_매출A!$B$2:$B$7000,$A3,RAW_매출A!$A$2:$A$7000,EDATE($E3,M$1-1))=0,"",SUMIFS(RAW_매출A!$J$2:$J$7000,RAW_매출A!$B$2:$B$7000,$A3,RAW_매출A!$A$2:$A$7000,EDATE($E3,M$1-1))/(INDEX(요약_월별시즈널리티!$F$7:$F$18,MONTH(EDATE($E3,M$1-1)))/100))),"")} -> 1907529.2 | N3: {=IFERROR(IF($A3="","",IF(SUMIFS(RAW_매출A!$J$2:$J$7000,RAW_매출A!$B$2:$B$7000,$A3,RAW_매출A!$A$2:$A$7000,EDATE($E3,N$1-1))=0,"",SUMIFS(RAW_매출A!$J$2:$J$7000,RAW_매출A!$B$2:$B$7000,$A3,RAW_매출A!$A$2:$A$7000,EDATE($E3,N$1-1))/(INDEX(요약_월별시즈널리티!$F$7:$F$18,MONTH(EDATE($E3,N$1-1)))/100))),"")} -> 1804778.2 | ... BN3: {=IFERROR(IF($A3="","",IF(SUMIFS(RAW_매출A!$J$2:$J$7000,RAW_매출A!$B$2:$B$7000,$A3,RAW_매출A!$A$2:$A$7000,EDATE($E3,BN$1-1))=0,"",SUMIFS(RAW_매출A!$J$2:$J$7000,RAW_매출A!$B$2:$B$7000,$A3,RAW_매출A!$A$2:$A$7000,EDATE($E3,BN$1-1))/(INDEX(요약_월별시즈널리티!$F$7:$F$18,MONTH(EDATE($E3,BN$1-1)))/100))),"")} -> 4493082.3
A4: =세팅!A5 -> (0003) 구디점 | B4: =세팅!B5 -> 150-3 | C4: =IFERROR(VALUE(MID(B4,5,10)),"") -> 3 | D4: =IF(C4="","",IF(C4>=3,"3+",TEXT(C4,"0"))) -> 3+ | E4: =세팅!D5 -> 42522 | F4: =IF(COUNT(J4:O4)>=4,AVERAGE(J4:O4),"") -> 5899967.7 | G4: {=IFERROR(IF($A4="","",IF(SUMIFS(RAW_매출A!$J$2:$J$7000,RAW_매출A!$B$2:$B$7000,$A4,RAW_매출A!$A$2:$A$7000,EDATE($E4,G$1-1))=0,"",SUMIFS(RAW_매출A!$J$2:$J$7000,RAW_매출A!$B$2:$B$7000,$A4,RAW_매출A!$A$2:$A$7000,EDATE($E4,G$1-1))/(INDEX(요약_월별시즈널리티!$F$7:$F$18,MONTH(EDATE($E4,G$1-1)))/100))),"")} -> 4466618.6 | H4: {=IFERROR(IF($A4="","",IF(SUMIFS(RAW_매출A!$J$2:$J$7000,RAW_매출A!$B$2:$B$7000,$A4,RAW_매출A!$A$2:$A$7000,EDATE($E4,H$1-1))=0,"",SUMIFS(RAW_매출A!$J$2:$J$7000,RAW_매출A!$B$2:$B$7000,$A4,RAW_매출A!$A$2:$A$7000,EDATE($E4,H$1-1))/(INDEX(요약_월별시즈널리티!$F$7:$F$18,MONTH(EDATE($E4,H$1-1)))/100))),"")} -> 5164376.9 | I4: {=IFERROR(IF($A4="","",IF(SUMIFS(RAW_매출A!$J$2:$J$7000,RAW_매출A!$B$2:$B$7000,$A4,RAW_매출A!$A$2:$A$7000,EDATE($E4,I$1-1))=0,"",SUMIFS(RAW_매출A!$J$2:$J$7000,RAW_매출A!$B$2:$B$7000,$A4,RAW_매출A!$A$2:$A$7000,EDATE($E4,I$1-1))/(INDEX(요약_월별시즈널리티!$F$7:$F$18,MONTH(EDATE($E4,I$1-1)))/100))),"")} -> 4756714.8 | J4: {=IFERROR(IF($A4="","",IF(SUMIFS(RAW_매출A!$J$2:$J$7000,RAW_매출A!$B$2:$B$7000,$A4,RAW_매출A!$A$2:$A$7000,EDATE($E4,J$1-1))=0,"",SUMIFS(RAW_매출A!$J$2:$J$7000,RAW_매출A!$B$2:$B$7000,$A4,RAW_매출A!$A$2:$A$7000,EDATE($E4,J$1-1))/(INDEX(요약_월별시즈널리티!$F$7:$F$18,MONTH(EDATE($E4,J$1-1)))/100))),"")} -> 5307441 | K4: {=IFERROR(IF($A4="","",IF(SUMIFS(RAW_매출A!$J$2:$J$7000,RAW_매출A!$B$2:$B$7000,$A4,RAW_매출A!$A$2:$A$7000,EDATE($E4,K$1-1))=0,"",SUMIFS(RAW_매출A!$J$2:$J$7000,RAW_매출A!$B$2:$B$7000,$A4,RAW_매출A!$A$2:$A$7000,EDATE($E4,K$1-1))/(INDEX(요약_월별시즈널리티!$F$7:$F$18,MONTH(EDATE($E4,K$1-1)))/100))),"")} -> 5360978.8 | L4: {=IFERROR(IF($A4="","",IF(SUMIFS(RAW_매출A!$J$2:$J$7000,RAW_매출A!$B$2:$B$7000,$A4,RAW_매출A!$A$2:$A$7000,EDATE($E4,L$1-1))=0,"",SUMIFS(RAW_매출A!$J$2:$J$7000,RAW_매출A!$B$2:$B$7000,$A4,RAW_매출A!$A$2:$A$7000,EDATE($E4,L$1-1))/(INDEX(요약_월별시즈널리티!$F$7:$F$18,MONTH(EDATE($E4,L$1-1)))/100))),"")} -> 5572817 | M4: {=IFERROR(IF($A4="","",IF(SUMIFS(RAW_매출A!$J$2:$J$7000,RAW_매출A!$B$2:$B$7000,$A4,RAW_매출A!$A$2:$A$7000,EDATE($E4,M$1-1))=0,"",SUMIFS(RAW_매출A!$J$2:$J$7000,RAW_매출A!$B$2:$B$7000,$A4,RAW_매출A!$A$2:$A$7000,EDATE($E4,M$1-1))/(INDEX(요약_월별시즈널리티!$F$7:$F$18,MONTH(EDATE($E4,M$1-1)))/100))),"")} -> 5961376.4 | N4: {=IFERROR(IF($A4="","",IF(SUMIFS(RAW_매출A!$J$2:$J$7000,RAW_매출A!$B$2:$B$7000,$A4,RAW_매출A!$A$2:$A$7000,EDATE($E4,N$1-1))=0,"",SUMIFS(RAW_매출A!$J$2:$J$7000,RAW_매출A!$B$2:$B$7000,$A4,RAW_매출A!$A$2:$A$7000,EDATE($E4,N$1-1))/(INDEX(요약_월별시즈널리티!$F$7:$F$18,MONTH(EDATE($E4,N$1-1)))/100))),"")} -> 6249566.3 | ... BN4: {=IFERROR(IF($A4="","",IF(SUMIFS(RAW_매출A!$J$2:$J$7000,RAW_매출A!$B$2:$B$7000,$A4,RAW_매출A!$A$2:$A$7000,EDATE($E4,BN$1-1))=0,"",SUMIFS(RAW_매출A!$J$2:$J$7000,RAW_매출A!$B$2:$B$7000,$A4,RAW_매출A!$A$2:$A$7000,EDATE($E4,BN$1-1))/(INDEX(요약_월별시즈널리티!$F$7:$F$18,MONTH(EDATE($E4,BN$1-1)))/100))),"")} -> 12213506
A5: =세팅!A6 -> (0004) 신림점 | B5: =세팅!B6 -> 150-4 | C5: =IFERROR(VALUE(MID(B5,5,10)),"") -> 4 | D5: =IF(C5="","",IF(C5>=3,"3+",TEXT(C5,"0"))) -> 3+ | E5: =세팅!D6 -> 42644 | F5: =IF(COUNT(J5:O5)>=4,AVERAGE(J5:O5),"") -> 5385185.1 | G5: {=IFERROR(IF($A5="","",IF(SUMIFS(RAW_매출A!$J$2:$J$7000,RAW_매출A!$B$2:$B$7000,$A5,RAW_매출A!$A$2:$A$7000,EDATE($E5,G$1-1))=0,"",SUMIFS(RAW_매출A!$J$2:$J$7000,RAW_매출A!$B$2:$B$7000,$A5,RAW_매출A!$A$2:$A$7000,EDATE($E5,G$1-1))/(INDEX(요약_월별시즈널리티!$F$7:$F$18,MONTH(EDATE($E5,G$1-1)))/100))),"")} -> 3412790.3 | H5: {=IFERROR(IF($A5="","",IF(SUMIFS(RAW_매출A!$J$2:$J$7000,RAW_매출A!$B$2:$B$7000,$A5,RAW_매출A!$A$2:$A$7000,EDATE($E5,H$1-1))=0,"",SUMIFS(RAW_매출A!$J$2:$J$7000,RAW_매출A!$B$2:$B$7000,$A5,RAW_매출A!$A$2:$A$7000,EDATE($E5,H$1-1))/(INDEX(요약_월별시즈널리티!$F$7:$F$18,MONTH(EDATE($E5,H$1-1)))/100))),"")} -> 3826629.3 | I5: {=IFERROR(IF($A5="","",IF(SUMIFS(RAW_매출A!$J$2:$J$7000,RAW_매출A!$B$2:$B$7000,$A5,RAW_매출A!$A$2:$A$7000,EDATE($E5,I$1-1))=0,"",SUMIFS(RAW_매출A!$J$2:$J$7000,RAW_매출A!$B$2:$B$7000,$A5,RAW_매출A!$A$2:$A$7000,EDATE($E5,I$1-1))/(INDEX(요약_월별시즈널리티!$F$7:$F$18,MONTH(EDATE($E5,I$1-1)))/100))),"")} -> 4662648 | J5: {=IFERROR(IF($A5="","",IF(SUMIFS(RAW_매출A!$J$2:$J$7000,RAW_매출A!$B$2:$B$7000,$A5,RAW_매출A!$A$2:$A$7000,EDATE($E5,J$1-1))=0,"",SUMIFS(RAW_매출A!$J$2:$J$7000,RAW_매출A!$B$2:$B$7000,$A5,RAW_매출A!$A$2:$A$7000,EDATE($E5,J$1-1))/(INDEX(요약_월별시즈널리티!$F$7:$F$18,MONTH(EDATE($E5,J$1-1)))/100))),"")} -> 5391610.4 | K5: {=IFERROR(IF($A5="","",IF(SUMIFS(RAW_매출A!$J$2:$J$7000,RAW_매출A!$B$2:$B$7000,$A5,RAW_매출A!$A$2:$A$7000,EDATE($E5,K$1-1))=0,"",SUMIFS(RAW_매출A!$J$2:$J$7000,RAW_매출A!$B$2:$B$7000,$A5,RAW_매출A!$A$2:$A$7000,EDATE($E5,K$1-1))/(INDEX(요약_월별시즈널리티!$F$7:$F$18,MONTH(EDATE($E5,K$1-1)))/100))),"")} -> 5459866.4 | L5: {=IFERROR(IF($A5="","",IF(SUMIFS(RAW_매출A!$J$2:$J$7000,RAW_매출A!$B$2:$B$7000,$A5,RAW_매출A!$A$2:$A$7000,EDATE($E5,L$1-1))=0,"",SUMIFS(RAW_매출A!$J$2:$J$7000,RAW_매출A!$B$2:$B$7000,$A5,RAW_매출A!$A$2:$A$7000,EDATE($E5,L$1-1))/(INDEX(요약_월별시즈널리티!$F$7:$F$18,MONTH(EDATE($E5,L$1-1)))/100))),"")} -> 5336950.3 | M5: {=IFERROR(IF($A5="","",IF(SUMIFS(RAW_매출A!$J$2:$J$7000,RAW_매출A!$B$2:$B$7000,$A5,RAW_매출A!$A$2:$A$7000,EDATE($E5,M$1-1))=0,"",SUMIFS(RAW_매출A!$J$2:$J$7000,RAW_매출A!$B$2:$B$7000,$A5,RAW_매출A!$A$2:$A$7000,EDATE($E5,M$1-1))/(INDEX(요약_월별시즈널리티!$F$7:$F$18,MONTH(EDATE($E5,M$1-1)))/100))),"")} -> 5652854.7 | N5: {=IFERROR(IF($A5="","",IF(SUMIFS(RAW_매출A!$J$2:$J$7000,RAW_매출A!$B$2:$B$7000,$A5,RAW_매출A!$A$2:$A$7000,EDATE($E5,N$1-1))=0,"",SUMIFS(RAW_매출A!$J$2:$J$7000,RAW_매출A!$B$2:$B$7000,$A5,RAW_매출A!$A$2:$A$7000,EDATE($E5,N$1-1))/(INDEX(요약_월별시즈널리티!$F$7:$F$18,MONTH(EDATE($E5,N$1-1)))/100))),"")} -> 5406818.1 | ... BN5: {=IFERROR(IF($A5="","",IF(SUMIFS(RAW_매출A!$J$2:$J$7000,RAW_매출A!$B$2:$B$7000,$A5,RAW_매출A!$A$2:$A$7000,EDATE($E5,BN$1-1))=0,"",SUMIFS(RAW_매출A!$J$2:$J$7000,RAW_매출A!$B$2:$B$7000,$A5,RAW_매출A!$A$2:$A$7000,EDATE($E5,BN$1-1))/(INDEX(요약_월별시즈널리티!$F$7:$F$18,MONTH(EDATE($E5,BN$1-1)))/100))),"")} -> 6154394.4
A6: =세팅!A7 -> (0005) 대학점 | B6: =세팅!B7 -> 150-2 | C6: =IFERROR(VALUE(MID(B6,5,10)),"") -> 2 | D6: =IF(C6="","",IF(C6>=3,"3+",TEXT(C6,"0"))) -> 2 | E6: =세팅!D7 -> 42736 | F6: =IF(COUNT(J6:O6)>=4,AVERAGE(J6:O6),"") -> 6295452.6 | G6: {=IFERROR(IF($A6="","",IF(SUMIFS(RAW_매출A!$J$2:$J$7000,RAW_매출A!$B$2:$B$7000,$A6,RAW_매출A!$A$2:$A$7000,EDATE($E6,G$1-1))=0,"",SUMIFS(RAW_매출A!$J$2:$J$7000,RAW_매출A!$B$2:$B$7000,$A6,RAW_매출A!$A$2:$A$7000,EDATE($E6,G$1-1))/(INDEX(요약_월별시즈널리티!$F$7:$F$18,MONTH(EDATE($E6,G$1-1)))/100))),"")} -> 4977462.6 | H6: {=IFERROR(IF($A6="","",IF(SUMIFS(RAW_매출A!$J$2:$J$7000,RAW_매출A!$B$2:$B$7000,$A6,RAW_매출A!$A$2:$A$7000,EDATE($E6,H$1-1))=0,"",SUMIFS(RAW_매출A!$J$2:$J$7000,RAW_매출A!$B$2:$B$7000,$A6,RAW_매출A!$A$2:$A$7000,EDATE($E6,H$1-1))/(INDEX(요약_월별시즈널리티!$F$7:$F$18,MONTH(EDATE($E6,H$1-1)))/100))),"")} -> 5326988.3 | I6: {=IFERROR(IF($A6="","",IF(SUMIFS(RAW_매출A!$J$2:$J$7000,RAW_매출A!$B$2:$B$7000,$A6,RAW_매출A!$A$2:$A$7000,EDATE($E6,I$1-1))=0,"",SUMIFS(RAW_매출A!$J$2:$J$7000,RAW_매출A!$B$2:$B$7000,$A6,RAW_매출A!$A$2:$A$7000,EDATE($E6,I$1-1))/(INDEX(요약_월별시즈널리티!$F$7:$F$18,MONTH(EDATE($E6,I$1-1)))/100))),"")} -> 5354445.1 | J6: {=IFERROR(IF($A6="","",IF(SUMIFS(RAW_매출A!$J$2:$J$7000,RAW_매출A!$B$2:$B$7000,$A6,RAW_매출A!$A$2:$A$7000,EDATE($E6,J$1-1))=0,"",SUMIFS(RAW_매출A!$J$2:$J$7000,RAW_매출A!$B$2:$B$7000,$A6,RAW_매출A!$A$2:$A$7000,EDATE($E6,J$1-1))/(INDEX(요약_월별시즈널리티!$F$7:$F$18,MONTH(EDATE($E6,J$1-1)))/100))),"")} -> 5339901.1 | K6: {=IFERROR(IF($A6="","",IF(SUMIFS(RAW_매출A!$J$2:$J$7000,RAW_매출A!$B$2:$B$7000,$A6,RAW_매출A!$A$2:$A$7000,EDATE($E6,K$1-1))=0,"",SUMIFS(RAW_매출A!$J$2:$J$7000,RAW_매출A!$B$2:$B$7000,$A6,RAW_매출A!$A$2:$A$7000,EDATE($E6,K$1-1))/(INDEX(요약_월별시즈널리티!$F$7:$F$18,MONTH(EDATE($E6,K$1-1)))/100))),"")} -> 5943039.3 | L6: {=IFERROR(IF($A6="","",IF(SUMIFS(RAW_매출A!$J$2:$J$7000,RAW_매출A!$B$2:$B$7000,$A6,RAW_매출A!$A$2:$A$7000,EDATE($E6,L$1-1))=0,"",SUMIFS(RAW_매출A!$J$2:$J$7000,RAW_매출A!$B$2:$B$7000,$A6,RAW_매출A!$A$2:$A$7000,EDATE($E6,L$1-1))/(INDEX(요약_월별시즈널리티!$F$7:$F$18,MONTH(EDATE($E6,L$1-1)))/100))),"")} -> 5941546.5 | M6: {=IFERROR(IF($A6="","",IF(SUMIFS(RAW_매출A!$J$2:$J$7000,RAW_매출A!$B$2:$B$7000,$A6,RAW_매출A!$A$2:$A$7000,EDATE($E6,M$1-1))=0,"",SUMIFS(RAW_매출A!$J$2:$J$7000,RAW_매출A!$B$2:$B$7000,$A6,RAW_매출A!$A$2:$A$7000,EDATE($E6,M$1-1))/(INDEX(요약_월별시즈널리티!$F$7:$F$18,MONTH(EDATE($E6,M$1-1)))/100))),"")} -> 7309035.8 | N6: {=IFERROR(IF($A6="","",IF(SUMIFS(RAW_매출A!$J$2:$J$7000,RAW_매출A!$B$2:$B$7000,$A6,RAW_매출A!$A$2:$A$7000,EDATE($E6,N$1-1))=0,"",SUMIFS(RAW_매출A!$J$2:$J$7000,RAW_매출A!$B$2:$B$7000,$A6,RAW_매출A!$A$2:$A$7000,EDATE($E6,N$1-1))/(INDEX(요약_월별시즈널리티!$F$7:$F$18,MONTH(EDATE($E6,N$1-1)))/100))),"")} -> 6736229.4 | ... BN6: {=IFERROR(IF($A6="","",IF(SUMIFS(RAW_매출A!$J$2:$J$7000,RAW_매출A!$B$2:$B$7000,$A6,RAW_매출A!$A$2:$A$7000,EDATE($E6,BN$1-1))=0,"",SUMIFS(RAW_매출A!$J$2:$J$7000,RAW_매출A!$B$2:$B$7000,$A6,RAW_매출A!$A$2:$A$7000,EDATE($E6,BN$1-1))/(INDEX(요약_월별시즈널리티!$F$7:$F$18,MONTH(EDATE($E6,BN$1-1)))/100))),"")} -> 3354242
A7: =세팅!A8 -> (0006) 서림점 | B7: =세팅!B8 -> 150-2 | C7: =IFERROR(VALUE(MID(B7,5,10)),"") -> 2 | D7: =IF(C7="","",IF(C7>=3,"3+",TEXT(C7,"0"))) -> 2 | E7: =세팅!D8 -> 43040 | F7: =IF(COUNT(J7:O7)>=4,AVERAGE(J7:O7),"") -> 4277752.1 | G7: {=IFERROR(IF($A7="","",IF(SUMIFS(RAW_매출A!$J$2:$J$7000,RAW_매출A!$B$2:$B$7000,$A7,RAW_매출A!$A$2:$A$7000,EDATE($E7,G$1-1))=0,"",SUMIFS(RAW_매출A!$J$2:$J$7000,RAW_매출A!$B$2:$B$7000,$A7,RAW_매출A!$A$2:$A$7000,EDATE($E7,G$1-1))/(INDEX(요약_월별시즈널리티!$F$7:$F$18,MONTH(EDATE($E7,G$1-1)))/100))),"")} -> 2566454.2 | H7: {=IFERROR(IF($A7="","",IF(SUMIFS(RAW_매출A!$J$2:$J$7000,RAW_매출A!$B$2:$B$7000,$A7,RAW_매출A!$A$2:$A$7000,EDATE($E7,H$1-1))=0,"",SUMIFS(RAW_매출A!$J$2:$J$7000,RAW_매출A!$B$2:$B$7000,$A7,RAW_매출A!$A$2:$A$7000,EDATE($E7,H$1-1))/(INDEX(요약_월별시즈널리티!$F$7:$F$18,MONTH(EDATE($E7,H$1-1)))/100))),"")} -> 3343596.7 | I7: {=IFERROR(IF($A7="","",IF(SUMIFS(RAW_매출A!$J$2:$J$7000,RAW_매출A!$B$2:$B$7000,$A7,RAW_매출A!$A$2:$A$7000,EDATE($E7,I$1-1))=0,"",SUMIFS(RAW_매출A!$J$2:$J$7000,RAW_매출A!$B$2:$B$7000,$A7,RAW_매출A!$A$2:$A$7000,EDATE($E7,I$1-1))/(INDEX(요약_월별시즈널리티!$F$7:$F$18,MONTH(EDATE($E7,I$1-1)))/100))),"")} -> 4406224.4 | J7: {=IFERROR(IF($A7="","",IF(SUMIFS(RAW_매출A!$J$2:$J$7000,RAW_매출A!$B$2:$B$7000,$A7,RAW_매출A!$A$2:$A$7000,EDATE($E7,J$1-1))=0,"",SUMIFS(RAW_매출A!$J$2:$J$7000,RAW_매출A!$B$2:$B$7000,$A7,RAW_매출A!$A$2:$A$7000,EDATE($E7,J$1-1))/(INDEX(요약_월별시즈널리티!$F$7:$F$18,MONTH(EDATE($E7,J$1-1)))/100))),"")} -> 4126339.7 | K7: {=IFERROR(IF($A7="","",IF(SUMIFS(RAW_매출A!$J$2:$J$7000,RAW_매출A!$B$2:$B$7000,$A7,RAW_매출A!$A$2:$A$7000,EDATE($E7,K$1-1))=0,"",SUMIFS(RAW_매출A!$J$2:$J$7000,RAW_매출A!$B$2:$B$7000,$A7,RAW_매출A!$A$2:$A$7000,EDATE($E7,K$1-1))/(INDEX(요약_월별시즈널리티!$F$7:$F$18,MONTH(EDATE($E7,K$1-1)))/100))),"")} -> 4047478.9 | L7: {=IFERROR(IF($A7="","",IF(SUMIFS(RAW_매출A!$J$2:$J$7000,RAW_매출A!$B$2:$B$7000,$A7,RAW_매출A!$A$2:$A$7000,EDATE($E7,L$1-1))=0,"",SUMIFS(RAW_매출A!$J$2:$J$7000,RAW_매출A!$B$2:$B$7000,$A7,RAW_매출A!$A$2:$A$7000,EDATE($E7,L$1-1))/(INDEX(요약_월별시즈널리티!$F$7:$F$18,MONTH(EDATE($E7,L$1-1)))/100))),"")} -> 3986532 | M7: {=IFERROR(IF($A7="","",IF(SUMIFS(RAW_매출A!$J$2:$J$7000,RAW_매출A!$B$2:$B$7000,$A7,RAW_매출A!$A$2:$A$7000,EDATE($E7,M$1-1))=0,"",SUMIFS(RAW_매출A!$J$2:$J$7000,RAW_매출A!$B$2:$B$7000,$A7,RAW_매출A!$A$2:$A$7000,EDATE($E7,M$1-1))/(INDEX(요약_월별시즈널리티!$F$7:$F$18,MONTH(EDATE($E7,M$1-1)))/100))),"")} -> 4447314.3 | N7: {=IFERROR(IF($A7="","",IF(SUMIFS(RAW_매출A!$J$2:$J$7000,RAW_매출A!$B$2:$B$7000,$A7,RAW_매출A!$A$2:$A$7000,EDATE($E7,N$1-1))=0,"",SUMIFS(RAW_매출A!$J$2:$J$7000,RAW_매출A!$B$2:$B$7000,$A7,RAW_매출A!$A$2:$A$7000,EDATE($E7,N$1-1))/(INDEX(요약_월별시즈널리티!$F$7:$F$18,MONTH(EDATE($E7,N$1-1)))/100))),"")} -> 4365436.2 | ... BN7: {=IFERROR(IF($A7="","",IF(SUMIFS(RAW_매출A!$J$2:$J$7000,RAW_매출A!$B$2:$B$7000,$A7,RAW_매출A!$A$2:$A$7000,EDATE($E7,BN$1-1))=0,"",SUMIFS(RAW_매출A!$J$2:$J$7000,RAW_매출A!$B$2:$B$7000,$A7,RAW_매출A!$A$2:$A$7000,EDATE($E7,BN$1-1))/(INDEX(요약_월별시즈널리티!$F$7:$F$18,MONTH(EDATE($E7,BN$1-1)))/100))),"")} -> 7164869.8
A8: =세팅!A9 -> (0007) 낙성대점 | B8: =세팅!B9 -> 150-1 | C8: =IFERROR(VALUE(MID(B8,5,10)),"") -> 1 | D8: =IF(C8="","",IF(C8>=3,"3+",TEXT(C8,"0"))) -> 1 | E8: =세팅!D9 -> 43160 | F8: =IF(COUNT(J8:O8)>=4,AVERAGE(J8:O8),"") -> 5204137.4 | G8: {=IFERROR(IF($A8="","",IF(SUMIFS(RAW_매출A!$J$2:$J$7000,RAW_매출A!$B$2:$B$7000,$A8,RAW_매출A!$A$2:$A$7000,EDATE($E8,G$1-1))=0,"",SUMIFS(RAW_매출A!$J$2:$J$7000,RAW_매출A!$B$2:$B$7000,$A8,RAW_매출A!$A$2:$A$7000,EDATE($E8,G$1-1))/(INDEX(요약_월별시즈널리티!$F$7:$F$18,MONTH(EDATE($E8,G$1-1)))/100))),"")} -> 3990878 | H8: {=IFERROR(IF($A8="","",IF(SUMIFS(RAW_매출A!$J$2:$J$7000,RAW_매출A!$B$2:$B$7000,$A8,RAW_매출A!$A$2:$A$7000,EDATE($E8,H$1-1))=0,"",SUMIFS(RAW_매출A!$J$2:$J$7000,RAW_매출A!$B$2:$B$7000,$A8,RAW_매출A!$A$2:$A$7000,EDATE($E8,H$1-1))/(INDEX(요약_월별시즈널리티!$F$7:$F$18,MONTH(EDATE($E8,H$1-1)))/100))),"")} -> 3938863.6 | I8: {=IFERROR(IF($A8="","",IF(SUMIFS(RAW_매출A!$J$2:$J$7000,RAW_매출A!$B$2:$B$7000,$A8,RAW_매출A!$A$2:$A$7000,EDATE($E8,I$1-1))=0,"",SUMIFS(RAW_매출A!$J$2:$J$7000,RAW_매출A!$B$2:$B$7000,$A8,RAW_매출A!$A$2:$A$7000,EDATE($E8,I$1-1))/(INDEX(요약_월별시즈널리티!$F$7:$F$18,MONTH(EDATE($E8,I$1-1)))/100))),"")} -> 5188533.4 | J8: {=IFERROR(IF($A8="","",IF(SUMIFS(RAW_매출A!$J$2:$J$7000,RAW_매출A!$B$2:$B$7000,$A8,RAW_매출A!$A$2:$A$7000,EDATE($E8,J$1-1))=0,"",SUMIFS(RAW_매출A!$J$2:$J$7000,RAW_매출A!$B$2:$B$7000,$A8,RAW_매출A!$A$2:$A$7000,EDATE($E8,J$1-1))/(INDEX(요약_월별시즈널리티!$F$7:$F$18,MONTH(EDATE($E8,J$1-1)))/100))),"")} -> 5241053 | K8: {=IFERROR(IF($A8="","",IF(SUMIFS(RAW_매출A!$J$2:$J$7000,RAW_매출A!$B$2:$B$7000,$A8,RAW_매출A!$A$2:$A$7000,EDATE($E8,K$1-1))=0,"",SUMIFS(RAW_매출A!$J$2:$J$7000,RAW_매출A!$B$2:$B$7000,$A8,RAW_매출A!$A$2:$A$7000,EDATE($E8,K$1-1))/(INDEX(요약_월별시즈널리티!$F$7:$F$18,MONTH(EDATE($E8,K$1-1)))/100))),"")} -> 5397471.2 | L8: {=IFERROR(IF($A8="","",IF(SUMIFS(RAW_매출A!$J$2:$J$7000,RAW_매출A!$B$2:$B$7000,$A8,RAW_매출A!$A$2:$A$7000,EDATE($E8,L$1-1))=0,"",SUMIFS(RAW_매출A!$J$2:$J$7000,RAW_매출A!$B$2:$B$7000,$A8,RAW_매출A!$A$2:$A$7000,EDATE($E8,L$1-1))/(INDEX(요약_월별시즈널리티!$F$7:$F$18,MONTH(EDATE($E8,L$1-1)))/100))),"")} -> 4413729.6 | M8: {=IFERROR(IF($A8="","",IF(SUMIFS(RAW_매출A!$J$2:$J$7000,RAW_매출A!$B$2:$B$7000,$A8,RAW_매출A!$A$2:$A$7000,EDATE($E8,M$1-1))=0,"",SUMIFS(RAW_매출A!$J$2:$J$7000,RAW_매출A!$B$2:$B$7000,$A8,RAW_매출A!$A$2:$A$7000,EDATE($E8,M$1-1))/(INDEX(요약_월별시즈널리티!$F$7:$F$18,MONTH(EDATE($E8,M$1-1)))/100))),"")} -> 5677983.1 | N8: {=IFERROR(IF($A8="","",IF(SUMIFS(RAW_매출A!$J$2:$J$7000,RAW_매출A!$B$2:$B$7000,$A8,RAW_매출A!$A$2:$A$7000,EDATE($E8,N$1-1))=0,"",SUMIFS(RAW_매출A!$J$2:$J$7000,RAW_매출A!$B$2:$B$7000,$A8,RAW_매출A!$A$2:$A$7000,EDATE($E8,N$1-1))/(INDEX(요약_월별시즈널리티!$F$7:$F$18,MONTH(EDATE($E8,N$1-1)))/100))),"")} -> 5398177.7 | ... BN8: {=IFERROR(IF($A8="","",IF(SUMIFS(RAW_매출A!$J$2:$J$7000,RAW_매출A!$B$2:$B$7000,$A8,RAW_매출A!$A$2:$A$7000,EDATE($E8,BN$1-1))=0,"",SUMIFS(RAW_매출A!$J$2:$J$7000,RAW_매출A!$B$2:$B$7000,$A8,RAW_매출A!$A$2:$A$7000,EDATE($E8,BN$1-1))/(INDEX(요약_월별시즈널리티!$F$7:$F$18,MONTH(EDATE($E8,BN$1-1)))/100))),"")} -> 8714549.5
A9: =세팅!A10 -> (0008) 트리하우스점 | B9: =세팅!B10 -> 0 | C9: =IFERROR(VALUE(MID(B9,5,10)),"") | D9: =IF(C9="","",IF(C9>=3,"3+",TEXT(C9,"0"))) | E9: =세팅!D10 -> 43282 | F9: =IF(COUNT(J9:O9)>=4,AVERAGE(J9:O9),"") | G9: {=IFERROR(IF($A9="","",IF(SUMIFS(RAW_매출A!$J$2:$J$7000,RAW_매출A!$B$2:$B$7000,$A9,RAW_매출A!$A$2:$A$7000,EDATE($E9,G$1-1))=0,"",SUMIFS(RAW_매출A!$J$2:$J$7000,RAW_매출A!$B$2:$B$7000,$A9,RAW_매출A!$A$2:$A$7000,EDATE($E9,G$1-1))/(INDEX(요약_월별시즈널리티!$F$7:$F$18,MONTH(EDATE($E9,G$1-1)))/100))),"")} | H9: {=IFERROR(IF($A9="","",IF(SUMIFS(RAW_매출A!$J$2:$J$7000,RAW_매출A!$B$2:$B$7000,$A9,RAW_매출A!$A$2:$A$7000,EDATE($E9,H$1-1))=0,"",SUMIFS(RAW_매출A!$J$2:$J$7000,RAW_매출A!$B$2:$B$7000,$A9,RAW_매출A!$A$2:$A$7000,EDATE($E9,H$1-1))/(INDEX(요약_월별시즈널리티!$F$7:$F$18,MONTH(EDATE($E9,H$1-1)))/100))),"")} | I9: {=IFERROR(IF($A9="","",IF(SUMIFS(RAW_매출A!$J$2:$J$7000,RAW_매출A!$B$2:$B$7000,$A9,RAW_매출A!$A$2:$A$7000,EDATE($E9,I$1-1))=0,"",SUMIFS(RAW_매출A!$J$2:$J$7000,RAW_매출A!$B$2:$B$7000,$A9,RAW_매출A!$A$2:$A$7000,EDATE($E9,I$1-1))/(INDEX(요약_월별시즈널리티!$F$7:$F$18,MONTH(EDATE($E9,I$1-1)))/100))),"")} | J9: {=IFERROR(IF($A9="","",IF(SUMIFS(RAW_매출A!$J$2:$J$7000,RAW_매출A!$B$2:$B$7000,$A9,RAW_매출A!$A$2:$A$7000,EDATE($E9,J$1-1))=0,"",SUMIFS(RAW_매출A!$J$2:$J$7000,RAW_매출A!$B$2:$B$7000,$A9,RAW_매출A!$A$2:$A$7000,EDATE($E9,J$1-1))/(INDEX(요약_월별시즈널리티!$F$7:$F$18,MONTH(EDATE($E9,J$1-1)))/100))),"")} | K9: {=IFERROR(IF($A9="","",IF(SUMIFS(RAW_매출A!$J$2:$J$7000,RAW_매출A!$B$2:$B$7000,$A9,RAW_매출A!$A$2:$A$7000,EDATE($E9,K$1-1))=0,"",SUMIFS(RAW_매출A!$J$2:$J$7000,RAW_매출A!$B$2:$B$7000,$A9,RAW_매출A!$A$2:$A$7000,EDATE($E9,K$1-1))/(INDEX(요약_월별시즈널리티!$F$7:$F$18,MONTH(EDATE($E9,K$1-1)))/100))),"")} | L9: {=IFERROR(IF($A9="","",IF(SUMIFS(RAW_매출A!$J$2:$J$7000,RAW_매출A!$B$2:$B$7000,$A9,RAW_매출A!$A$2:$A$7000,EDATE($E9,L$1-1))=0,"",SUMIFS(RAW_매출A!$J$2:$J$7000,RAW_매출A!$B$2:$B$7000,$A9,RAW_매출A!$A$2:$A$7000,EDATE($E9,L$1-1))/(INDEX(요약_월별시즈널리티!$F$7:$F$18,MONTH(EDATE($E9,L$1-1)))/100))),"")} | M9: {=IFERROR(IF($A9="","",IF(SUMIFS(RAW_매출A!$J$2:$J$7000,RAW_매출A!$B$2:$B$7000,$A9,RAW_매출A!$A$2:$A$7000,EDATE($E9,M$1-1))=0,"",SUMIFS(RAW_매출A!$J$2:$J$7000,RAW_매출A!$B$2:$B$7000,$A9,RAW_매출A!$A$2:$A$7000,EDATE($E9,M$1-1))/(INDEX(요약_월별시즈널리티!$F$7:$F$18,MONTH(EDATE($E9,M$1-1)))/100))),"")} | N9: {=IFERROR(IF($A9="","",IF(SUMIFS(RAW_매출A!$J$2:$J$7000,RAW_매출A!$B$2:$B$7000,$A9,RAW_매출A!$A$2:$A$7000,EDATE($E9,N$1-1))=0,"",SUMIFS(RAW_매출A!$J$2:$J$7000,RAW_매출A!$B$2:$B$7000,$A9,RAW_매출A!$A$2:$A$7000,EDATE($E9,N$1-1))/(INDEX(요약_월별시즈널리티!$F$7:$F$18,MONTH(EDATE($E9,N$1-1)))/100))),"")} | ... BN9: {=IFERROR(IF($A9="","",IF(SUMIFS(RAW_매출A!$J$2:$J$7000,RAW_매출A!$B$2:$B$7000,$A9,RAW_매출A!$A$2:$A$7000,EDATE($E9,BN$1-1))=0,"",SUMIFS(RAW_매출A!$J$2:$J$7000,RAW_매출A!$B$2:$B$7000,$A9,RAW_매출A!$A$2:$A$7000,EDATE($E9,BN$1-1))/(INDEX(요약_월별시즈널리티!$F$7:$F$18,MONTH(EDATE($E9,BN$1-1)))/100))),"")} -> 711195.43
A10: =세팅!A11 -> (0009) 신원점 | B10: =세팅!B11 -> 150-0 | C10: =IFERROR(VALUE(MID(B10,5,10)),"") -> 0 | D10: =IF(C10="","",IF(C10>=3,"3+",TEXT(C10,"0"))) -> 0 | E10: =세팅!D11 -> 43800 | F10: =IF(COUNT(J10:O10)>=4,AVERAGE(J10:O10),"") -> 4670950.9 | G10: {=IFERROR(IF($A10="","",IF(SUMIFS(RAW_매출A!$J$2:$J$7000,RAW_매출A!$B$2:$B$7000,$A10,RAW_매출A!$A$2:$A$7000,EDATE($E10,G$1-1))=0,"",SUMIFS(RAW_매출A!$J$2:$J$7000,RAW_매출A!$B$2:$B$7000,$A10,RAW_매출A!$A$2:$A$7000,EDATE($E10,G$1-1))/(INDEX(요약_월별시즈널리티!$F$7:$F$18,MONTH(EDATE($E10,G$1-1)))/100))),"")} -> 3735537.8 | H10: {=IFERROR(IF($A10="","",IF(SUMIFS(RAW_매출A!$J$2:$J$7000,RAW_매출A!$B$2:$B$7000,$A10,RAW_매출A!$A$2:$A$7000,EDATE($E10,H$1-1))=0,"",SUMIFS(RAW_매출A!$J$2:$J$7000,RAW_매출A!$B$2:$B$7000,$A10,RAW_매출A!$A$2:$A$7000,EDATE($E10,H$1-1))/(INDEX(요약_월별시즈널리티!$F$7:$F$18,MONTH(EDATE($E10,H$1-1)))/100))),"")} -> 3860252.4 | I10: {=IFERROR(IF($A10="","",IF(SUMIFS(RAW_매출A!$J$2:$J$7000,RAW_매출A!$B$2:$B$7000,$A10,RAW_매출A!$A$2:$A$7000,EDATE($E10,I$1-1))=0,"",SUMIFS(RAW_매출A!$J$2:$J$7000,RAW_매출A!$B$2:$B$7000,$A10,RAW_매출A!$A$2:$A$7000,EDATE($E10,I$1-1))/(INDEX(요약_월별시즈널리티!$F$7:$F$18,MONTH(EDATE($E10,I$1-1)))/100))),"")} -> 4326843.3 | J10: {=IFERROR(IF($A10="","",IF(SUMIFS(RAW_매출A!$J$2:$J$7000,RAW_매출A!$B$2:$B$7000,$A10,RAW_매출A!$A$2:$A$7000,EDATE($E10,J$1-1))=0,"",SUMIFS(RAW_매출A!$J$2:$J$7000,RAW_매출A!$B$2:$B$7000,$A10,RAW_매출A!$A$2:$A$7000,EDATE($E10,J$1-1))/(INDEX(요약_월별시즈널리티!$F$7:$F$18,MONTH(EDATE($E10,J$1-1)))/100))),"")} -> 4338716.2 | K10: {=IFERROR(IF($A10="","",IF(SUMIFS(RAW_매출A!$J$2:$J$7000,RAW_매출A!$B$2:$B$7000,$A10,RAW_매출A!$A$2:$A$7000,EDATE($E10,K$1-1))=0,"",SUMIFS(RAW_매출A!$J$2:$J$7000,RAW_매출A!$B$2:$B$7000,$A10,RAW_매출A!$A$2:$A$7000,EDATE($E10,K$1-1))/(INDEX(요약_월별시즈널리티!$F$7:$F$18,MONTH(EDATE($E10,K$1-1)))/100))),"")} -> 3850780.6 | L10: {=IFERROR(IF($A10="","",IF(SUMIFS(RAW_매출A!$J$2:$J$7000,RAW_매출A!$B$2:$B$7000,$A10,RAW_매출A!$A$2:$A$7000,EDATE($E10,L$1-1))=0,"",SUMIFS(RAW_매출A!$J$2:$J$7000,RAW_매출A!$B$2:$B$7000,$A10,RAW_매출A!$A$2:$A$7000,EDATE($E10,L$1-1))/(INDEX(요약_월별시즈널리티!$F$7:$F$18,MONTH(EDATE($E10,L$1-1)))/100))),"")} -> 4878189.4 | M10: {=IFERROR(IF($A10="","",IF(SUMIFS(RAW_매출A!$J$2:$J$7000,RAW_매출A!$B$2:$B$7000,$A10,RAW_매출A!$A$2:$A$7000,EDATE($E10,M$1-1))=0,"",SUMIFS(RAW_매출A!$J$2:$J$7000,RAW_매출A!$B$2:$B$7000,$A10,RAW_매출A!$A$2:$A$7000,EDATE($E10,M$1-1))/(INDEX(요약_월별시즈널리티!$F$7:$F$18,MONTH(EDATE($E10,M$1-1)))/100))),"")} -> 4461754.1 | N10: {=IFERROR(IF($A10="","",IF(SUMIFS(RAW_매출A!$J$2:$J$7000,RAW_매출A!$B$2:$B$7000,$A10,RAW_매출A!$A$2:$A$7000,EDATE($E10,N$1-1))=0,"",SUMIFS(RAW_매출A!$J$2:$J$7000,RAW_매출A!$B$2:$B$7000,$A10,RAW_매출A!$A$2:$A$7000,EDATE($E10,N$1-1))/(INDEX(요약_월별시즈널리티!$F$7:$F$18,MONTH(EDATE($E10,N$1-1)))/100))),"")} -> 4027564.4 | ... BN10: {=IFERROR(IF($A10="","",IF(SUMIFS(RAW_매출A!$J$2:$J$7000,RAW_매출A!$B$2:$B$7000,$A10,RAW_매출A!$A$2:$A$7000,EDATE($E10,BN$1-1))=0,"",SUMIFS(RAW_매출A!$J$2:$J$7000,RAW_매출A!$B$2:$B$7000,$A10,RAW_매출A!$A$2:$A$7000,EDATE($E10,BN$1-1))/(INDEX(요약_월별시즈널리티!$F$7:$F$18,MONTH(EDATE($E10,BN$1-1)))/100))),"")} -> 6328413
A11: =세팅!A12 -> (0010) 별빛거리점 | B11: =세팅!B12 -> 150-3 | C11: =IFERROR(VALUE(MID(B11,5,10)),"") -> 3 | D11: =IF(C11="","",IF(C11>=3,"3+",TEXT(C11,"0"))) -> 3+ | E11: =세팅!D12 -> 44593 | F11: =IF(COUNT(J11:O11)>=4,AVERAGE(J11:O11),"") -> 6295519.9 | G11: {=IFERROR(IF($A11="","",IF(SUMIFS(RAW_매출A!$J$2:$J$7000,RAW_매출A!$B$2:$B$7000,$A11,RAW_매출A!$A$2:$A$7000,EDATE($E11,G$1-1))=0,"",SUMIFS(RAW_매출A!$J$2:$J$7000,RAW_매출A!$B$2:$B$7000,$A11,RAW_매출A!$A$2:$A$7000,EDATE($E11,G$1-1))/(INDEX(요약_월별시즈널리티!$F$7:$F$18,MONTH(EDATE($E11,G$1-1)))/100))),"")} -> 3834957 | H11: {=IFERROR(IF($A11="","",IF(SUMIFS(RAW_매출A!$J$2:$J$7000,RAW_매출A!$B$2:$B$7000,$A11,RAW_매출A!$A$2:$A$7000,EDATE($E11,H$1-1))=0,"",SUMIFS(RAW_매출A!$J$2:$J$7000,RAW_매출A!$B$2:$B$7000,$A11,RAW_매출A!$A$2:$A$7000,EDATE($E11,H$1-1))/(INDEX(요약_월별시즈널리티!$F$7:$F$18,MONTH(EDATE($E11,H$1-1)))/100))),"")} -> 4101404.1 | I11: {=IFERROR(IF($A11="","",IF(SUMIFS(RAW_매출A!$J$2:$J$7000,RAW_매출A!$B$2:$B$7000,$A11,RAW_매출A!$A$2:$A$7000,EDATE($E11,I$1-1))=0,"",SUMIFS(RAW_매출A!$J$2:$J$7000,RAW_매출A!$B$2:$B$7000,$A11,RAW_매출A!$A$2:$A$7000,EDATE($E11,I$1-1))/(INDEX(요약_월별시즈널리티!$F$7:$F$18,MONTH(EDATE($E11,I$1-1)))/100))),"")} -> 4573993.7 | J11: {=IFERROR(IF($A11="","",IF(SUMIFS(RAW_매출A!$J$2:$J$7000,RAW_매출A!$B$2:$B$7000,$A11,RAW_매출A!$A$2:$A$7000,EDATE($E11,J$1-1))=0,"",SUMIFS(RAW_매출A!$J$2:$J$7000,RAW_매출A!$B$2:$B$7000,$A11,RAW_매출A!$A$2:$A$7000,EDATE($E11,J$1-1))/(INDEX(요약_월별시즈널리티!$F$7:$F$18,MONTH(EDATE($E11,J$1-1)))/100))),"")} -> 5122573.4 | K11: {=IFERROR(IF($A11="","",IF(SUMIFS(RAW_매출A!$J$2:$J$7000,RAW_매출A!$B$2:$B$7000,$A11,RAW_매출A!$A$2:$A$7000,EDATE($E11,K$1-1))=0,"",SUMIFS(RAW_매출A!$J$2:$J$7000,RAW_매출A!$B$2:$B$7000,$A11,RAW_매출A!$A$2:$A$7000,EDATE($E11,K$1-1))/(INDEX(요약_월별시즈널리티!$F$7:$F$18,MONTH(EDATE($E11,K$1-1)))/100))),"")} -> 6233224.2 | L11: {=IFERROR(IF($A11="","",IF(SUMIFS(RAW_매출A!$J$2:$J$7000,RAW_매출A!$B$2:$B$7000,$A11,RAW_매출A!$A$2:$A$7000,EDATE($E11,L$1-1))=0,"",SUMIFS(RAW_매출A!$J$2:$J$7000,RAW_매출A!$B$2:$B$7000,$A11,RAW_매출A!$A$2:$A$7000,EDATE($E11,L$1-1))/(INDEX(요약_월별시즈널리티!$F$7:$F$18,MONTH(EDATE($E11,L$1-1)))/100))),"")} -> 6494447.6 | M11: {=IFERROR(IF($A11="","",IF(SUMIFS(RAW_매출A!$J$2:$J$7000,RAW_매출A!$B$2:$B$7000,$A11,RAW_매출A!$A$2:$A$7000,EDATE($E11,M$1-1))=0,"",SUMIFS(RAW_매출A!$J$2:$J$7000,RAW_매출A!$B$2:$B$7000,$A11,RAW_매출A!$A$2:$A$7000,EDATE($E11,M$1-1))/(INDEX(요약_월별시즈널리티!$F$7:$F$18,MONTH(EDATE($E11,M$1-1)))/100))),"")} -> 7262760.7 | N11: {=IFERROR(IF($A11="","",IF(SUMIFS(RAW_매출A!$J$2:$J$7000,RAW_매출A!$B$2:$B$7000,$A11,RAW_매출A!$A$2:$A$7000,EDATE($E11,N$1-1))=0,"",SUMIFS(RAW_매출A!$J$2:$J$7000,RAW_매출A!$B$2:$B$7000,$A11,RAW_매출A!$A$2:$A$7000,EDATE($E11,N$1-1))/(INDEX(요약_월별시즈널리티!$F$7:$F$18,MONTH(EDATE($E11,N$1-1)))/100))),"")} -> 6730682.2 | ... BN11: {=IFERROR(IF($A11="","",IF(SUMIFS(RAW_매출A!$J$2:$J$7000,RAW_매출A!$B$2:$B$7000,$A11,RAW_매출A!$A$2:$A$7000,EDATE($E11,BN$1-1))=0,"",SUMIFS(RAW_매출A!$J$2:$J$7000,RAW_매출A!$B$2:$B$7000,$A11,RAW_매출A!$A$2:$A$7000,EDATE($E11,BN$1-1))/(INDEX(요약_월별시즈널리티!$F$7:$F$18,MONTH(EDATE($E11,BN$1-1)))/100))),"")}
A12: =세팅!A13 -> (0011) 천안성정공원점 | B12: =세팅!B13 -> 150-2 | C12: =IFERROR(VALUE(MID(B12,5,10)),"") -> 2 | D12: =IF(C12="","",IF(C12>=3,"3+",TEXT(C12,"0"))) -> 2 | E12: =세팅!D13 -> 44896 | F12: =IF(COUNT(J12:O12)>=4,AVERAGE(J12:O12),"") -> 6469805.3 | G12: {=IFERROR(IF($A12="","",IF(SUMIFS(RAW_매출A!$J$2:$J$7000,RAW_매출A!$B$2:$B$7000,$A12,RAW_매출A!$A$2:$A$7000,EDATE($E12,G$1-1))=0,"",SUMIFS(RAW_매출A!$J$2:$J$7000,RAW_매출A!$B$2:$B$7000,$A12,RAW_매출A!$A$2:$A$7000,EDATE($E12,G$1-1))/(INDEX(요약_월별시즈널리티!$F$7:$F$18,MONTH(EDATE($E12,G$1-1)))/100))),"")} -> 3673814.3 | H12: {=IFERROR(IF($A12="","",IF(SUMIFS(RAW_매출A!$J$2:$J$7000,RAW_매출A!$B$2:$B$7000,$A12,RAW_매출A!$A$2:$A$7000,EDATE($E12,H$1-1))=0,"",SUMIFS(RAW_매출A!$J$2:$J$7000,RAW_매출A!$B$2:$B$7000,$A12,RAW_매출A!$A$2:$A$7000,EDATE($E12,H$1-1))/(INDEX(요약_월별시즈널리티!$F$7:$F$18,MONTH(EDATE($E12,H$1-1)))/100))),"")} -> 4912242.6 | I12: {=IFERROR(IF($A12="","",IF(SUMIFS(RAW_매출A!$J$2:$J$7000,RAW_매출A!$B$2:$B$7000,$A12,RAW_매출A!$A$2:$A$7000,EDATE($E12,I$1-1))=0,"",SUMIFS(RAW_매출A!$J$2:$J$7000,RAW_매출A!$B$2:$B$7000,$A12,RAW_매출A!$A$2:$A$7000,EDATE($E12,I$1-1))/(INDEX(요약_월별시즈널리티!$F$7:$F$18,MONTH(EDATE($E12,I$1-1)))/100))),"")} -> 5258176.4 | J12: {=IFERROR(IF($A12="","",IF(SUMIFS(RAW_매출A!$J$2:$J$7000,RAW_매출A!$B$2:$B$7000,$A12,RAW_매출A!$A$2:$A$7000,EDATE($E12,J$1-1))=0,"",SUMIFS(RAW_매출A!$J$2:$J$7000,RAW_매출A!$B$2:$B$7000,$A12,RAW_매출A!$A$2:$A$7000,EDATE($E12,J$1-1))/(INDEX(요약_월별시즈널리티!$F$7:$F$18,MONTH(EDATE($E12,J$1-1)))/100))),"")} -> 5979113.2 | K12: {=IFERROR(IF($A12="","",IF(SUMIFS(RAW_매출A!$J$2:$J$7000,RAW_매출A!$B$2:$B$7000,$A12,RAW_매출A!$A$2:$A$7000,EDATE($E12,K$1-1))=0,"",SUMIFS(RAW_매출A!$J$2:$J$7000,RAW_매출A!$B$2:$B$7000,$A12,RAW_매출A!$A$2:$A$7000,EDATE($E12,K$1-1))/(INDEX(요약_월별시즈널리티!$F$7:$F$18,MONTH(EDATE($E12,K$1-1)))/100))),"")} -> 6324876 | L12: {=IFERROR(IF($A12="","",IF(SUMIFS(RAW_매출A!$J$2:$J$7000,RAW_매출A!$B$2:$B$7000,$A12,RAW_매출A!$A$2:$A$7000,EDATE($E12,L$1-1))=0,"",SUMIFS(RAW_매출A!$J$2:$J$7000,RAW_매출A!$B$2:$B$7000,$A12,RAW_매출A!$A$2:$A$7000,EDATE($E12,L$1-1))/(INDEX(요약_월별시즈널리티!$F$7:$F$18,MONTH(EDATE($E12,L$1-1)))/100))),"")} -> 5880401.1 | M12: {=IFERROR(IF($A12="","",IF(SUMIFS(RAW_매출A!$J$2:$J$7000,RAW_매출A!$B$2:$B$7000,$A12,RAW_매출A!$A$2:$A$7000,EDATE($E12,M$1-1))=0,"",SUMIFS(RAW_매출A!$J$2:$J$7000,RAW_매출A!$B$2:$B$7000,$A12,RAW_매출A!$A$2:$A$7000,EDATE($E12,M$1-1))/(INDEX(요약_월별시즈널리티!$F$7:$F$18,MONTH(EDATE($E12,M$1-1)))/100))),"")} -> 6197421.2 | N12: {=IFERROR(IF($A12="","",IF(SUMIFS(RAW_매출A!$J$2:$J$7000,RAW_매출A!$B$2:$B$7000,$A12,RAW_매출A!$A$2:$A$7000,EDATE($E12,N$1-1))=0,"",SUMIFS(RAW_매출A!$J$2:$J$7000,RAW_매출A!$B$2:$B$7000,$A12,RAW_매출A!$A$2:$A$7000,EDATE($E12,N$1-1))/(INDEX(요약_월별시즈널리티!$F$7:$F$18,MONTH(EDATE($E12,N$1-1)))/100))),"")} -> 7507739.2 | ... BN12: {=IFERROR(IF($A12="","",IF(SUMIFS(RAW_매출A!$J$2:$J$7000,RAW_매출A!$B$2:$B$7000,$A12,RAW_매출A!$A$2:$A$7000,EDATE($E12,BN$1-1))=0,"",SUMIFS(RAW_매출A!$J$2:$J$7000,RAW_매출A!$B$2:$B$7000,$A12,RAW_매출A!$A$2:$A$7000,EDATE($E12,BN$1-1))/(INDEX(요약_월별시즈널리티!$F$7:$F$18,MONTH(EDATE($E12,BN$1-1)))/100))),"")}
